Workbook

Sheet 1-10
A2: i Wall@
A3: SharpSing Limited
A4: Room 1609, 16/F., Golden Era Plaza, No. 39 Sai Yee Street, Mongkok, KLN. Tel:35868635 Fax:31889330
B6: =Total!$A$2 -> 2026 Jun Century Field Promoter Salary Summary
B8: Name/姓名 | C8: =Total!$E$8 -> Tan Xing Fang | D8: {=INDEX(Total!$D$8:$D$31,MATCH($C8&$G8,Total!$E$8:$E$31&Total!#REF!,0))} -> #REF! | F8: CQ NO. | G8: =Total!#REF! -> #REF!
B10: Job Detail | E10: Content
B11: Job Categories/工作類別 | E11: Promoter
B12: Location/工作地點 | E12: {=INDEX(Total!$F$8:$F$31,MATCH($C8&$G8,Total!$E$8:$E$31&Total!#REF!,0))} -> #REF!
B13: Period/工作日子 | E13: {=INDEX(Total!$G$8:$G$31,MATCH($C8&$G8,Total!$E$8:$E$31&Total!#REF!,0))} -> #REF!
B14: Reg.Day/工作日數 | E14: {=INDEX(Total!$H$8:$H$31,MATCH($C8&$G8,Total!$E$8:$E$31&Total!#REF!,0))} -> #REF!
B15: Reg.Hour/工作時數 | E15: {=INDEX(Total!$I$8:$I$31,MATCH($C8&$G8,Total!$E$8:$E$31&Total!#REF!,0))} -> #REF!
B16: HK$/時薪 | E16: {=INDEX(Total!$J$8:$J$31,MATCH($C8&$G8,Total!$E$8:$E$31&Total!#REF!,0))} -> #REF!
B17: Sales Record/銷售紀錄 | E17: {=INDEX(Total!$L$8:$L$31,MATCH($C8&$G8,Total!$E$8:$E$31&Total!#REF!,0))} -> #REF!
C19: Salary Detail | F19: Sub. Total
C20: Basic/酬金 | G20: {=INDEX(Total!$K$8:$K$31,MATCH($C8&$G8,Total!$E$8:$E$31&Total!#REF!,0))} -> #REF!
C21: Attendance/出勤 | G21: {=INDEX(Total!$Q$8:$Q$31,MATCH($C8&$G8,Total!$E$8:$E$31&Total!#REF!,0))} -> #REF!
C22: Commission/佣金 | G22: =Total!N8 -> 3675.186
C23: Allowance/津貼 | G23: {=INDEX(Total!$R$8:$R$31,MATCH($C8&$G8,Total!$E$8:$E$31&Total!#REF!,0))} -> #REF!
C24: Award/獎金 | G24: {=INDEX(Total!#REF!,MATCH($C8&$G8,Total!$E$8:$E$31&Total!#REF!,0))} -> #REF!
C25: Expenses/支出 | G25: {=INDEX(Total!$S$8:$S$31,MATCH($C8&$G8,Total!$E$8:$E$31&Total!#REF!,0))} -> #REF!
C26: Other/其他 | G26: {=INDEX(Total!#REF!,MATCH($C8&$G8,Total!$E$8:$E$31&Total!#REF!,0))} -> #REF!
C27: Adjustment/調整 | G27: {=INDEX(Total!$T$8:$T$31,MATCH($C8&$G8,Total!$E$8:$E$31&Total!#REF!,0))} -> #REF!
C28: MPF/強積金** | G28: {=-INDEX(Total!$U$8:$U$31,MATCH($C8&$G8,Total!$E$8:$E$31&Total!#REF!,0))} -> #REF!
E29: Total | F29: =SUM($G20:$G28) -> #REF! | J29: {=INDEX(Total!$W$8:$W$31,MATCH($C8&$G8,Total!$E$8:$E$31&Total!#REF!,0))} -> #REF!
B31: **如屬自僱人仕必須自行購買勞工保險及強積金；
B32: 註 1：如所支付之金額有錯誤，請在兩天內提出；
B33: 註 2：請自行核對清楚支票上的姓名及金額；
E34: Promoter 確認簽名 :
F36: I.D. Card No. :
A39: i Wall@
A40: SharpSing Limited
A41: Room 1609, 16/F., Golden Era Plaza, No. 39 Sai Yee Street, Mongkok, KLN. Tel:35868635 Fax:31889330
B43: =Total!$A$2 -> 2026 Jun Century Field Promoter Salary Summary
B45: Name/姓名 | C45: =Total!$E$9 -> Yuen Maria Wing Yan | D45: {=INDEX(Total!$D$8:$D$31,MATCH($C45&$G45,Total!$E$8:$E$31&Total!#REF!,0))} -> #REF! | F45: CQ NO. | G45: =Total!#REF! -> #REF!
B47: Job Detail | E47: Content
B48: Job Categories/工作類別 | E48: Promoter
B49: Location/工作地點 | E49: {=INDEX(Total!$F$8:$F$31,MATCH($C45&$G45,Total!$E$8:$E$31&Total!#REF!,0))} -> #REF!
B50: Period/工作日子 | E50: {=INDEX(Total!$G$8:$G$31,MATCH($C45&$G45,Total!$E$8:$E$31&Total!#REF!,0))} -> #REF!
B51: Reg.Day/工作日數 | E51: {=INDEX(Total!$H$8:$H$31,MATCH($C45&$G45,Total!$E$8:$E$31&Total!#REF!,0))} -> #REF!
B52: Reg.Hour/工作時數 | E52: {=INDEX(Total!$I$8:$I$31,MATCH($C45&$G45,Total!$E$8:$E$31&Total!#REF!,0))} -> #REF!
...

Sheet 11-20
A2: i Wall@
A3: SharpSing Limited
A4: Room 1609, 16/F., Golden Era Plaza, No. 39 Sai Yee Street, Mongkok, KLN. Tel:35868635 Fax:31889330
B6: =Total!$A$2 -> 2026 Jun Century Field Promoter Salary Summary
B8: Name/姓名 | C8: =Total!E15 -> Siu Wai Ling | D8: =Total!D15 -> Margaret | F8: CQ NO. | G8: =Total!#REF! -> #REF!
B10: Job Detail | E10: Content
B11: Job Categories/工作類別 | E11: Promoter
B12: Location/工作地點 | E12: =Total!#REF! -> #REF!
B13: Period/工作日子 | E13: =Total!G15 -> 5,6,7,12,13,14,19,20,21,25,29/Jun
B14: Reg.Day/工作日數 | E14: =Total!H15 -> 11
B15: Reg.Hour/工作時數 | E15: =Total!I15 -> 88
B16: HK$/時薪 | E16: =Total!J15 -> 56.25
B17: Sales Record/銷售紀錄 | E17: =Total!L15 -> 159644
C19: Salary Detail | F19: Sub. Total
C20: Basic/酬金 | G20: =Total!K15 -> 4950
C21: Attendance/出勤 | G21: =Total!Q15 -> 0
C22: Commission/佣金 | G22: =Total!N15 -> 4789.32
C23: Allowance/津貼 | G23: =Total!R15 -> 0
C24: Award/獎金 | G24: =Total!#REF! -> #REF!
C25: Expenses/支出 | G25: =Total!S15 -> 0
C26: Other/其他 | G26: =Total!#REF! -> #REF!
C27: Adjustment/調整 | G27: =Total!T15 -> 0
C28: MPF/強積金** | G28: =Total!U15 -> 0
E29: Total | F29: =SUM(G20:G27)-G28 -> #REF! | J29: =Total!V15 -> 9739.32
B31: **如屬自僱人仕必須自行購買勞工保險及強積金；
B32: 註 1：如所支付之金額有錯誤，請在兩天內提出；
B33: 註 2：請自行核對清楚支票上的姓名及金額；
E34: Promoter 確認簽名 :
F36: I.D. Card No. :
A39: i Wall@
A40: SharpSing Limited
A41: Room 1609, 16/F., Golden Era Plaza, No. 39 Sai Yee Street, Mongkok, KLN. Tel:35868635 Fax:31889330
B43: =Total!$A$2 -> 2026 Jun Century Field Promoter Salary Summary
B45: Name/姓名 | C45: =Total!E16 -> Siu Wai Ling | D45: =Total!D16 -> Margaret | F45: CQ NO. | G45: =Total!#REF! -> #REF!
B47: Job Detail | E47: Content
B48: Job Categories/工作類別 | E48: Promoter
B49: Location/工作地點 | E49: =Total!G16 -> 1,2,8,9,15,22,23/Jun
B50: Period/工作日子 | E50: =Total!#REF! -> #REF!
B51: Reg.Day/工作日數 | E51: =Total!H16 -> 7
B52: Reg.Hour/工作時數 | E52: =Total!I16 -> 56
...

Sheet Roster
A1: 要入當月1號日期>>>>> | B1: 46174 | C1: =YEAR(B1) -> 2026 | D1: =MONTH(B1) -> 6
A4: 保護工作表PW:1234 | AH4: Man Day | AI4: Hours
B5: 2026 Jun | AH5: =SUBTOTAL(9,AH8:AH31) -> 155 | AI5: =SUBTOTAL(9,AI8:AI31) -> 1240 | AL5: =B5 -> 2026 Jun
C6: =TEXT($C$1&"/"&$D$1&"/"&C7,"ddd") -> Mon | D6: =TEXT($C$1&"/"&$D$1&"/"&D7,"ddd") -> Tue | E6: =TEXT($C$1&"/"&$D$1&"/"&E7,"ddd") -> Wed | F6: =TEXT($C$1&"/"&$D$1&"/"&F7,"ddd") -> Thu | G6: =TEXT($C$1&"/"&$D$1&"/"&G7,"ddd") -> Fri | H6: =TEXT($C$1&"/"&$D$1&"/"&H7,"ddd") -> Sat | I6: =TEXT($C$1&"/"&$D$1&"/"&I7,"ddd") -> Sun | J6: =TEXT($C$1&"/"&$D$1&"/"&J7,"ddd") -> Mon | ... AG6: =TEXT($C$1&"/"&$D$1&"/"&AG7,"ddd") -> 2026/6/31 | AM6: =C6 -> Mon | AN6: =D6 -> Tue | AO6: =E6 -> Wed | AP6: =F6 -> Thu | AQ6: =G6 -> Fri | AR6: =H6 -> Sat | AS6: =I6 -> Sun | AT6: =J6 -> Mon | ... BQ6: =AG6 -> 2026/6/31 | BR6: =#REF! -> #REF! | BS6: =#REF! -> #REF!
A7: 以下溢出代表時間表個頁相同location n date,不同人 | B7: 以下不用入location… | C7: =DAY(B1) -> 1 | D7: =C7+1 -> 2 | E7: =D7+1 -> 3 | F7: =E7+1 -> 4 | G7: =F7+1 -> 5 | H7: =G7+1 -> 6 | I7: =H7+1 -> 7 | J7: =I7+1 -> 8 | K7: =J7+1 -> 9 | ... AG7: =AF7+1 -> 31 | AM7: =C7 -> 1 | AN7: =D7 -> 2 | AO7: =E7 -> 3 | AP7: =F7 -> 4 | AQ7: =G7 -> 5 | AR7: =H7 -> 6 | AS7: =I7 -> 7 | AT7: =J7 -> 8 | ... BQ7: =AG7 -> 31 | BR7: =#REF! -> #REF! | BS7: =#REF! -> #REF!
A8: {=_xlfn.LET( _xlpm.data, C8:AG8, _xlpm.removeList, {" off","."," SL","xxx"}, _xlpm.cleaned, TRIM(_xlfn.REDUCE(_xlpm.data, _xlpm.removeList, _xlfn.LAMBDA(_xlpm.arr,_xlpm.str, SUBSTITUTE(_xlpm.arr, _xlpm.str, "")))), _xlpm.first, _xlfn._xlws.FILTER(_xlpm.cleaned, _xlpm.cleaned <> ""), INDEX(_xlpm.first, 1) )} -> Margaret | B8: {=_xlfn.ANCHORARRAY('Name List'!$K$3)} -> Central Fortress | C8: {=_xlfn.LET( _xlpm.data, 表格3_5[[Date]:[Location]], _xlpm.date_col, INDEX(_xlpm.data, , 1), _xlpm.name_col, INDEX(_xlpm.data, , 2), _xlpm.loc_col, INDEX(_xlpm.data, , 3), _xlpm.target_date, DATE(YEAR($B$1), MONTH($B$1), C$7), _xlpm.filtered, _xlfn._xlws.FILTER(_xlpm.name_col, (_xlpm.date_col = _xlpm.target_date) * (_xlpm.loc_col =$B8), ""), IF(_xlpm.filtered="", "", _xlpm.filtered) )} -> Margaret | D8: {=_xlfn.LET( _xlpm.data, 表格3_5[[Date]:[Location]], _xlpm.date_col, INDEX(_xlpm.data, , 1), _xlpm.name_col, INDEX(_xlpm.data, , 2), _xlpm.loc_col, INDEX(_xlpm.data, , 3), _xlpm.target_date, DATE(YEAR($B$1), MONTH($B$1), D$7), _xlpm.filtered, _xlfn._xlws.FILTER(_xlpm.name_col, (_xlpm.date_col = _xlpm.target_date) * (_xlpm.loc_col =$B8), ""), IF(_xlpm.filtered="", "", _xlpm.filtered) )} -> Margaret | E8: {=_xlfn.LET( _xlpm.data, 表格3_5[[Date]:[Location]], _xlpm.date_col, INDEX(_xlpm.data, , 1), _xlpm.name_col, INDEX(_xlpm.data, , 2), _xlpm.loc_col, INDEX(_xlpm.data, , 3), _xlpm.target_date, DATE(YEAR($B$1), MONTH($B$1), E$7), _xlpm.filtered, _xlfn._xlws.FILTER(_xlpm.name_col, (_xlpm.date_col = _xlpm.target_date) * (_xlpm.loc_col =$B8), ""), IF(_xlpm.filtered="", "", _xlpm.filtered) )} | F8: {=_xlfn.LET( _xlpm.data, 表格3_5[[Date]:[Location]], _xlpm.date_col, INDEX(_xlpm.data, , 1), _xlpm.name_col, INDEX(_xlpm.data, , 2), _xlpm.loc_col, INDEX(_xlpm.data, , 3), _xlpm.target_date, DATE(YEAR($B$1), MONTH($B$1), F$7), _xlpm.filtered, _xlfn._xlws.FILTER(_xlpm.name_col, (_xlpm.date_col = _xlpm.target_date) * (_xlpm.loc_col =$B8), ""), IF(_xlpm.filtered="", "", _xlpm.filtered) )} | G8: {=_xlfn.LET( _xlpm.data, 表格3_5[[Date]:[Location]], _xlpm.date_col, INDEX(_xlpm.data, , 1), _xlpm.name_col, INDEX(_xlpm.data, , 2), _xlpm.loc_col, INDEX(_xlpm.data, , 3), _xlpm.target_date, DATE(YEAR($B$1), MONTH($B$1), G$7), _xlpm.filtered, _xlfn._xlws.FILTER(_xlpm.name_col, (_xlpm.date_col = _xlpm.target_date) * (_xlpm.loc_col =$B8), ""), IF(_xlpm.filtered="", "", _xlpm.filtered) )} | H8: {=_xlfn.LET( _xlpm.data, 表格3_5[[Date]:[Location]], _xlpm.date_col, INDEX(_xlpm.data, , 1), _xlpm.name_col, INDEX(_xlpm.data, , 2), _xlpm.loc_col, INDEX(_xlpm.data, , 3), _xlpm.target_date, DATE(YEAR($B$1), MONTH($B$1), H$7), _xlpm.filtered, _xlfn._xlws.FILTER(_xlpm.name_col, (_xlpm.date_col = _xlpm.target_date) * (_xlpm.loc_col =$B8), ""), IF(_xlpm.filtered="", "", _xlpm.filtered) )} | I8: {=_xlfn.LET( _xlpm.data, 表格3_5[[Date]:[Location]], _xlpm.date_col, INDEX(_xlpm.data, , 1), _xlpm.name_col, INDEX(_xlpm.data, , 2), _xlpm.loc_col, INDEX(_xlpm.data, , 3), _xlpm.target_date, DATE(YEAR($B$1), MONTH($B$1), I$7), _xlpm.filtered, _xlfn._xlws.FILTER(_xlpm.name_col, (_xlpm.date_col = _xlpm.target_date) * (_xlpm.loc_col =$B8), ""), IF(_xlpm.filtered="", "", _xlpm.filtered) )} | J8: {=_xlfn.LET( _xlpm.data, 表格3_5[[Date]:[Location]], _xlpm.date_col, INDEX(_xlpm.data, , 1), _xlpm.name_col, INDEX(_xlpm.data, , 2), _xlpm.loc_col, INDEX(_xlpm.data, , 3), _xlpm.target_date, DATE(YEAR($B$1), MONTH($B$1), J$7), _xlpm.filtered, _xlfn._xlws.FILTER(_xlpm.name_col, (_xlpm.date_col = _xlpm.target_date) * (_xlpm.loc_col =$B8), ""), IF(_xlpm.filtered="", "", _xlpm.filtered) )} -> Margaret | ... AG8: {=_xlfn.LET( _xlpm.data, 表格3_5[[Date]:[Location]], _xlpm.date_col, INDEX(_xlpm.data, , 1), _xlpm.name_col, INDEX(_xlpm.data, , 2), _xlpm.loc_col, INDEX(_xlpm.data, , 3), _xlpm.target_date, DATE(YEAR($B$1), MONTH($B$1), AG$7), _xlpm.filtered, _xlfn._xlws.FILTER(_xlpm.name_col, (_xlpm.date_col = _xlpm.target_date) * (_xlpm.loc_col =$B8), ""), IF(_xlpm.filtered="", "", _xlpm.filtered) )} | AH8: =COUNTIF(C8:AG8,"?*") -> 7 | AI8: =AH8*8 -> 56 | AL8: =B8 -> Central Fortress | AM8: =IF(C8=".",C8,IF(VLOOKUP($AL8&C$1+#REF!&C8, 工作表1!$C:$V,1,) > 0,C8,"ERROR")) -> #REF! | AN8: =IF(D8=".",D8,IF(VLOOKUP($AL8&D$1+#REF!&D8, 工作表1!$C:$V,1,) > 0,D8,"ERROR")) -> #REF! | AO8: =IF(E8=".",E8,IF(VLOOKUP($AL8&E$1+#REF!&E8, 工作表1!$C:$V,1,) > 0,E8,"ERROR")) -> #REF! | AP8: =IF(F8=".",F8,IF(VLOOKUP($AL8&F$1+#REF!&F8, 工作表1!$C:$V,1,) > 0,F8,"ERROR")) -> #REF! | AQ8: =IF(G8=".",G8,IF(VLOOKUP($AL8&G$1+#REF!&G8, 工作表1!$C:$V,1,) > 0,G8,"ERROR")) -> #REF! | AR8: =IF(H8=".",H8,IF(VLOOKUP($AL8&H$1+#REF!&H8, 工作表1!$C:$V,1,) > 0,H8,"ERROR")) -> #REF! | AS8: =IF(I8=".",I8,IF(VLOOKUP($AL8&I$1+#REF!&I8, 工作表1!$C:$V,1,) > 0,I8,"ERROR")) -> #REF! | AT8: =IF(J8=".",J8,IF(VLOOKUP($AL8&J$1+#REF!&J8, 工作表1!$C:$V,1,) > 0,J8,"ERROR")) -> #REF! | ... BQ8: =IF(AG8=".",AG8,IF(VLOOKUP($AL8&AG$1+#REF!&AG8, 工作表1!$C:$V,1,) > 0,AG8,"ERROR")) -> #REF! | BR8: =IF(#REF!=".",#REF!,IF(VLOOKUP($AL8&#REF!+#REF!&#REF!, 工作表1!$C:$V,1,) > 0,#REF!,"ERROR")) -> #REF! | BS8: =IF(#REF!=".",#REF!,IF(VLOOKUP($AL8&#REF!+#REF!&#REF!, 工作表1!$C:$V,1,) > 0,#REF!,"ERROR")) -> #REF!
A9: {=_xlfn.LET( _xlpm.data, C9:AG9, _xlpm.removeList, {" off","."," SL","xxx"}, _xlpm.cleaned, TRIM(_xlfn.REDUCE(_xlpm.data, _xlpm.removeList, _xlfn.LAMBDA(_xlpm.arr,_xlpm.str, SUBSTITUTE(_xlpm.arr, _xlpm.str, "")))), _xlpm.first, _xlfn._xlws.FILTER(_xlpm.cleaned, _xlpm.cleaned <> ""), INDEX(_xlpm.first, 1) )} -> Shirley | B9: Festival Walk Fortress | C9: {=_xlfn.LET( _xlpm.data, 表格3_5[[Date]:[Location]], _xlpm.date_col, INDEX(_xlpm.data, , 1), _xlpm.name_col, INDEX(_xlpm.data, , 2), _xlpm.loc_col, INDEX(_xlpm.data, , 3), _xlpm.target_date, DATE(YEAR($B$1), MONTH($B$1), C$7), _xlpm.filtered, _xlfn._xlws.FILTER(_xlpm.name_col, (_xlpm.date_col = _xlpm.target_date) * (_xlpm.loc_col =$B9), ""), IF(_xlpm.filtered="", "", _xlpm.filtered) )} | D9: {=_xlfn.LET( _xlpm.data, 表格3_5[[Date]:[Location]], _xlpm.date_col, INDEX(_xlpm.data, , 1), _xlpm.name_col, INDEX(_xlpm.data, , 2), _xlpm.loc_col, INDEX(_xlpm.data, , 3), _xlpm.target_date, DATE(YEAR($B$1), MONTH($B$1), D$7), _xlpm.filtered, _xlfn._xlws.FILTER(_xlpm.name_col, (_xlpm.date_col = _xlpm.target_date) * (_xlpm.loc_col =$B9), ""), IF(_xlpm.filtered="", "", _xlpm.filtered) )} | E9: {=_xlfn.LET( _xlpm.data, 表格3_5[[Date]:[Location]], _xlpm.date_col, INDEX(_xlpm.data, , 1), _xlpm.name_col, INDEX(_xlpm.data, , 2), _xlpm.loc_col, INDEX(_xlpm.data, , 3), _xlpm.target_date, DATE(YEAR($B$1), MONTH($B$1), E$7), _xlpm.filtered, _xlfn._xlws.FILTER(_xlpm.name_col, (_xlpm.date_col = _xlpm.target_date) * (_xlpm.loc_col =$B9), ""), IF(_xlpm.filtered="", "", _xlpm.filtered) )} | F9: {=_xlfn.LET( _xlpm.data, 表格3_5[[Date]:[Location]], _xlpm.date_col, INDEX(_xlpm.data, , 1), _xlpm.name_col, INDEX(_xlpm.data, , 2), _xlpm.loc_col, INDEX(_xlpm.data, , 3), _xlpm.target_date, DATE(YEAR($B$1), MONTH($B$1), F$7), _xlpm.filtered, _xlfn._xlws.FILTER(_xlpm.name_col, (_xlpm.date_col = _xlpm.target_date) * (_xlpm.loc_col =$B9), ""), IF(_xlpm.filtered="", "", _xlpm.filtered) )} | G9: {=_xlfn.LET( _xlpm.data, 表格3_5[[Date]:[Location]], _xlpm.date_col, INDEX(_xlpm.data, , 1), _xlpm.name_col, INDEX(_xlpm.data, , 2), _xlpm.loc_col, INDEX(_xlpm.data, , 3), _xlpm.target_date, DATE(YEAR($B$1), MONTH($B$1), G$7), _xlpm.filtered, _xlfn._xlws.FILTER(_xlpm.name_col, (_xlpm.date_col = _xlpm.target_date) * (_xlpm.loc_col =$B9), ""), IF(_xlpm.filtered="", "", _xlpm.filtered) )} -> Shirley | H9: {=_xlfn.LET( _xlpm.data, 表格3_5[[Date]:[Location]], _xlpm.date_col, INDEX(_xlpm.data, , 1), _xlpm.name_col, INDEX(_xlpm.data, , 2), _xlpm.loc_col, INDEX(_xlpm.data, , 3), _xlpm.target_date, DATE(YEAR($B$1), MONTH($B$1), H$7), _xlpm.filtered, _xlfn._xlws.FILTER(_xlpm.name_col, (_xlpm.date_col = _xlpm.target_date) * (_xlpm.loc_col =$B9), ""), IF(_xlpm.filtered="", "", _xlpm.filtered) )} -> Shirley | I9: {=_xlfn.LET( _xlpm.data, 表格3_5[[Date]:[Location]], _xlpm.date_col, INDEX(_xlpm.data, , 1), _xlpm.name_col, INDEX(_xlpm.data, , 2), _xlpm.loc_col, INDEX(_xlpm.data, , 3), _xlpm.target_date, DATE(YEAR($B$1), MONTH($B$1), I$7), _xlpm.filtered, _xlfn._xlws.FILTER(_xlpm.name_col, (_xlpm.date_col = _xlpm.target_date) * (_xlpm.loc_col =$B9), ""), IF(_xlpm.filtered="", "", _xlpm.filtered) )} -> Shirley | J9: {=_xlfn.LET( _xlpm.data, 表格3_5[[Date]:[Location]], _xlpm.date_col, INDEX(_xlpm.data, , 1), _xlpm.name_col, INDEX(_xlpm.data, , 2), _xlpm.loc_col, INDEX(_xlpm.data, , 3), _xlpm.target_date, DATE(YEAR($B$1), MONTH($B$1), J$7), _xlpm.filtered, _xlfn._xlws.FILTER(_xlpm.name_col, (_xlpm.date_col = _xlpm.target_date) * (_xlpm.loc_col =$B9), ""), IF(_xlpm.filtered="", "", _xlpm.filtered) )} | ... AG9: {=_xlfn.LET( _xlpm.data, 表格3_5[[Date]:[Location]], _xlpm.date_col, INDEX(_xlpm.data, , 1), _xlpm.name_col, INDEX(_xlpm.data, , 2), _xlpm.loc_col, INDEX(_xlpm.data, , 3), _xlpm.target_date, DATE(YEAR($B$1), MONTH($B$1), AG$7), _xlpm.filtered, _xlfn._xlws.FILTER(_xlpm.name_col, (_xlpm.date_col = _xlpm.target_date) * (_xlpm.loc_col =$B9), ""), IF(_xlpm.filtered="", "", _xlpm.filtered) )} | AH9: =COUNTIF(C9:AG9,"?*") -> 3 | AI9: =AH9*8 -> 24 | AL9: =B9 -> Festival Walk Fortress | AM9: =IF(C9=".",C9,IF(VLOOKUP($AL9&C$1+C4&C9, 工作表1!$C:$V,1,) > 0,C9,"ERROR")) -> #N/A | AN9: =IF(D9=".",D9,IF(VLOOKUP($AL9&D$1+D4&D9, 工作表1!$C:$V,1,) > 0,D9,"ERROR")) -> #N/A | AO9: =IF(E9=".",E9,IF(VLOOKUP($AL9&E$1+E4&E9, 工作表1!$C:$V,1,) > 0,E9,"ERROR")) -> #N/A | AP9: =IF(F9=".",F9,IF(VLOOKUP($AL9&F$1+F4&F9, 工作表1!$C:$V,1,) > 0,F9,"ERROR")) -> #N/A | AQ9: =IF(G9=".",G9,IF(VLOOKUP($AL9&G$1+G4&G9, 工作表1!$C:$V,1,) > 0,G9,"ERROR")) -> #N/A | AR9: =IF(H9=".",H9,IF(VLOOKUP($AL9&H$1+H4&H9, 工作表1!$C:$V,1,) > 0,H9,"ERROR")) -> #N/A | AS9: =IF(I9=".",I9,IF(VLOOKUP($AL9&I$1+I4&I9, 工作表1!$C:$V,1,) > 0,I9,"ERROR")) -> #N/A | AT9: =IF(J9=".",J9,IF(VLOOKUP($AL9&J$1+J4&J9, 工作表1!$C:$V,1,) > 0,J9,"ERROR")) -> #N/A | ... BQ9: =IF(AG9=".",AG9,IF(VLOOKUP($AL9&AG$1+AG4&AG9, 工作表1!$C:$V,1,) > 0,AG9,"ERROR")) -> #N/A | BR9: =IF(#REF!=".",#REF!,IF(VLOOKUP($AL9&#REF!+#REF!&#REF!, 工作表1!$C:$V,1,) > 0,#REF!,"ERROR")) -> #REF! | BS9: =IF(#REF!=".",#REF!,IF(VLOOKUP($AL9&#REF!+#REF!&#REF!, 工作表1!$C:$V,1,) > 0,#REF!,"ERROR")) -> #REF!
A10: {=_xlfn.LET( _xlpm.data, C10:AG10, _xlpm.removeList, {" off","."," SL","xxx"}, _xlpm.cleaned, TRIM(_xlfn.REDUCE(_xlpm.data, _xlpm.removeList, _xlfn.LAMBDA(_xlpm.arr,_xlpm.str, SUBSTITUTE(_xlpm.arr, _xlpm.str, "")))), _xlpm.first, _xlfn._xlws.FILTER(_xlpm.cleaned, _xlpm.cleaned <> ""), INDEX(_xlpm.first, 1) )} -> Jenny P | B10: In - Home Expo | C10: {=_xlfn.LET( _xlpm.data, 表格3_5[[Date]:[Location]], _xlpm.date_col, INDEX(_xlpm.data, , 1), _xlpm.name_col, INDEX(_xlpm.data, , 2), _xlpm.loc_col, INDEX(_xlpm.data, , 3), _xlpm.target_date, DATE(YEAR($B$1), MONTH($B$1), C$7), _xlpm.filtered, _xlfn._xlws.FILTER(_xlpm.name_col, (_xlpm.date_col = _xlpm.target_date) * (_xlpm.loc_col =$B10), ""), IF(_xlpm.filtered="", "", _xlpm.filtered) )} | D10: {=_xlfn.LET( _xlpm.data, 表格3_5[[Date]:[Location]], _xlpm.date_col, INDEX(_xlpm.data, , 1), _xlpm.name_col, INDEX(_xlpm.data, , 2), _xlpm.loc_col, INDEX(_xlpm.data, , 3), _xlpm.target_date, DATE(YEAR($B$1), MONTH($B$1), D$7), _xlpm.filtered, _xlfn._xlws.FILTER(_xlpm.name_col, (_xlpm.date_col = _xlpm.target_date) * (_xlpm.loc_col =$B10), ""), IF(_xlpm.filtered="", "", _xlpm.filtered) )} | E10: {=_xlfn.LET( _xlpm.data, 表格3_5[[Date]:[Location]], _xlpm.date_col, INDEX(_xlpm.data, , 1), _xlpm.name_col, INDEX(_xlpm.data, , 2), _xlpm.loc_col, INDEX(_xlpm.data, , 3), _xlpm.target_date, DATE(YEAR($B$1), MONTH($B$1), E$7), _xlpm.filtered, _xlfn._xlws.FILTER(_xlpm.name_col, (_xlpm.date_col = _xlpm.target_date) * (_xlpm.loc_col =$B10), ""), IF(_xlpm.filtered="", "", _xlpm.filtered) )} | F10: {=_xlfn.LET( _xlpm.data, 表格3_5[[Date]:[Location]], _xlpm.date_col, INDEX(_xlpm.data, , 1), _xlpm.name_col, INDEX(_xlpm.data, , 2), _xlpm.loc_col, INDEX(_xlpm.data, , 3), _xlpm.target_date, DATE(YEAR($B$1), MONTH($B$1), F$7), _xlpm.filtered, _xlfn._xlws.FILTER(_xlpm.name_col, (_xlpm.date_col = _xlpm.target_date) * (_xlpm.loc_col =$B10), ""), IF(_xlpm.filtered="", "", _xlpm.filtered) )} | G10: {=_xlfn.LET( _xlpm.data, 表格3_5[[Date]:[Location]], _xlpm.date_col, INDEX(_xlpm.data, , 1), _xlpm.name_col, INDEX(_xlpm.data, , 2), _xlpm.loc_col, INDEX(_xlpm.data, , 3), _xlpm.target_date, DATE(YEAR($B$1), MONTH($B$1), G$7), _xlpm.filtered, _xlfn._xlws.FILTER(_xlpm.name_col, (_xlpm.date_col = _xlpm.target_date) * (_xlpm.loc_col =$B10), ""), IF(_xlpm.filtered="", "", _xlpm.filtered) )} | H10: {=_xlfn.LET( _xlpm.data, 表格3_5[[Date]:[Location]], _xlpm.date_col, INDEX(_xlpm.data, , 1), _xlpm.name_col, INDEX(_xlpm.data, , 2), _xlpm.loc_col, INDEX(_xlpm.data, , 3), _xlpm.target_date, DATE(YEAR($B$1), MONTH($B$1), H$7), _xlpm.filtered, _xlfn._xlws.FILTER(_xlpm.name_col, (_xlpm.date_col = _xlpm.target_date) * (_xlpm.loc_col =$B10), ""), IF(_xlpm.filtered="", "", _xlpm.filtered) )} | I10: {=_xlfn.LET( _xlpm.data, 表格3_5[[Date]:[Location]], _xlpm.date_col, INDEX(_xlpm.data, , 1), _xlpm.name_col, INDEX(_xlpm.data, , 2), _xlpm.loc_col, INDEX(_xlpm.data, , 3), _xlpm.target_date, DATE(YEAR($B$1), MONTH($B$1), I$7), _xlpm.filtered, _xlfn._xlws.FILTER(_xlpm.name_col, (_xlpm.date_col = _xlpm.target_date) * (_xlpm.loc_col =$B10), ""), IF(_xlpm.filtered="", "", _xlpm.filtered) )} | J10: {=_xlfn.LET( _xlpm.data, 表格3_5[[Date]:[Location]], _xlpm.date_col, INDEX(_xlpm.data, , 1), _xlpm.name_col, INDEX(_xlpm.data, , 2), _xlpm.loc_col, INDEX(_xlpm.data, , 3), _xlpm.target_date, DATE(YEAR($B$1), MONTH($B$1), J$7), _xlpm.filtered, _xlfn._xlws.FILTER(_xlpm.name_col, (_xlpm.date_col = _xlpm.target_date) * (_xlpm.loc_col =$B10), ""), IF(_xlpm.filtered="", "", _xlpm.filtered) )} | ... AG10: {=_xlfn.LET( _xlpm.data, 表格3_5[[Date]:[Location]], _xlpm.date_col, INDEX(_xlpm.data, , 1), _xlpm.name_col, INDEX(_xlpm.data, , 2), _xlpm.loc_col, INDEX(_xlpm.data, , 3), _xlpm.target_date, DATE(YEAR($B$1), MONTH($B$1), AG$7), _xlpm.filtered, _xlfn._xlws.FILTER(_xlpm.name_col, (_xlpm.date_col = _xlpm.target_date) * (_xlpm.loc_col =$B10), ""), IF(_xlpm.filtered="", "", _xlpm.filtered) )} | AH10: =COUNTIF(C10:AG10,"?*") -> 4 | AI10: =AH10*8 -> 32 | AL10: =B10 -> In - Home Expo | AM10: =IF(C10=".",C10,IF(VLOOKUP($AL10&C$1+C5&C10, 工作表1!$C:$V,1,) > 0,C10,"ERROR")) -> #N/A | AN10: =IF(D10=".",D10,IF(VLOOKUP($AL10&D$1+D5&D10, 工作表1!$C:$V,1,) > 0,D10,"ERROR")) -> #N/A | AO10: =IF(E10=".",E10,IF(VLOOKUP($AL10&E$1+E5&E10, 工作表1!$C:$V,1,) > 0,E10,"ERROR")) -> #N/A | AP10: =IF(F10=".",F10,IF(VLOOKUP($AL10&F$1+F5&F10, 工作表1!$C:$V,1,) > 0,F10,"ERROR")) -> #N/A | AQ10: =IF(G10=".",G10,IF(VLOOKUP($AL10&G$1+G5&G10, 工作表1!$C:$V,1,) > 0,G10,"ERROR")) -> #N/A | AR10: =IF(H10=".",H10,IF(VLOOKUP($AL10&H$1+H5&H10, 工作表1!$C:$V,1,) > 0,H10,"ERROR")) -> #N/A | AS10: =IF(I10=".",I10,IF(VLOOKUP($AL10&I$1+I5&I10, 工作表1!$C:$V,1,) > 0,I10,"ERROR")) -> #N/A | AT10: =IF(J10=".",J10,IF(VLOOKUP($AL10&J$1+J5&J10, 工作表1!$C:$V,1,) > 0,J10,"ERROR")) -> #N/A | ... BQ10: =IF(AG10=".",AG10,IF(VLOOKUP($AL10&AG$1+AG5&AG10, 工作表1!$C:$V,1,) > 0,AG10,"ERROR")) -> #N/A | BR10: =IF(#REF!=".",#REF!,IF(VLOOKUP($AL10&#REF!+#REF!&#REF!, 工作表1!$C:$V,1,) > 0,#REF!,"ERROR")) -> #REF! | BS10: =IF(#REF!=".",#REF!,IF(VLOOKUP($AL10&#REF!+#REF!&#REF!, 工作表1!$C:$V,1,) > 0,#REF!,"ERROR")) -> #REF!
A11: {=_xlfn.LET( _xlpm.data, C11:AG11, _xlpm.removeList, {" off","."," SL","xxx"}, _xlpm.cleaned, TRIM(_xlfn.REDUCE(_xlpm.data, _xlpm.removeList, _xlfn.LAMBDA(_xlpm.arr,_xlpm.str, SUBSTITUTE(_xlpm.arr, _xlpm.str, "")))), _xlpm.first, _xlfn._xlws.FILTER(_xlpm.cleaned, _xlpm.cleaned <> ""), INDEX(_xlpm.first, 1) )} -> Margaret | B11: In - Home Expo 2 | C11: {=_xlfn.LET( _xlpm.data, 表格3_5[[Date]:[Location]], _xlpm.date_col, INDEX(_xlpm.data, , 1), _xlpm.name_col, INDEX(_xlpm.data, , 2), _xlpm.loc_col, INDEX(_xlpm.data, , 3), _xlpm.target_date, DATE(YEAR($B$1), MONTH($B$1), C$7), _xlpm.filtered, _xlfn._xlws.FILTER(_xlpm.name_col, (_xlpm.date_col = _xlpm.target_date) * (_xlpm.loc_col =$B11), ""), IF(_xlpm.filtered="", "", _xlpm.filtered) )} | D11: {=_xlfn.LET( _xlpm.data, 表格3_5[[Date]:[Location]], _xlpm.date_col, INDEX(_xlpm.data, , 1), _xlpm.name_col, INDEX(_xlpm.data, , 2), _xlpm.loc_col, INDEX(_xlpm.data, , 3), _xlpm.target_date, DATE(YEAR($B$1), MONTH($B$1), D$7), _xlpm.filtered, _xlfn._xlws.FILTER(_xlpm.name_col, (_xlpm.date_col = _xlpm.target_date) * (_xlpm.loc_col =$B11), ""), IF(_xlpm.filtered="", "", _xlpm.filtered) )} | E11: {=_xlfn.LET( _xlpm.data, 表格3_5[[Date]:[Location]], _xlpm.date_col, INDEX(_xlpm.data, , 1), _xlpm.name_col, INDEX(_xlpm.data, , 2), _xlpm.loc_col, INDEX(_xlpm.data, , 3), _xlpm.target_date, DATE(YEAR($B$1), MONTH($B$1), E$7), _xlpm.filtered, _xlfn._xlws.FILTER(_xlpm.name_col, (_xlpm.date_col = _xlpm.target_date) * (_xlpm.loc_col =$B11), ""), IF(_xlpm.filtered="", "", _xlpm.filtered) )} | F11: {=_xlfn.LET( _xlpm.data, 表格3_5[[Date]:[Location]], _xlpm.date_col, INDEX(_xlpm.data, , 1), _xlpm.name_col, INDEX(_xlpm.data, , 2), _xlpm.loc_col, INDEX(_xlpm.data, , 3), _xlpm.target_date, DATE(YEAR($B$1), MONTH($B$1), F$7), _xlpm.filtered, _xlfn._xlws.FILTER(_xlpm.name_col, (_xlpm.date_col = _xlpm.target_date) * (_xlpm.loc_col =$B11), ""), IF(_xlpm.filtered="", "", _xlpm.filtered) )} | G11: {=_xlfn.LET( _xlpm.data, 表格3_5[[Date]:[Location]], _xlpm.date_col, INDEX(_xlpm.data, , 1), _xlpm.name_col, INDEX(_xlpm.data, , 2), _xlpm.loc_col, INDEX(_xlpm.data, , 3), _xlpm.target_date, DATE(YEAR($B$1), MONTH($B$1), G$7), _xlpm.filtered, _xlfn._xlws.FILTER(_xlpm.name_col, (_xlpm.date_col = _xlpm.target_date) * (_xlpm.loc_col =$B11), ""), IF(_xlpm.filtered="", "", _xlpm.filtered) )} | H11: {=_xlfn.LET( _xlpm.data, 表格3_5[[Date]:[Location]], _xlpm.date_col, INDEX(_xlpm.data, , 1), _xlpm.name_col, INDEX(_xlpm.data, , 2), _xlpm.loc_col, INDEX(_xlpm.data, , 3), _xlpm.target_date, DATE(YEAR($B$1), MONTH($B$1), H$7), _xlpm.filtered, _xlfn._xlws.FILTER(_xlpm.name_col, (_xlpm.date_col = _xlpm.target_date) * (_xlpm.loc_col =$B11), ""), IF(_xlpm.filtered="", "", _xlpm.filtered) )} | I11: {=_xlfn.LET( _xlpm.data, 表格3_5[[Date]:[Location]], _xlpm.date_col, INDEX(_xlpm.data, , 1), _xlpm.name_col, INDEX(_xlpm.data, , 2), _xlpm.loc_col, INDEX(_xlpm.data, , 3), _xlpm.target_date, DATE(YEAR($B$1), MONTH($B$1), I$7), _xlpm.filtered, _xlfn._xlws.FILTER(_xlpm.name_col, (_xlpm.date_col = _xlpm.target_date) * (_xlpm.loc_col =$B11), ""), IF(_xlpm.filtered="", "", _xlpm.filtered) )} | J11: {=_xlfn.LET( _xlpm.data, 表格3_5[[Date]:[Location]], _xlpm.date_col, INDEX(_xlpm.data, , 1), _xlpm.name_col, INDEX(_xlpm.data, , 2), _xlpm.loc_col, INDEX(_xlpm.data, , 3), _xlpm.target_date, DATE(YEAR($B$1), MONTH($B$1), J$7), _xlpm.filtered, _xlfn._xlws.FILTER(_xlpm.name_col, (_xlpm.date_col = _xlpm.target_date) * (_xlpm.loc_col =$B11), ""), IF(_xlpm.filtered="", "", _xlpm.filtered) )} | ... AG11: {=_xlfn.LET( _xlpm.data, 表格3_5[[Date]:[Location]], _xlpm.date_col, INDEX(_xlpm.data, , 1), _xlpm.name_col, INDEX(_xlpm.data, , 2), _xlpm.loc_col, INDEX(_xlpm.data, , 3), _xlpm.target_date, DATE(YEAR($B$1), MONTH($B$1), AG$7), _xlpm.filtered, _xlfn._xlws.FILTER(_xlpm.name_col, (_xlpm.date_col = _xlpm.target_date) * (_xlpm.loc_col =$B11), ""), IF(_xlpm.filtered="", "", _xlpm.filtered) )} | AH11: =COUNTIF(C11:AG11,"?*") -> 2 | AI11: =AH11*8 -> 16 | AL11: =B11 -> In - Home Expo 2 | AM11: =IF(C11=".",C11,IF(VLOOKUP($AL11&C$1+C6&C11, 工作表1!$C:$V,1,) > 0,C11,"ERROR")) -> #VALUE! | AN11: =IF(D11=".",D11,IF(VLOOKUP($AL11&D$1+D6&D11, 工作表1!$C:$V,1,) > 0,D11,"ERROR")) -> #VALUE! | AO11: =IF(E11=".",E11,IF(VLOOKUP($AL11&E$1+E6&E11, 工作表1!$C:$V,1,) > 0,E11,"ERROR")) -> #VALUE! | AP11: =IF(F11=".",F11,IF(VLOOKUP($AL11&F$1+F6&F11, 工作表1!$C:$V,1,) > 0,F11,"ERROR")) -> #VALUE! | AQ11: =IF(G11=".",G11,IF(VLOOKUP($AL11&G$1+G6&G11, 工作表1!$C:$V,1,) > 0,G11,"ERROR")) -> #VALUE! | AR11: =IF(H11=".",H11,IF(VLOOKUP($AL11&H$1+H6&H11, 工作表1!$C:$V,1,) > 0,H11,"ERROR")) -> #VALUE! | AS11: =IF(I11=".",I11,IF(VLOOKUP($AL11&I$1+I6&I11, 工作表1!$C:$V,1,) > 0,I11,"ERROR")) -> #VALUE! | AT11: =IF(J11=".",J11,IF(VLOOKUP($AL11&J$1+J6&J11, 工作表1!$C:$V,1,) > 0,J11,"ERROR")) -> #VALUE! | ... BQ11: =IF(AG11=".",AG11,IF(VLOOKUP($AL11&AG$1+AG6&AG11, 工作表1!$C:$V,1,) > 0,AG11,"ERROR")) -> #VALUE! | BR11: =IF(#REF!=".",#REF!,IF(VLOOKUP($AL11&#REF!+#REF!&#REF!, 工作表1!$C:$V,1,) > 0,#REF!,"ERROR")) -> #REF! | BS11: =IF(#REF!=".",#REF!,IF(VLOOKUP($AL11&#REF!+#REF!&#REF!, 工作表1!$C:$V,1,) > 0,#REF!,"ERROR")) -> #REF!
A12: {=_xlfn.LET( _xlpm.data, C12:AG12, _xlpm.removeList, {" off","."," SL","xxx"}, _xlpm.cleaned, TRIM(_xlfn.REDUCE(_xlpm.data, _xlpm.removeList, _xlfn.LAMBDA(_xlpm.arr,_xlpm.str, SUBSTITUTE(_xlpm.arr, _xlpm.str, "")))), _xlpm.first, _xlfn._xlws.FILTER(_xlpm.cleaned, _xlpm.cleaned <> ""), INDEX(_xlpm.first, 1) )} -> Wah | B12: Kowloon Bay Fortress | C12: {=_xlfn.LET( _xlpm.data, 表格3_5[[Date]:[Location]], _xlpm.date_col, INDEX(_xlpm.data, , 1), _xlpm.name_col, INDEX(_xlpm.data, , 2), _xlpm.loc_col, INDEX(_xlpm.data, , 3), _xlpm.target_date, DATE(YEAR($B$1), MONTH($B$1), C$7), _xlpm.filtered, _xlfn._xlws.FILTER(_xlpm.name_col, (_xlpm.date_col = _xlpm.target_date) * (_xlpm.loc_col =$B12), ""), IF(_xlpm.filtered="", "", _xlpm.filtered) )} | D12: {=_xlfn.LET( _xlpm.data, 表格3_5[[Date]:[Location]], _xlpm.date_col, INDEX(_xlpm.data, , 1), _xlpm.name_col, INDEX(_xlpm.data, , 2), _xlpm.loc_col, INDEX(_xlpm.data, , 3), _xlpm.target_date, DATE(YEAR($B$1), MONTH($B$1), D$7), _xlpm.filtered, _xlfn._xlws.FILTER(_xlpm.name_col, (_xlpm.date_col = _xlpm.target_date) * (_xlpm.loc_col =$B12), ""), IF(_xlpm.filtered="", "", _xlpm.filtered) )} | E12: {=_xlfn.LET( _xlpm.data, 表格3_5[[Date]:[Location]], _xlpm.date_col, INDEX(_xlpm.data, , 1), _xlpm.name_col, INDEX(_xlpm.data, , 2), _xlpm.loc_col, INDEX(_xlpm.data, , 3), _xlpm.target_date, DATE(YEAR($B$1), MONTH($B$1), E$7), _xlpm.filtered, _xlfn._xlws.FILTER(_xlpm.name_col, (_xlpm.date_col = _xlpm.target_date) * (_xlpm.loc_col =$B12), ""), IF(_xlpm.filtered="", "", _xlpm.filtered) )} | F12: {=_xlfn.LET( _xlpm.data, 表格3_5[[Date]:[Location]], _xlpm.date_col, INDEX(_xlpm.data, , 1), _xlpm.name_col, INDEX(_xlpm.data, , 2), _xlpm.loc_col, INDEX(_xlpm.data, , 3), _xlpm.target_date, DATE(YEAR($B$1), MONTH($B$1), F$7), _xlpm.filtered, _xlfn._xlws.FILTER(_xlpm.name_col, (_xlpm.date_col = _xlpm.target_date) * (_xlpm.loc_col =$B12), ""), IF(_xlpm.filtered="", "", _xlpm.filtered) )} -> Wah | G12: {=_xlfn.LET( _xlpm.data, 表格3_5[[Date]:[Location]], _xlpm.date_col, INDEX(_xlpm.data, , 1), _xlpm.name_col, INDEX(_xlpm.data, , 2), _xlpm.loc_col, INDEX(_xlpm.data, , 3), _xlpm.target_date, DATE(YEAR($B$1), MONTH($B$1), G$7), _xlpm.filtered, _xlfn._xlws.FILTER(_xlpm.name_col, (_xlpm.date_col = _xlpm.target_date) * (_xlpm.loc_col =$B12), ""), IF(_xlpm.filtered="", "", _xlpm.filtered) )} -> Wah | H12: {=_xlfn.LET( _xlpm.data, 表格3_5[[Date]:[Location]], _xlpm.date_col, INDEX(_xlpm.data, , 1), _xlpm.name_col, INDEX(_xlpm.data, , 2), _xlpm.loc_col, INDEX(_xlpm.data, , 3), _xlpm.target_date, DATE(YEAR($B$1), MONTH($B$1), H$7), _xlpm.filtered, _xlfn._xlws.FILTER(_xlpm.name_col, (_xlpm.date_col = _xlpm.target_date) * (_xlpm.loc_col =$B12), ""), IF(_xlpm.filtered="", "", _xlpm.filtered) )} -> Wah | I12: {=_xlfn.LET( _xlpm.data, 表格3_5[[Date]:[Location]], _xlpm.date_col, INDEX(_xlpm.data, , 1), _xlpm.name_col, INDEX(_xlpm.data, , 2), _xlpm.loc_col, INDEX(_xlpm.data, , 3), _xlpm.target_date, DATE(YEAR($B$1), MONTH($B$1), I$7), _xlpm.filtered, _xlfn._xlws.FILTER(_xlpm.name_col, (_xlpm.date_col = _xlpm.target_date) * (_xlpm.loc_col =$B12), ""), IF(_xlpm.filtered="", "", _xlpm.filtered) )} -> Wah | J12: {=_xlfn.LET( _xlpm.data, 表格3_5[[Date]:[Location]], _xlpm.date_col, INDEX(_xlpm.data, , 1), _xlpm.name_col, INDEX(_xlpm.data, , 2), _xlpm.loc_col, INDEX(_xlpm.data, , 3), _xlpm.target_date, DATE(YEAR($B$1), MONTH($B$1), J$7), _xlpm.filtered, _xlfn._xlws.FILTER(_xlpm.name_col, (_xlpm.date_col = _xlpm.target_date) * (_xlpm.loc_col =$B12), ""), IF(_xlpm.filtered="", "", _xlpm.filtered) )} | ... AG12: {=_xlfn.LET( _xlpm.data, 表格3_5[[Date]:[Location]], _xlpm.date_col, INDEX(_xlpm.data, , 1), _xlpm.name_col, INDEX(_xlpm.data, , 2), _xlpm.loc_col, INDEX(_xlpm.data, , 3), _xlpm.target_date, DATE(YEAR($B$1), MONTH($B$1), AG$7), _xlpm.filtered, _xlfn._xlws.FILTER(_xlpm.name_col, (_xlpm.date_col = _xlpm.target_date) * (_xlpm.loc_col =$B12), ""), IF(_xlpm.filtered="", "", _xlpm.filtered) )} | AH12: =COUNTIF(C12:AG12,"?*") -> 16 | AI12: =AH12*8 -> 128 | AL12: =B12 -> Kowloon Bay Fortress | AM12: =IF(C12=".",C12,IF(VLOOKUP($AL12&C$1+C7&C12, 工作表1!$C:$V,1,) > 0,C12,"ERROR")) -> #N/A | AN12: =IF(D12=".",D12,IF(VLOOKUP($AL12&D$1+D7&D12, 工作表1!$C:$V,1,) > 0,D12,"ERROR")) -> #N/A | AO12: =IF(E12=".",E12,IF(VLOOKUP($AL12&E$1+E7&E12, 工作表1!$C:$V,1,) > 0,E12,"ERROR")) -> #N/A | AP12: =IF(F12=".",F12,IF(VLOOKUP($AL12&F$1+F7&F12, 工作表1!$C:$V,1,) > 0,F12,"ERROR")) -> #N/A | AQ12: =IF(G12=".",G12,IF(VLOOKUP($AL12&G$1+G7&G12, 工作表1!$C:$V,1,) > 0,G12,"ERROR")) -> #N/A | AR12: =IF(H12=".",H12,IF(VLOOKUP($AL12&H$1+H7&H12, 工作表1!$C:$V,1,) > 0,H12,"ERROR")) -> #N/A | AS12: =IF(I12=".",I12,IF(VLOOKUP($AL12&I$1+I7&I12, 工作表1!$C:$V,1,) > 0,I12,"ERROR")) -> #N/A | AT12: =IF(J12=".",J12,IF(VLOOKUP($AL12&J$1+J7&J12, 工作表1!$C:$V,1,) > 0,J12,"ERROR")) -> #N/A | ... BQ12: =IF(AG12=".",AG12,IF(VLOOKUP($AL12&AG$1+AG7&AG12, 工作表1!$C:$V,1,) > 0,AG12,"ERROR")) -> #N/A | BR12: =IF(#REF!=".",#REF!,IF(VLOOKUP($AL12&#REF!+#REF!&#REF!, 工作表1!$C:$V,1,) > 0,#REF!,"ERROR")) -> #REF! | BS12: =IF(#REF!=".",#REF!,IF(VLOOKUP($AL12&#REF!+#REF!&#REF!, 工作表1!$C:$V,1,) > 0,#REF!,"ERROR")) -> #REF!
A13: {=_xlfn.LET( _xlpm.data, C13:AG13, _xlpm.removeList, {" off","."," SL","xxx"}, _xlpm.cleaned, TRIM(_xlfn.REDUCE(_xlpm.data, _xlpm.removeList, _xlfn.LAMBDA(_xlpm.arr,_xlpm.str, SUBSTITUTE(_xlpm.arr, _xlpm.str, "")))), _xlpm.first, _xlfn._xlws.FILTER(_xlpm.cleaned, _xlpm.cleaned <> ""), INDEX(_xlpm.first, 1) )} -> Wu Sir | B13: Kwai Fong Fortress | C13: {=_xlfn.LET( _xlpm.data, 表格3_5[[Date]:[Location]], _xlpm.date_col, INDEX(_xlpm.data, , 1), _xlpm.name_col, INDEX(_xlpm.data, , 2), _xlpm.loc_col, INDEX(_xlpm.data, , 3), _xlpm.target_date, DATE(YEAR($B$1), MONTH($B$1), C$7), _xlpm.filtered, _xlfn._xlws.FILTER(_xlpm.name_col, (_xlpm.date_col = _xlpm.target_date) * (_xlpm.loc_col =$B13), ""), IF(_xlpm.filtered="", "", _xlpm.filtered) )} | D13: {=_xlfn.LET( _xlpm.data, 表格3_5[[Date]:[Location]], _xlpm.date_col, INDEX(_xlpm.data, , 1), _xlpm.name_col, INDEX(_xlpm.data, , 2), _xlpm.loc_col, INDEX(_xlpm.data, , 3), _xlpm.target_date, DATE(YEAR($B$1), MONTH($B$1), D$7), _xlpm.filtered, _xlfn._xlws.FILTER(_xlpm.name_col, (_xlpm.date_col = _xlpm.target_date) * (_xlpm.loc_col =$B13), ""), IF(_xlpm.filtered="", "", _xlpm.filtered) )} | E13: {=_xlfn.LET( _xlpm.data, 表格3_5[[Date]:[Location]], _xlpm.date_col, INDEX(_xlpm.data, , 1), _xlpm.name_col, INDEX(_xlpm.data, , 2), _xlpm.loc_col, INDEX(_xlpm.data, , 3), _xlpm.target_date, DATE(YEAR($B$1), MONTH($B$1), E$7), _xlpm.filtered, _xlfn._xlws.FILTER(_xlpm.name_col, (_xlpm.date_col = _xlpm.target_date) * (_xlpm.loc_col =$B13), ""), IF(_xlpm.filtered="", "", _xlpm.filtered) )} | F13: {=_xlfn.LET( _xlpm.data, 表格3_5[[Date]:[Location]], _xlpm.date_col, INDEX(_xlpm.data, , 1), _xlpm.name_col, INDEX(_xlpm.data, , 2), _xlpm.loc_col, INDEX(_xlpm.data, , 3), _xlpm.target_date, DATE(YEAR($B$1), MONTH($B$1), F$7), _xlpm.filtered, _xlfn._xlws.FILTER(_xlpm.name_col, (_xlpm.date_col = _xlpm.target_date) * (_xlpm.loc_col =$B13), ""), IF(_xlpm.filtered="", "", _xlpm.filtered) )} | G13: {=_xlfn.LET( _xlpm.data, 表格3_5[[Date]:[Location]], _xlpm.date_col, INDEX(_xlpm.data, , 1), _xlpm.name_col, INDEX(_xlpm.data, , 2), _xlpm.loc_col, INDEX(_xlpm.data, , 3), _xlpm.target_date, DATE(YEAR($B$1), MONTH($B$1), G$7), _xlpm.filtered, _xlfn._xlws.FILTER(_xlpm.name_col, (_xlpm.date_col = _xlpm.target_date) * (_xlpm.loc_col =$B13), ""), IF(_xlpm.filtered="", "", _xlpm.filtered) )} | H13: {=_xlfn.LET( _xlpm.data, 表格3_5[[Date]:[Location]], _xlpm.date_col, INDEX(_xlpm.data, , 1), _xlpm.name_col, INDEX(_xlpm.data, , 2), _xlpm.loc_col, INDEX(_xlpm.data, , 3), _xlpm.target_date, DATE(YEAR($B$1), MONTH($B$1), H$7), _xlpm.filtered, _xlfn._xlws.FILTER(_xlpm.name_col, (_xlpm.date_col = _xlpm.target_date) * (_xlpm.loc_col =$B13), ""), IF(_xlpm.filtered="", "", _xlpm.filtered) )} -> Wu Sir | I13: {=_xlfn.LET( _xlpm.data, 表格3_5[[Date]:[Location]], _xlpm.date_col, INDEX(_xlpm.data, , 1), _xlpm.name_col, INDEX(_xlpm.data, , 2), _xlpm.loc_col, INDEX(_xlpm.data, , 3), _xlpm.target_date, DATE(YEAR($B$1), MONTH($B$1), I$7), _xlpm.filtered, _xlfn._xlws.FILTER(_xlpm.name_col, (_xlpm.date_col = _xlpm.target_date) * (_xlpm.loc_col =$B13), ""), IF(_xlpm.filtered="", "", _xlpm.filtered) )} -> Wu Sir | J13: {=_xlfn.LET( _xlpm.data, 表格3_5[[Date]:[Location]], _xlpm.date_col, INDEX(_xlpm.data, , 1), _xlpm.name_col, INDEX(_xlpm.data, , 2), _xlpm.loc_col, INDEX(_xlpm.data, , 3), _xlpm.target_date, DATE(YEAR($B$1), MONTH($B$1), J$7), _xlpm.filtered, _xlfn._xlws.FILTER(_xlpm.name_col, (_xlpm.date_col = _xlpm.target_date) * (_xlpm.loc_col =$B13), ""), IF(_xlpm.filtered="", "", _xlpm.filtered) )} | ... AG13: {=_xlfn.LET( _xlpm.data, 表格3_5[[Date]:[Location]], _xlpm.date_col, INDEX(_xlpm.data, , 1), _xlpm.name_col, INDEX(_xlpm.data, , 2), _xlpm.loc_col, INDEX(_xlpm.data, , 3), _xlpm.target_date, DATE(YEAR($B$1), MONTH($B$1), AG$7), _xlpm.filtered, _xlfn._xlws.FILTER(_xlpm.name_col, (_xlpm.date_col = _xlpm.target_date) * (_xlpm.loc_col =$B13), ""), IF(_xlpm.filtered="", "", _xlpm.filtered) )} | AH13: =COUNTIF(C13:AG13,"?*") -> 6 | AI13: =AH13*8 -> 48 | AL13: =B13 -> Kwai Fong Fortress | AM13: =IF(C13=".",C13,IF(VLOOKUP($AL13&C$1+C8&C13, 工作表1!$C:$V,1,) > 0,C13,"ERROR")) -> #VALUE! | AN13: =IF(D13=".",D13,IF(VLOOKUP($AL13&D$1+D8&D13, 工作表1!$C:$V,1,) > 0,D13,"ERROR")) -> #VALUE! | AO13: =IF(E13=".",E13,IF(VLOOKUP($AL13&E$1+E8&E13, 工作表1!$C:$V,1,) > 0,E13,"ERROR")) -> #VALUE! | AP13: =IF(F13=".",F13,IF(VLOOKUP($AL13&F$1+F8&F13, 工作表1!$C:$V,1,) > 0,F13,"ERROR")) -> #VALUE! | AQ13: =IF(G13=".",G13,IF(VLOOKUP($AL13&G$1+G8&G13, 工作表1!$C:$V,1,) > 0,G13,"ERROR")) -> #VALUE! | AR13: =IF(H13=".",H13,IF(VLOOKUP($AL13&H$1+H8&H13, 工作表1!$C:$V,1,) > 0,H13,"ERROR")) -> #VALUE! | AS13: =IF(I13=".",I13,IF(VLOOKUP($AL13&I$1+I8&I13, 工作表1!$C:$V,1,) > 0,I13,"ERROR")) -> #VALUE! | AT13: =IF(J13=".",J13,IF(VLOOKUP($AL13&J$1+J8&J13, 工作表1!$C:$V,1,) > 0,J13,"ERROR")) -> #VALUE! | ... BQ13: =IF(AG13=".",AG13,IF(VLOOKUP($AL13&AG$1+AG8&AG13, 工作表1!$C:$V,1,) > 0,AG13,"ERROR")) -> #VALUE! | BR13: =IF(#REF!=".",#REF!,IF(VLOOKUP($AL13&#REF!+#REF!&#REF!, 工作表1!$C:$V,1,) > 0,#REF!,"ERROR")) -> #REF! | BS13: =IF(#REF!=".",#REF!,IF(VLOOKUP($AL13&#REF!+#REF!&#REF!, 工作表1!$C:$V,1,) > 0,#REF!,"ERROR")) -> #REF!
A14: {=_xlfn.LET( _xlpm.data, C14:AG14, _xlpm.removeList, {" off","."," SL","xxx"}, _xlpm.cleaned, TRIM(_xlfn.REDUCE(_xlpm.data, _xlpm.removeList, _xlfn.LAMBDA(_xlpm.arr,_xlpm.str, SUBSTITUTE(_xlpm.arr, _xlpm.str, "")))), _xlpm.first, _xlfn._xlws.FILTER(_xlpm.cleaned, _xlpm.cleaned <> ""), INDEX(_xlpm.first, 1) )} -> Margaret | B14: Shatin Fortress | C14: {=_xlfn.LET( _xlpm.data, 表格3_5[[Date]:[Location]], _xlpm.date_col, INDEX(_xlpm.data, , 1), _xlpm.name_col, INDEX(_xlpm.data, , 2), _xlpm.loc_col, INDEX(_xlpm.data, , 3), _xlpm.target_date, DATE(YEAR($B$1), MONTH($B$1), C$7), _xlpm.filtered, _xlfn._xlws.FILTER(_xlpm.name_col, (_xlpm.date_col = _xlpm.target_date) * (_xlpm.loc_col =$B14), ""), IF(_xlpm.filtered="", "", _xlpm.filtered) )} | D14: {=_xlfn.LET( _xlpm.data, 表格3_5[[Date]:[Location]], _xlpm.date_col, INDEX(_xlpm.data, , 1), _xlpm.name_col, INDEX(_xlpm.data, , 2), _xlpm.loc_col, INDEX(_xlpm.data, , 3), _xlpm.target_date, DATE(YEAR($B$1), MONTH($B$1), D$7), _xlpm.filtered, _xlfn._xlws.FILTER(_xlpm.name_col, (_xlpm.date_col = _xlpm.target_date) * (_xlpm.loc_col =$B14), ""), IF(_xlpm.filtered="", "", _xlpm.filtered) )} | E14: {=_xlfn.LET( _xlpm.data, 表格3_5[[Date]:[Location]], _xlpm.date_col, INDEX(_xlpm.data, , 1), _xlpm.name_col, INDEX(_xlpm.data, , 2), _xlpm.loc_col, INDEX(_xlpm.data, , 3), _xlpm.target_date, DATE(YEAR($B$1), MONTH($B$1), E$7), _xlpm.filtered, _xlfn._xlws.FILTER(_xlpm.name_col, (_xlpm.date_col = _xlpm.target_date) * (_xlpm.loc_col =$B14), ""), IF(_xlpm.filtered="", "", _xlpm.filtered) )} | F14: {=_xlfn.LET( _xlpm.data, 表格3_5[[Date]:[Location]], _xlpm.date_col, INDEX(_xlpm.data, , 1), _xlpm.name_col, INDEX(_xlpm.data, , 2), _xlpm.loc_col, INDEX(_xlpm.data, , 3), _xlpm.target_date, DATE(YEAR($B$1), MONTH($B$1), F$7), _xlpm.filtered, _xlfn._xlws.FILTER(_xlpm.name_col, (_xlpm.date_col = _xlpm.target_date) * (_xlpm.loc_col =$B14), ""), IF(_xlpm.filtered="", "", _xlpm.filtered) )} | G14: {=_xlfn.LET( _xlpm.data, 表格3_5[[Date]:[Location]], _xlpm.date_col, INDEX(_xlpm.data, , 1), _xlpm.name_col, INDEX(_xlpm.data, , 2), _xlpm.loc_col, INDEX(_xlpm.data, , 3), _xlpm.target_date, DATE(YEAR($B$1), MONTH($B$1), G$7), _xlpm.filtered, _xlfn._xlws.FILTER(_xlpm.name_col, (_xlpm.date_col = _xlpm.target_date) * (_xlpm.loc_col =$B14), ""), IF(_xlpm.filtered="", "", _xlpm.filtered) )} -> Margaret | H14: {=_xlfn.LET( _xlpm.data, 表格3_5[[Date]:[Location]], _xlpm.date_col, INDEX(_xlpm.data, , 1), _xlpm.name_col, INDEX(_xlpm.data, , 2), _xlpm.loc_col, INDEX(_xlpm.data, , 3), _xlpm.target_date, DATE(YEAR($B$1), MONTH($B$1), H$7), _xlpm.filtered, _xlfn._xlws.FILTER(_xlpm.name_col, (_xlpm.date_col = _xlpm.target_date) * (_xlpm.loc_col =$B14), ""), IF(_xlpm.filtered="", "", _xlpm.filtered) )} -> Margaret | I14: {=_xlfn.LET( _xlpm.data, 表格3_5[[Date]:[Location]], _xlpm.date_col, INDEX(_xlpm.data, , 1), _xlpm.name_col, INDEX(_xlpm.data, , 2), _xlpm.loc_col, INDEX(_xlpm.data, , 3), _xlpm.target_date, DATE(YEAR($B$1), MONTH($B$1), I$7), _xlpm.filtered, _xlfn._xlws.FILTER(_xlpm.name_col, (_xlpm.date_col = _xlpm.target_date) * (_xlpm.loc_col =$B14), ""), IF(_xlpm.filtered="", "", _xlpm.filtered) )} -> Margaret | J14: {=_xlfn.LET( _xlpm.data, 表格3_5[[Date]:[Location]], _xlpm.date_col, INDEX(_xlpm.data, , 1), _xlpm.name_col, INDEX(_xlpm.data, , 2), _xlpm.loc_col, INDEX(_xlpm.data, , 3), _xlpm.target_date, DATE(YEAR($B$1), MONTH($B$1), J$7), _xlpm.filtered, _xlfn._xlws.FILTER(_xlpm.name_col, (_xlpm.date_col = _xlpm.target_date) * (_xlpm.loc_col =$B14), ""), IF(_xlpm.filtered="", "", _xlpm.filtered) )} | ... AG14: {=_xlfn.LET( _xlpm.data, 表格3_5[[Date]:[Location]], _xlpm.date_col, INDEX(_xlpm.data, , 1), _xlpm.name_col, INDEX(_xlpm.data, , 2), _xlpm.loc_col, INDEX(_xlpm.data, , 3), _xlpm.target_date, DATE(YEAR($B$1), MONTH($B$1), AG$7), _xlpm.filtered, _xlfn._xlws.FILTER(_xlpm.name_col, (_xlpm.date_col = _xlpm.target_date) * (_xlpm.loc_col =$B14), ""), IF(_xlpm.filtered="", "", _xlpm.filtered) )} | AH14: =COUNTIF(C14:AG14,"?*") -> 11 | AI14: =AH14*8 -> 88 | AL14: =B14 -> Shatin Fortress | AM14: =IF(C14=".",C14,IF(VLOOKUP($AL14&C$1+C9&C14, 工作表1!$C:$V,1,) > 0,C14,"ERROR")) -> #VALUE! | AN14: =IF(D14=".",D14,IF(VLOOKUP($AL14&D$1+D9&D14, 工作表1!$C:$V,1,) > 0,D14,"ERROR")) -> #VALUE! | AO14: =IF(E14=".",E14,IF(VLOOKUP($AL14&E$1+E9&E14, 工作表1!$C:$V,1,) > 0,E14,"ERROR")) -> #VALUE! | AP14: =IF(F14=".",F14,IF(VLOOKUP($AL14&F$1+F9&F14, 工作表1!$C:$V,1,) > 0,F14,"ERROR")) -> #VALUE! | AQ14: =IF(G14=".",G14,IF(VLOOKUP($AL14&G$1+G9&G14, 工作表1!$C:$V,1,) > 0,G14,"ERROR")) -> #VALUE! | AR14: =IF(H14=".",H14,IF(VLOOKUP($AL14&H$1+H9&H14, 工作表1!$C:$V,1,) > 0,H14,"ERROR")) -> #VALUE! | AS14: =IF(I14=".",I14,IF(VLOOKUP($AL14&I$1+I9&I14, 工作表1!$C:$V,1,) > 0,I14,"ERROR")) -> #VALUE! | AT14: =IF(J14=".",J14,IF(VLOOKUP($AL14&J$1+J9&J14, 工作表1!$C:$V,1,) > 0,J14,"ERROR")) -> #VALUE! | ... BQ14: =IF(AG14=".",AG14,IF(VLOOKUP($AL14&AG$1+AG9&AG14, 工作表1!$C:$V,1,) > 0,AG14,"ERROR")) -> #VALUE! | BR14: =IF(#REF!=".",#REF!,IF(VLOOKUP($AL14&#REF!+#REF!&#REF!, 工作表1!$C:$V,1,) > 0,#REF!,"ERROR")) -> #REF! | BS14: =IF(#REF!=".",#REF!,IF(VLOOKUP($AL14&#REF!+#REF!&#REF!, 工作表1!$C:$V,1,) > 0,#REF!,"ERROR")) -> #REF!
A15: {=_xlfn.LET( _xlpm.data, C15:AG15, _xlpm.removeList, {" off","."," SL","xxx"}, _xlpm.cleaned, TRIM(_xlfn.REDUCE(_xlpm.data, _xlpm.removeList, _xlfn.LAMBDA(_xlpm.arr,_xlpm.str, SUBSTITUTE(_xlpm.arr, _xlpm.str, "")))), _xlpm.first, _xlfn._xlws.FILTER(_xlpm.cleaned, _xlpm.cleaned <> ""), INDEX(_xlpm.first, 1) )} -> Carol | B15: SW Wing On | C15: {=_xlfn.LET( _xlpm.data, 表格3_5[[Date]:[Location]], _xlpm.date_col, INDEX(_xlpm.data, , 1), _xlpm.name_col, INDEX(_xlpm.data, , 2), _xlpm.loc_col, INDEX(_xlpm.data, , 3), _xlpm.target_date, DATE(YEAR($B$1), MONTH($B$1), C$7), _xlpm.filtered, _xlfn._xlws.FILTER(_xlpm.name_col, (_xlpm.date_col = _xlpm.target_date) * (_xlpm.loc_col =$B15), ""), IF(_xlpm.filtered="", "", _xlpm.filtered) )} | D15: {=_xlfn.LET( _xlpm.data, 表格3_5[[Date]:[Location]], _xlpm.date_col, INDEX(_xlpm.data, , 1), _xlpm.name_col, INDEX(_xlpm.data, , 2), _xlpm.loc_col, INDEX(_xlpm.data, , 3), _xlpm.target_date, DATE(YEAR($B$1), MONTH($B$1), D$7), _xlpm.filtered, _xlfn._xlws.FILTER(_xlpm.name_col, (_xlpm.date_col = _xlpm.target_date) * (_xlpm.loc_col =$B15), ""), IF(_xlpm.filtered="", "", _xlpm.filtered) )} | E15: {=_xlfn.LET( _xlpm.data, 表格3_5[[Date]:[Location]], _xlpm.date_col, INDEX(_xlpm.data, , 1), _xlpm.name_col, INDEX(_xlpm.data, , 2), _xlpm.loc_col, INDEX(_xlpm.data, , 3), _xlpm.target_date, DATE(YEAR($B$1), MONTH($B$1), E$7), _xlpm.filtered, _xlfn._xlws.FILTER(_xlpm.name_col, (_xlpm.date_col = _xlpm.target_date) * (_xlpm.loc_col =$B15), ""), IF(_xlpm.filtered="", "", _xlpm.filtered) )} -> Carol | F15: {=_xlfn.LET( _xlpm.data, 表格3_5[[Date]:[Location]], _xlpm.date_col, INDEX(_xlpm.data, , 1), _xlpm.name_col, INDEX(_xlpm.data, , 2), _xlpm.loc_col, INDEX(_xlpm.data, , 3), _xlpm.target_date, DATE(YEAR($B$1), MONTH($B$1), F$7), _xlpm.filtered, _xlfn._xlws.FILTER(_xlpm.name_col, (_xlpm.date_col = _xlpm.target_date) * (_xlpm.loc_col =$B15), ""), IF(_xlpm.filtered="", "", _xlpm.filtered) )} -> Hazel | G15: {=_xlfn.LET( _xlpm.data, 表格3_5[[Date]:[Location]], _xlpm.date_col, INDEX(_xlpm.data, , 1), _xlpm.name_col, INDEX(_xlpm.data, , 2), _xlpm.loc_col, INDEX(_xlpm.data, , 3), _xlpm.target_date, DATE(YEAR($B$1), MONTH($B$1), G$7), _xlpm.filtered, _xlfn._xlws.FILTER(_xlpm.name_col, (_xlpm.date_col = _xlpm.target_date) * (_xlpm.loc_col =$B15), ""), IF(_xlpm.filtered="", "", _xlpm.filtered) )} -> Hazel | H15: {=_xlfn.LET( _xlpm.data, 表格3_5[[Date]:[Location]], _xlpm.date_col, INDEX(_xlpm.data, , 1), _xlpm.name_col, INDEX(_xlpm.data, , 2), _xlpm.loc_col, INDEX(_xlpm.data, , 3), _xlpm.target_date, DATE(YEAR($B$1), MONTH($B$1), H$7), _xlpm.filtered, _xlfn._xlws.FILTER(_xlpm.name_col, (_xlpm.date_col = _xlpm.target_date) * (_xlpm.loc_col =$B15), ""), IF(_xlpm.filtered="", "", _xlpm.filtered) )} -> Hazel | I15: {=_xlfn.LET( _xlpm.data, 表格3_5[[Date]:[Location]], _xlpm.date_col, INDEX(_xlpm.data, , 1), _xlpm.name_col, INDEX(_xlpm.data, , 2), _xlpm.loc_col, INDEX(_xlpm.data, , 3), _xlpm.target_date, DATE(YEAR($B$1), MONTH($B$1), I$7), _xlpm.filtered, _xlfn._xlws.FILTER(_xlpm.name_col, (_xlpm.date_col = _xlpm.target_date) * (_xlpm.loc_col =$B15), ""), IF(_xlpm.filtered="", "", _xlpm.filtered) )} | J15: {=_xlfn.LET( _xlpm.data, 表格3_5[[Date]:[Location]], _xlpm.date_col, INDEX(_xlpm.data, , 1), _xlpm.name_col, INDEX(_xlpm.data, , 2), _xlpm.loc_col, INDEX(_xlpm.data, , 3), _xlpm.target_date, DATE(YEAR($B$1), MONTH($B$1), J$7), _xlpm.filtered, _xlfn._xlws.FILTER(_xlpm.name_col, (_xlpm.date_col = _xlpm.target_date) * (_xlpm.loc_col =$B15), ""), IF(_xlpm.filtered="", "", _xlpm.filtered) )} | ... AG15: {=_xlfn.LET( _xlpm.data, 表格3_5[[Date]:[Location]], _xlpm.date_col, INDEX(_xlpm.data, , 1), _xlpm.name_col, INDEX(_xlpm.data, , 2), _xlpm.loc_col, INDEX(_xlpm.data, , 3), _xlpm.target_date, DATE(YEAR($B$1), MONTH($B$1), AG$7), _xlpm.filtered, _xlfn._xlws.FILTER(_xlpm.name_col, (_xlpm.date_col = _xlpm.target_date) * (_xlpm.loc_col =$B15), ""), IF(_xlpm.filtered="", "", _xlpm.filtered) )} | AH15: =COUNTIF(C15:AG15,"?*") -> 25 | AI15: =AH15*8 -> 200 | AL15: =B15 -> SW Wing On | AM15: =IF(C15=".",C15,IF(VLOOKUP($AL15&C$1+C10&C15, 工作表1!$C:$V,1,) > 0,C15,"ERROR")) -> #VALUE! | AN15: =IF(D15=".",D15,IF(VLOOKUP($AL15&D$1+D10&D15, 工作表1!$C:$V,1,) > 0,D15,"ERROR")) -> #VALUE! | AO15: =IF(E15=".",E15,IF(VLOOKUP($AL15&E$1+E10&E15, 工作表1!$C:$V,1,) > 0,E15,"ERROR")) -> #VALUE! | AP15: =IF(F15=".",F15,IF(VLOOKUP($AL15&F$1+F10&F15, 工作表1!$C:$V,1,) > 0,F15,"ERROR")) -> #VALUE! | AQ15: =IF(G15=".",G15,IF(VLOOKUP($AL15&G$1+G10&G15, 工作表1!$C:$V,1,) > 0,G15,"ERROR")) -> #VALUE! | AR15: =IF(H15=".",H15,IF(VLOOKUP($AL15&H$1+H10&H15, 工作表1!$C:$V,1,) > 0,H15,"ERROR")) -> #VALUE! | AS15: =IF(I15=".",I15,IF(VLOOKUP($AL15&I$1+I10&I15, 工作表1!$C:$V,1,) > 0,I15,"ERROR")) -> #VALUE! | AT15: =IF(J15=".",J15,IF(VLOOKUP($AL15&J$1+J10&J15, 工作表1!$C:$V,1,) > 0,J15,"ERROR")) -> #VALUE! | ... BQ15: =IF(AG15=".",AG15,IF(VLOOKUP($AL15&AG$1+AG10&AG15, 工作表1!$C:$V,1,) > 0,AG15,"ERROR")) -> #VALUE! | BR15: =IF(#REF!=".",#REF!,IF(VLOOKUP($AL15&#REF!+#REF!&#REF!, 工作表1!$C:$V,1,) > 0,#REF!,"ERROR")) -> #REF! | BS15: =IF(#REF!=".",#REF!,IF(VLOOKUP($AL15&#REF!+#REF!&#REF!, 工作表1!$C:$V,1,) > 0,#REF!,"ERROR")) -> #REF!
A16: {=_xlfn.LET( _xlpm.data, C16:AG16, _xlpm.removeList, {" off","."," SL","xxx"}, _xlpm.cleaned, TRIM(_xlfn.REDUCE(_xlpm.data, _xlpm.removeList, _xlfn.LAMBDA(_xlpm.arr,_xlpm.str, SUBSTITUTE(_xlpm.arr, _xlpm.str, "")))), _xlpm.first, _xlfn._xlws.FILTER(_xlpm.cleaned, _xlpm.cleaned <> ""), INDEX(_xlpm.first, 1) )} -> Joe | B16: Tai Po Yata | C16: {=_xlfn.LET( _xlpm.data, 表格3_5[[Date]:[Location]], _xlpm.date_col, INDEX(_xlpm.data, , 1), _xlpm.name_col, INDEX(_xlpm.data, , 2), _xlpm.loc_col, INDEX(_xlpm.data, , 3), _xlpm.target_date, DATE(YEAR($B$1), MONTH($B$1), C$7), _xlpm.filtered, _xlfn._xlws.FILTER(_xlpm.name_col, (_xlpm.date_col = _xlpm.target_date) * (_xlpm.loc_col =$B16), ""), IF(_xlpm.filtered="", "", _xlpm.filtered) )} | D16: {=_xlfn.LET( _xlpm.data, 表格3_5[[Date]:[Location]], _xlpm.date_col, INDEX(_xlpm.data, , 1), _xlpm.name_col, INDEX(_xlpm.data, , 2), _xlpm.loc_col, INDEX(_xlpm.data, , 3), _xlpm.target_date, DATE(YEAR($B$1), MONTH($B$1), D$7), _xlpm.filtered, _xlfn._xlws.FILTER(_xlpm.name_col, (_xlpm.date_col = _xlpm.target_date) * (_xlpm.loc_col =$B16), ""), IF(_xlpm.filtered="", "", _xlpm.filtered) )} | E16: {=_xlfn.LET( _xlpm.data, 表格3_5[[Date]:[Location]], _xlpm.date_col, INDEX(_xlpm.data, , 1), _xlpm.name_col, INDEX(_xlpm.data, , 2), _xlpm.loc_col, INDEX(_xlpm.data, , 3), _xlpm.target_date, DATE(YEAR($B$1), MONTH($B$1), E$7), _xlpm.filtered, _xlfn._xlws.FILTER(_xlpm.name_col, (_xlpm.date_col = _xlpm.target_date) * (_xlpm.loc_col =$B16), ""), IF(_xlpm.filtered="", "", _xlpm.filtered) )} | F16: {=_xlfn.LET( _xlpm.data, 表格3_5[[Date]:[Location]], _xlpm.date_col, INDEX(_xlpm.data, , 1), _xlpm.name_col, INDEX(_xlpm.data, , 2), _xlpm.loc_col, INDEX(_xlpm.data, , 3), _xlpm.target_date, DATE(YEAR($B$1), MONTH($B$1), F$7), _xlpm.filtered, _xlfn._xlws.FILTER(_xlpm.name_col, (_xlpm.date_col = _xlpm.target_date) * (_xlpm.loc_col =$B16), ""), IF(_xlpm.filtered="", "", _xlpm.filtered) )} | G16: {=_xlfn.LET( _xlpm.data, 表格3_5[[Date]:[Location]], _xlpm.date_col, INDEX(_xlpm.data, , 1), _xlpm.name_col, INDEX(_xlpm.data, , 2), _xlpm.loc_col, INDEX(_xlpm.data, , 3), _xlpm.target_date, DATE(YEAR($B$1), MONTH($B$1), G$7), _xlpm.filtered, _xlfn._xlws.FILTER(_xlpm.name_col, (_xlpm.date_col = _xlpm.target_date) * (_xlpm.loc_col =$B16), ""), IF(_xlpm.filtered="", "", _xlpm.filtered) )} -> Joe | H16: {=_xlfn.LET( _xlpm.data, 表格3_5[[Date]:[Location]], _xlpm.date_col, INDEX(_xlpm.data, , 1), _xlpm.name_col, INDEX(_xlpm.data, , 2), _xlpm.loc_col, INDEX(_xlpm.data, , 3), _xlpm.target_date, DATE(YEAR($B$1), MONTH($B$1), H$7), _xlpm.filtered, _xlfn._xlws.FILTER(_xlpm.name_col, (_xlpm.date_col = _xlpm.target_date) * (_xlpm.loc_col =$B16), ""), IF(_xlpm.filtered="", "", _xlpm.filtered) )} -> Joe | I16: {=_xlfn.LET( _xlpm.data, 表格3_5[[Date]:[Location]], _xlpm.date_col, INDEX(_xlpm.data, , 1), _xlpm.name_col, INDEX(_xlpm.data, , 2), _xlpm.loc_col, INDEX(_xlpm.data, , 3), _xlpm.target_date, DATE(YEAR($B$1), MONTH($B$1), I$7), _xlpm.filtered, _xlfn._xlws.FILTER(_xlpm.name_col, (_xlpm.date_col = _xlpm.target_date) * (_xlpm.loc_col =$B16), ""), IF(_xlpm.filtered="", "", _xlpm.filtered) )} -> Joe | J16: {=_xlfn.LET( _xlpm.data, 表格3_5[[Date]:[Location]], _xlpm.date_col, INDEX(_xlpm.data, , 1), _xlpm.name_col, INDEX(_xlpm.data, , 2), _xlpm.loc_col, INDEX(_xlpm.data, , 3), _xlpm.target_date, DATE(YEAR($B$1), MONTH($B$1), J$7), _xlpm.filtered, _xlfn._xlws.FILTER(_xlpm.name_col, (_xlpm.date_col = _xlpm.target_date) * (_xlpm.loc_col =$B16), ""), IF(_xlpm.filtered="", "", _xlpm.filtered) )} | ... AG16: {=_xlfn.LET( _xlpm.data, 表格3_5[[Date]:[Location]], _xlpm.date_col, INDEX(_xlpm.data, , 1), _xlpm.name_col, INDEX(_xlpm.data, , 2), _xlpm.loc_col, INDEX(_xlpm.data, , 3), _xlpm.target_date, DATE(YEAR($B$1), MONTH($B$1), AG$7), _xlpm.filtered, _xlfn._xlws.FILTER(_xlpm.name_col, (_xlpm.date_col = _xlpm.target_date) * (_xlpm.loc_col =$B16), ""), IF(_xlpm.filtered="", "", _xlpm.filtered) )} | AH16: =COUNTIF(C16:AG16,"?*") -> 12 | AI16: =AH16*8 -> 96 | AL16: =B16 -> Tai Po Yata | AM16: =IF(C16=".",C16,IF(VLOOKUP($AL16&C$1+C11&C16, 工作表1!$C:$V,1,) > 0,C16,"ERROR")) -> #VALUE! | AN16: =IF(D16=".",D16,IF(VLOOKUP($AL16&D$1+D11&D16, 工作表1!$C:$V,1,) > 0,D16,"ERROR")) -> #VALUE! | AO16: =IF(E16=".",E16,IF(VLOOKUP($AL16&E$1+E11&E16, 工作表1!$C:$V,1,) > 0,E16,"ERROR")) -> #VALUE! | AP16: =IF(F16=".",F16,IF(VLOOKUP($AL16&F$1+F11&F16, 工作表1!$C:$V,1,) > 0,F16,"ERROR")) -> #VALUE! | AQ16: =IF(G16=".",G16,IF(VLOOKUP($AL16&G$1+G11&G16, 工作表1!$C:$V,1,) > 0,G16,"ERROR")) -> #VALUE! | AR16: =IF(H16=".",H16,IF(VLOOKUP($AL16&H$1+H11&H16, 工作表1!$C:$V,1,) > 0,H16,"ERROR")) -> #VALUE! | AS16: =IF(I16=".",I16,IF(VLOOKUP($AL16&I$1+I11&I16, 工作表1!$C:$V,1,) > 0,I16,"ERROR")) -> #VALUE! | AT16: =IF(J16=".",J16,IF(VLOOKUP($AL16&J$1+J11&J16, 工作表1!$C:$V,1,) > 0,J16,"ERROR")) -> #VALUE! | ... BQ16: =IF(AG16=".",AG16,IF(VLOOKUP($AL16&AG$1+AG11&AG16, 工作表1!$C:$V,1,) > 0,AG16,"ERROR")) -> #VALUE! | BR16: =IF(#REF!=".",#REF!,IF(VLOOKUP($AL16&#REF!+#REF!&#REF!, 工作表1!$C:$V,1,) > 0,#REF!,"ERROR")) -> #REF! | BS16: =IF(#REF!=".",#REF!,IF(VLOOKUP($AL16&#REF!+#REF!&#REF!, 工作表1!$C:$V,1,) > 0,#REF!,"ERROR")) -> #REF!
A17: {=_xlfn.LET( _xlpm.data, C17:AG17, _xlpm.removeList, {" off","."," SL","xxx"}, _xlpm.cleaned, TRIM(_xlfn.REDUCE(_xlpm.data, _xlpm.removeList, _xlfn.LAMBDA(_xlpm.arr,_xlpm.str, SUBSTITUTE(_xlpm.arr, _xlpm.str, "")))), _xlpm.first, _xlfn._xlws.FILTER(_xlpm.cleaned, _xlpm.cleaned <> ""), INDEX(_xlpm.first, 1) )} -> Rebacca | B17: Tai Wan Fortress | C17: {=_xlfn.LET( _xlpm.data, 表格3_5[[Date]:[Location]], _xlpm.date_col, INDEX(_xlpm.data, , 1), _xlpm.name_col, INDEX(_xlpm.data, , 2), _xlpm.loc_col, INDEX(_xlpm.data, , 3), _xlpm.target_date, DATE(YEAR($B$1), MONTH($B$1), C$7), _xlpm.filtered, _xlfn._xlws.FILTER(_xlpm.name_col, (_xlpm.date_col = _xlpm.target_date) * (_xlpm.loc_col =$B17), ""), IF(_xlpm.filtered="", "", _xlpm.filtered) )} | D17: {=_xlfn.LET( _xlpm.data, 表格3_5[[Date]:[Location]], _xlpm.date_col, INDEX(_xlpm.data, , 1), _xlpm.name_col, INDEX(_xlpm.data, , 2), _xlpm.loc_col, INDEX(_xlpm.data, , 3), _xlpm.target_date, DATE(YEAR($B$1), MONTH($B$1), D$7), _xlpm.filtered, _xlfn._xlws.FILTER(_xlpm.name_col, (_xlpm.date_col = _xlpm.target_date) * (_xlpm.loc_col =$B17), ""), IF(_xlpm.filtered="", "", _xlpm.filtered) )} | E17: {=_xlfn.LET( _xlpm.data, 表格3_5[[Date]:[Location]], _xlpm.date_col, INDEX(_xlpm.data, , 1), _xlpm.name_col, INDEX(_xlpm.data, , 2), _xlpm.loc_col, INDEX(_xlpm.data, , 3), _xlpm.target_date, DATE(YEAR($B$1), MONTH($B$1), E$7), _xlpm.filtered, _xlfn._xlws.FILTER(_xlpm.name_col, (_xlpm.date_col = _xlpm.target_date) * (_xlpm.loc_col =$B17), ""), IF(_xlpm.filtered="", "", _xlpm.filtered) )} | F17: {=_xlfn.LET( _xlpm.data, 表格3_5[[Date]:[Location]], _xlpm.date_col, INDEX(_xlpm.data, , 1), _xlpm.name_col, INDEX(_xlpm.data, , 2), _xlpm.loc_col, INDEX(_xlpm.data, , 3), _xlpm.target_date, DATE(YEAR($B$1), MONTH($B$1), F$7), _xlpm.filtered, _xlfn._xlws.FILTER(_xlpm.name_col, (_xlpm.date_col = _xlpm.target_date) * (_xlpm.loc_col =$B17), ""), IF(_xlpm.filtered="", "", _xlpm.filtered) )} | G17: {=_xlfn.LET( _xlpm.data, 表格3_5[[Date]:[Location]], _xlpm.date_col, INDEX(_xlpm.data, , 1), _xlpm.name_col, INDEX(_xlpm.data, , 2), _xlpm.loc_col, INDEX(_xlpm.data, , 3), _xlpm.target_date, DATE(YEAR($B$1), MONTH($B$1), G$7), _xlpm.filtered, _xlfn._xlws.FILTER(_xlpm.name_col, (_xlpm.date_col = _xlpm.target_date) * (_xlpm.loc_col =$B17), ""), IF(_xlpm.filtered="", "", _xlpm.filtered) )} -> Rebacca | H17: {=_xlfn.LET( _xlpm.data, 表格3_5[[Date]:[Location]], _xlpm.date_col, INDEX(_xlpm.data, , 1), _xlpm.name_col, INDEX(_xlpm.data, , 2), _xlpm.loc_col, INDEX(_xlpm.data, , 3), _xlpm.target_date, DATE(YEAR($B$1), MONTH($B$1), H$7), _xlpm.filtered, _xlfn._xlws.FILTER(_xlpm.name_col, (_xlpm.date_col = _xlpm.target_date) * (_xlpm.loc_col =$B17), ""), IF(_xlpm.filtered="", "", _xlpm.filtered) )} -> Rebacca | I17: {=_xlfn.LET( _xlpm.data, 表格3_5[[Date]:[Location]], _xlpm.date_col, INDEX(_xlpm.data, , 1), _xlpm.name_col, INDEX(_xlpm.data, , 2), _xlpm.loc_col, INDEX(_xlpm.data, , 3), _xlpm.target_date, DATE(YEAR($B$1), MONTH($B$1), I$7), _xlpm.filtered, _xlfn._xlws.FILTER(_xlpm.name_col, (_xlpm.date_col = _xlpm.target_date) * (_xlpm.loc_col =$B17), ""), IF(_xlpm.filtered="", "", _xlpm.filtered) )} -> Rebacca | J17: {=_xlfn.LET( _xlpm.data, 表格3_5[[Date]:[Location]], _xlpm.date_col, INDEX(_xlpm.data, , 1), _xlpm.name_col, INDEX(_xlpm.data, , 2), _xlpm.loc_col, INDEX(_xlpm.data, , 3), _xlpm.target_date, DATE(YEAR($B$1), MONTH($B$1), J$7), _xlpm.filtered, _xlfn._xlws.FILTER(_xlpm.name_col, (_xlpm.date_col = _xlpm.target_date) * (_xlpm.loc_col =$B17), ""), IF(_xlpm.filtered="", "", _xlpm.filtered) )} | ... AG17: {=_xlfn.LET( _xlpm.data, 表格3_5[[Date]:[Location]], _xlpm.date_col, INDEX(_xlpm.data, , 1), _xlpm.name_col, INDEX(_xlpm.data, , 2), _xlpm.loc_col, INDEX(_xlpm.data, , 3), _xlpm.target_date, DATE(YEAR($B$1), MONTH($B$1), AG$7), _xlpm.filtered, _xlfn._xlws.FILTER(_xlpm.name_col, (_xlpm.date_col = _xlpm.target_date) * (_xlpm.loc_col =$B17), ""), IF(_xlpm.filtered="", "", _xlpm.filtered) )} | AH17: =COUNTIF(C17:AG17,"?*") -> 12 | AI17: =AH17*8 -> 96 | AL17: =B17 -> Tai Wan Fortress | AM17: =IF(C17=".",C17,IF(VLOOKUP($AL17&C$1+C12&C17, 工作表1!$C:$V,1,) > 0,C17,"ERROR")) -> #VALUE! | AN17: =IF(D17=".",D17,IF(VLOOKUP($AL17&D$1+D12&D17, 工作表1!$C:$V,1,) > 0,D17,"ERROR")) -> #VALUE! | AO17: =IF(E17=".",E17,IF(VLOOKUP($AL17&E$1+E12&E17, 工作表1!$C:$V,1,) > 0,E17,"ERROR")) -> #VALUE! | AP17: =IF(F17=".",F17,IF(VLOOKUP($AL17&F$1+F12&F17, 工作表1!$C:$V,1,) > 0,F17,"ERROR")) -> #VALUE! | AQ17: =IF(G17=".",G17,IF(VLOOKUP($AL17&G$1+G12&G17, 工作表1!$C:$V,1,) > 0,G17,"ERROR")) -> #VALUE! | AR17: =IF(H17=".",H17,IF(VLOOKUP($AL17&H$1+H12&H17, 工作表1!$C:$V,1,) > 0,H17,"ERROR")) -> #VALUE! | AS17: =IF(I17=".",I17,IF(VLOOKUP($AL17&I$1+I12&I17, 工作表1!$C:$V,1,) > 0,I17,"ERROR")) -> #VALUE! | AT17: =IF(J17=".",J17,IF(VLOOKUP($AL17&J$1+J12&J17, 工作表1!$C:$V,1,) > 0,J17,"ERROR")) -> #VALUE! | ... BQ17: =IF(AG17=".",AG17,IF(VLOOKUP($AL17&AG$1+AG12&AG17, 工作表1!$C:$V,1,) > 0,AG17,"ERROR")) -> #VALUE! | BR17: =IF(#REF!=".",#REF!,IF(VLOOKUP($AL17&#REF!+#REF!&#REF!, 工作表1!$C:$V,1,) > 0,#REF!,"ERROR")) -> #REF! | BS17: =IF(#REF!=".",#REF!,IF(VLOOKUP($AL17&#REF!+#REF!&#REF!, 工作表1!$C:$V,1,) > 0,#REF!,"ERROR")) -> #REF!
