Workbook

Sheet Roster
A1: 2026 | F1: 已入數 | G1: 0數 | H1: OFF | I1: - | J1: 更正
A2: 3 | F2: 已入數 | G2: 0數 | H2: OFF | I2: - | J2: 更正 | AH2: =+AH3*60 -> 314550
B3: =TEXT($A$1&"/"&$A$2&"/"&B4,"ddd") -> Sun | C3: =TEXT($A$1&"/"&$A$2&"/"&C4,"ddd") -> Mon | D3: =TEXT($A$1&"/"&$A$2&"/"&D4,"ddd") -> Tue | E3: =TEXT($A$1&"/"&$A$2&"/"&E4,"ddd") -> Wed | F3: =TEXT($A$1&"/"&$A$2&"/"&F4,"ddd") -> Thu | G3: =TEXT($A$1&"/"&$A$2&"/"&G4,"ddd") -> Fri | H3: =TEXT($A$1&"/"&$A$2&"/"&H4,"ddd") -> Sat | I3: =TEXT($A$1&"/"&$A$2&"/"&I4,"ddd") -> Sun | ... AF3: =TEXT($A$1&"/"&$A$2&"/"&AF4,"ddd") -> Tue | AG3: =SUM(AG5:AG69) -> 652 | AH3: =SUM(AH5:AH69) -> 5242.5
B4: 1 | C4: 2 | D4: 3 | E4: 4 | F4: 5 | G4: 6 | H4: 7 | I4: 8 | J4: 9 | K4: 10 | L4: 11 | M4: 12 | N4: 13 | O4: 14 | P4: 15 | Q4: 16 | R4: 17 | S4: 18 | T4: 19 | U4: 20 | V4: 21 | W4: 22 | X4: 23 | Y4: 24 | Z4: 25 | AA4: 26 | AB4: 27 | AC4: 28 | AD4: 29 | AE4: 30 | AF4: 31 | AI4: Name1 | AJ4: Full Name1 | AK4: No. | AL4: $$$ | AM4: Allowance
A5: Kornhill Aeon | B5: May C | C5: May C | D5: May C | E5: May C off | F5: May C | G5: May C | H5: May C | I5: May C | J5: May C off | K5: May C | L5: May C | M5: May C | N5: May C | O5: May C off | P5: May C | Q5: May C | R5: May C | S5: May C off | T5: May C off | U5: May C | V5: May C | W5: May C | X5: May C | Y5: May C off | Z5: May C off | AA5: May C | AB5: May C | AC5: May C | AD5: May C | AE5: May C off | AF5: May C off | AG5: =COUNTA(B5:AF5)-COUNTIF(B5:AF5,"."&"*")-COUNTIF(B5:AF5,"off")-COUNTIF(B5:AF5,"SL"&" "&"*")-COUNTIF(B5:AF5,"PH"&" "&"*")-COUNTIF(B5:AF5,"AL"&" "&"*")-COUNTIF(B5:AF5,"CL"&" "&"*")-COUNTIF(B5:AF5,"Typhoon"&" "&"*")-COUNTIF(B5:AF5,"*"&"off")-COUNTIF(B5:AF5," "&"*") -> 22 | AH5: =AG5*8 -> 176 | AI5: {=_xlfn.LET( _xlpm.data, B5:AF5, _xlpm.removeList, {" off","."," SL","xxx"}, _xlpm.cleaned, TRIM(_xlfn.REDUCE(_xlpm.data, _xlpm.removeList, _xlfn.LAMBDA(_xlpm.arr,_xlpm.str, SUBSTITUTE(_xlpm.arr, _xlpm.str, "")))), _xlpm.first, _xlfn._xlws.FILTER(_xlpm.cleaned, _xlpm.cleaned <> ""), INDEX(_xlpm.first, 1) )} -> May C | AJ5: {=_xlfn._xlws.FILTER(表格6[Full Name],(表格6[Name]=AI5)+(表格6[Name]&"_1"=AI5)+(表格6[Name]&"_2"=AI5)+(表格6[Name]&"_3"=AI5)+(表格6[Name]&"_4"=AI5)+(表格6[Name]&"_5"=AI5))} -> Cheng Muk Kiu | AK5: {=_xlfn._xlws.FILTER(三國演義!$C$13:$C$80,三國演義!$E$13:$E$80=Roster!AI5)} -> 1 | AL5: 55 | AM5: 30 | AN5: 0.02
A6: Vcity_1 Fortress | B6: Ivy Wong_1 | C6: . | D6: . | E6: . | F6: . | G6: . | H6: . | I6: . | J6: . | K6: . | L6: . | M6: . | N6: . | O6: Ivy Wong_1 | P6: Ivy Wong_1 | Q6: . | R6: . | S6: . | T6: . | U6: . | V6: Ivy Wong_1 | W6: Ivy Wong_1 | X6: . | Y6: . | Z6: Ivy Wong_1 | AA6: . | AB6: . | AC6: Ivy Wong_1 | AD6: . | AE6: . | AF6: . | AG6: =COUNTA(B6:AF6)-COUNTIF(B6:AF6,"."&"*")-COUNTIF(B6:AF6,"off")-COUNTIF(B6:AF6,"SL"&" "&"*")-COUNTIF(B6:AF6,"PH"&" "&"*")-COUNTIF(B6:AF6,"AL"&" "&"*")-COUNTIF(B6:AF6,"CL"&" "&"*")-COUNTIF(B6:AF6,"Typhoon"&" "&"*")-COUNTIF(B6:AF6,"*"&"off")-COUNTIF(B6:AF6," "&"*") -> 7 | AH6: =AG6*8 -> 56 | AI6: {=_xlfn.LET( _xlpm.data, B6:AF6, _xlpm.removeList, {" off","."," SL","xxx"}, _xlpm.cleaned, TRIM(_xlfn.REDUCE(_xlpm.data, _xlpm.removeList, _xlfn.LAMBDA(_xlpm.arr,_xlpm.str, SUBSTITUTE(_xlpm.arr, _xlpm.str, "")))), _xlpm.first, _xlfn._xlws.FILTER(_xlpm.cleaned, _xlpm.cleaned <> ""), INDEX(_xlpm.first, 1) )} -> Ivy Wong_1 | AJ6: {=_xlfn._xlws.FILTER(表格6[Full Name],(表格6[Name]=AI6)+(表格6[Name]&"_1"=AI6)+(表格6[Name]&"_2"=AI6)+(表格6[Name]&"_3"=AI6)+(表格6[Name]&"_4"=AI6)+(表格6[Name]&"_5"=AI6))} -> Wong Wai Chu | AK6: {=_xlfn._xlws.FILTER(三國演義!$C$13:$C$80,三國演義!$E$13:$E$80=Roster!AI6)} -> 2 | AL6: 60 | AM6: 0 | AN6: 0.02
A7: Vcity_2 Fortress | B7: . | C7: . | D7: . | E7: . | F7: . | G7: . | H7: Kit_3 | I7: Kit_3 | J7: . | K7: . | L7: . | M7: . | N7: . | O7: . | P7: . | Q7: . | R7: . | S7: . | T7: . | U7: . | V7: . | W7: . | X7: . | Y7: . | Z7: . | AA7: . | AB7: . | AC7: . | AD7: . | AE7: . | AF7: . | AG7: =COUNTA(B7:AF7)-COUNTIF(B7:AF7,"."&"*")-COUNTIF(B7:AF7,"off")-COUNTIF(B7:AF7,"SL"&" "&"*")-COUNTIF(B7:AF7,"PH"&" "&"*")-COUNTIF(B7:AF7,"AL"&" "&"*")-COUNTIF(B7:AF7,"CL"&" "&"*")-COUNTIF(B7:AF7,"Typhoon"&" "&"*")-COUNTIF(B7:AF7,"*"&"off")-COUNTIF(B7:AF7," "&"*") -> 2 | AH7: =AG7*8 -> 16 | AI7: {=_xlfn.LET( _xlpm.data, B7:AF7, _xlpm.removeList, {" off","."," SL","xxx"}, _xlpm.cleaned, TRIM(_xlfn.REDUCE(_xlpm.data, _xlpm.removeList, _xlfn.LAMBDA(_xlpm.arr,_xlpm.str, SUBSTITUTE(_xlpm.arr, _xlpm.str, "")))), _xlpm.first, _xlfn._xlws.FILTER(_xlpm.cleaned, _xlpm.cleaned <> ""), INDEX(_xlpm.first, 1) )} -> Kit_3 | AJ7: {=_xlfn._xlws.FILTER(表格6[Full Name],(表格6[Name]=AI7)+(表格6[Name]&"_1"=AI7)+(表格6[Name]&"_2"=AI7)+(表格6[Name]&"_3"=AI7)+(表格6[Name]&"_4"=AI7)+(表格6[Name]&"_5"=AI7))} -> Li Wenjie | AK7: {=_xlfn._xlws.FILTER(三國演義!$C$13:$C$80,三國演義!$E$13:$E$80=Roster!AI7)} -> 3 | AL7: 60
A8: Diamond Hill Fortress | B8: Vicky L | C8: Vicky L | D8: Vicky L off | E8: Vicky L | F8: Vicky L off | G8: Vicky L | H8: Vicky L | I8: Vicky L | J8: Vicky L off | K8: Vicky L off | L8: Vicky L off | M8: Vicky L off | N8: Vicky L | O8: Vicky L | P8: Vicky L | Q8: Vicky L | R8: Vicky L | S8: Vicky L | T8: Vicky L | U8: Vicky L off | V8: Vicky L | W8: Vicky L | X8: Vicky L | Y8: Vicky L | Z8: Vicky L | AA8: Vicky L | AB8: Vicky L | AC8: Vicky L | AD8: Vicky L | AE8: Vicky L | AF8: Vicky L | AG8: =COUNTA(B8:AF8)-COUNTIF(B8:AF8,"."&"*")-COUNTIF(B8:AF8,"off")-COUNTIF(B8:AF8,"SL"&" "&"*")-COUNTIF(B8:AF8,"PH"&" "&"*")-COUNTIF(B8:AF8,"AL"&" "&"*")-COUNTIF(B8:AF8,"CL"&" "&"*")-COUNTIF(B8:AF8,"Typhoon"&" "&"*")-COUNTIF(B8:AF8,"*"&"off")-COUNTIF(B8:AF8," "&"*") -> 24 | AH8: =AG8*8 -> 192 | AI8: {=_xlfn.LET( _xlpm.data, B8:AF8, _xlpm.removeList, {" off","."," SL","xxx"}, _xlpm.cleaned, TRIM(_xlfn.REDUCE(_xlpm.data, _xlpm.removeList, _xlfn.LAMBDA(_xlpm.arr,_xlpm.str, SUBSTITUTE(_xlpm.arr, _xlpm.str, "")))), _xlpm.first, _xlfn._xlws.FILTER(_xlpm.cleaned, _xlpm.cleaned <> ""), INDEX(_xlpm.first, 1) )} -> Vicky L | AJ8: {=_xlfn._xlws.FILTER(表格6[Full Name],(表格6[Name]=AI8)+(表格6[Name]&"_1"=AI8)+(表格6[Name]&"_2"=AI8)+(表格6[Name]&"_3"=AI8)+(表格6[Name]&"_4"=AI8)+(表格6[Name]&"_5"=AI8))} -> Leung Ching | AK8: {=_xlfn._xlws.FILTER(三國演義!$C$13:$C$80,三國演義!$E$13:$E$80=Roster!AI8)} -> 4 | AL8: 60 | AM8: 0 | AN8: 0.02
A9: Good Hope Fortress | B9: Michelle | C9: Michelle off | D9: Michelle off | E9: Michelle off | F9: Michelle | G9: Michelle | H9: Michelle | I9: Michelle | J9: Michelle off | K9: Michelle off | L9: Michelle | M9: Michelle | N9: Michelle | O9: Michelle | P9: Michelle | Q9: Michelle off | R9: Michelle | S9: Michelle | T9: Michelle | U9: Michelle | V9: Michelle | W9: Michelle | X9: Michelle off | Y9: Michelle off | Z9: Michelle | AA9: Michelle | AB9: Michelle | AC9: Michelle | AD9: Michelle | AE9: Michelle off | AF9: Michelle | AG9: =COUNTA(B9:AF9)-COUNTIF(B9:AF9,"."&"*")-COUNTIF(B9:AF9,"off")-COUNTIF(B9:AF9,"SL"&" "&"*")-COUNTIF(B9:AF9,"PH"&" "&"*")-COUNTIF(B9:AF9,"AL"&" "&"*")-COUNTIF(B9:AF9,"CL"&" "&"*")-COUNTIF(B9:AF9,"Typhoon"&" "&"*")-COUNTIF(B9:AF9,"*"&"off")-COUNTIF(B9:AF9," "&"*") -> 22 | AH9: =AG9*8 -> 176 | AI9: {=_xlfn.LET( _xlpm.data, B9:AF9, _xlpm.removeList, {" off","."," SL","xxx"}, _xlpm.cleaned, TRIM(_xlfn.REDUCE(_xlpm.data, _xlpm.removeList, _xlfn.LAMBDA(_xlpm.arr,_xlpm.str, SUBSTITUTE(_xlpm.arr, _xlpm.str, "")))), _xlpm.first, _xlfn._xlws.FILTER(_xlpm.cleaned, _xlpm.cleaned <> ""), INDEX(_xlpm.first, 1) )} -> Michelle | AJ9: {=_xlfn._xlws.FILTER(表格6[Full Name],(表格6[Name]=AI9)+(表格6[Name]&"_1"=AI9)+(表格6[Name]&"_2"=AI9)+(表格6[Name]&"_3"=AI9)+(表格6[Name]&"_4"=AI9)+(表格6[Name]&"_5"=AI9))} -> Lo Muk Chun | AK9: {=_xlfn._xlws.FILTER(三國演義!$C$13:$C$80,三國演義!$E$13:$E$80=Roster!AI9)} -> 5 | AL9: 60 | AM9: 0 | AN9: 0.02
A10: Whampoa Aeon | B10: Jessica | C10: Jessica | D10: Jessica | E10: Jessica off | F10: Jessica off | G10: Jessica | H10: Jessica | I10: Jessica | J10: Jessica | K10: Jessica off | L10: Jessica off | M10: Jessica | N10: Jessica | O10: Jessica | P10: Jessica | Q10: Jessica off | R10: Jessica off | S10: Jessica off | T10: Jessica | U10: Jessica | V10: Jessica | W10: Jessica | X10: Jessica | Y10: Jessica | Z10: Jessica off | AA10: Jessica off | AB10: Jessica | AC10: Jessica | AD10: Jessica off | AE10: Jessica off | AF10: Jessica | AG10: =COUNTA(B10:AF10)-COUNTIF(B10:AF10,"."&"*")-COUNTIF(B10:AF10,"off")-COUNTIF(B10:AF10,"SL"&" "&"*")-COUNTIF(B10:AF10,"PH"&" "&"*")-COUNTIF(B10:AF10,"AL"&" "&"*")-COUNTIF(B10:AF10,"CL"&" "&"*")-COUNTIF(B10:AF10,"Typhoon"&" "&"*")-COUNTIF(B10:AF10,"*"&"off")-COUNTIF(B10:AF10," "&"*") -> 20 | AH10: =AG10*8 -> 160 | AI10: {=_xlfn.LET( _xlpm.data, B10:AF10, _xlpm.removeList, {" off","."," SL","xxx"}, _xlpm.cleaned, TRIM(_xlfn.REDUCE(_xlpm.data, _xlpm.removeList, _xlfn.LAMBDA(_xlpm.arr,_xlpm.str, SUBSTITUTE(_xlpm.arr, _xlpm.str, "")))), _xlpm.first, _xlfn._xlws.FILTER(_xlpm.cleaned, _xlpm.cleaned <> ""), INDEX(_xlpm.first, 1) )} -> Jessica | AJ10: {=_xlfn._xlws.FILTER(表格6[Full Name],(表格6[Name]=AI10)+(表格6[Name]&"_1"=AI10)+(表格6[Name]&"_2"=AI10)+(表格6[Name]&"_3"=AI10)+(表格6[Name]&"_4"=AI10)+(表格6[Name]&"_5"=AI10))} -> Chiu Kan | AK10: {=_xlfn._xlws.FILTER(三國演義!$C$13:$C$80,三國演義!$E$13:$E$80=Roster!AI10)} -> 6 | AL10: 55 | AM10: 80 | AN10: 0.02
A11: TKW Suning | B11: Kitty Yeung | C11: Kitty Yeung | D11: Kitty Yeung | E11: Kitty Yeung | F11: Kitty Yeung off | G11: Kitty Yeung off | H11: Kitty Yeung | I11: Kitty Yeung | J11: Kitty Yeung | K11: Kitty Yeung | L11: Kitty Yeung | M11: Kitty Yeung off | N11: Kitty Yeung off | O11: Kitty Yeung | P11: Kitty Yeung | Q11: Kitty Yeung | R11: Kitty Yeung | S11: Kitty Yeung off | T11: Kitty Yeung off | U11: Kitty Yeung off | V11: Kitty Yeung | W11: Kitty Yeung | X11: Kitty Yeung | Y11: Kitty Yeung | Z11: Kitty Yeung | AA11: Kitty Yeung off | AB11: Kitty Yeung off | AC11: Kitty Yeung | AD11: Kitty Yeung | AE11: Kitty Yeung | AF11: Kitty Yeung | AG11: =COUNTA(B11:AF11)-COUNTIF(B11:AF11,"."&"*")-COUNTIF(B11:AF11,"off")-COUNTIF(B11:AF11,"SL"&" "&"*")-COUNTIF(B11:AF11,"PH"&" "&"*")-COUNTIF(B11:AF11,"AL"&" "&"*")-COUNTIF(B11:AF11,"CL"&" "&"*")-COUNTIF(B11:AF11,"Typhoon"&" "&"*")-COUNTIF(B11:AF11,"*"&"off")-COUNTIF(B11:AF11," "&"*") -> 22 | AH11: =AG11*8 -> 176 | AI11: {=_xlfn.LET( _xlpm.data, B11:AF11, _xlpm.removeList, {" off","."," SL","xxx"}, _xlpm.cleaned, TRIM(_xlfn.REDUCE(_xlpm.data, _xlpm.removeList, _xlfn.LAMBDA(_xlpm.arr,_xlpm.str, SUBSTITUTE(_xlpm.arr, _xlpm.str, "")))), _xlpm.first, _xlfn._xlws.FILTER(_xlpm.cleaned, _xlpm.cleaned <> ""), INDEX(_xlpm.first, 1) )} -> Kitty Yeung | AJ11: {=_xlfn._xlws.FILTER(表格6[Full Name],(表格6[Name]=AI11)+(表格6[Name]&"_1"=AI11)+(表格6[Name]&"_2"=AI11)+(表格6[Name]&"_3"=AI11)+(表格6[Name]&"_4"=AI11)+(表格6[Name]&"_5"=AI11))} -> Yeung Lai Shan | AK11: {=_xlfn._xlws.FILTER(三國演義!$C$13:$C$80,三國演義!$E$13:$E$80=Roster!AI11)} -> 7 | AL11: 60 | AM11: 0 | AN11: 0.02
A12: Tai koo Broadway | B12: Amy Or_1 | C12: . | D12: . | E12: . | F12: . | G12: . | H12: Amy Or_1 | I12: . | J12: . | K12: . | L12: . | M12: . | N12: . | O12: . | P12: . | Q12: . | R12: . | S12: . | T12: . | U12: . | V12: . | W12: . | X12: . | Y12: . | Z12: . | AA12: . | AB12: . | AC12: Amy Or_1 | AD12: Amy Or_1 | AE12: . | AF12: . | AG12: =COUNTA(B12:AF12)-COUNTIF(B12:AF12,"."&"*")-COUNTIF(B12:AF12,"off")-COUNTIF(B12:AF12,"SL"&" "&"*")-COUNTIF(B12:AF12,"PH"&" "&"*")-COUNTIF(B12:AF12,"AL"&" "&"*")-COUNTIF(B12:AF12,"CL"&" "&"*")-COUNTIF(B12:AF12,"Typhoon"&" "&"*")-COUNTIF(B12:AF12,"*"&"off")-COUNTIF(B12:AF12," "&"*") -> 4 | AH12: =AG12*8 -> 32 | AI12: {=_xlfn.LET( _xlpm.data, B12:AF12, _xlpm.removeList, {" off","."," SL","xxx"}, _xlpm.cleaned, TRIM(_xlfn.REDUCE(_xlpm.data, _xlpm.removeList, _xlfn.LAMBDA(_xlpm.arr,_xlpm.str, SUBSTITUTE(_xlpm.arr, _xlpm.str, "")))), _xlpm.first, _xlfn._xlws.FILTER(_xlpm.cleaned, _xlpm.cleaned <> ""), INDEX(_xlpm.first, 1) )} -> Amy Or_1 | AJ12: {=_xlfn._xlws.FILTER(表格6[Full Name],(表格6[Name]=AI12)+(表格6[Name]&"_1"=AI12)+(表格6[Name]&"_2"=AI12)+(表格6[Name]&"_3"=AI12)+(表格6[Name]&"_4"=AI12)+(表格6[Name]&"_5"=AI12))} -> Or Sim Kiu | AK12: {=_xlfn._xlws.FILTER(三國演義!$C$13:$C$80,三國演義!$E$13:$E$80=Roster!AI12)} -> 8 | AL12: 55 | AM12: 30 | AN12: 0.02
A13: Diamond Hill_1 Broadway | B13: Fong_1 | C13: . | D13: . | E13: . | F13: . | G13: . | H13: Fong_1 | I13: Fong_1 | J13: . | K13: . | L13: . | M13: . | N13: . | O13: Fong_1 | P13: Fong_1 | Q13: . | R13: . | S13: . | T13: . | U13: . | V13: . | W13: . | X13: . | Y13: . | Z13: . | AA13: . | AB13: . | AC13: Fong_1 | AD13: Fong_1 | AE13: . | AF13: . | AG13: =COUNTA(B13:AF13)-COUNTIF(B13:AF13,"."&"*")-COUNTIF(B13:AF13,"off")-COUNTIF(B13:AF13,"SL"&" "&"*")-COUNTIF(B13:AF13,"PH"&" "&"*")-COUNTIF(B13:AF13,"AL"&" "&"*")-COUNTIF(B13:AF13,"CL"&" "&"*")-COUNTIF(B13:AF13,"Typhoon"&" "&"*")-COUNTIF(B13:AF13,"*"&"off")-COUNTIF(B13:AF13," "&"*") -> 7 | AH13: =AG13*8 -> 56 | AI13: {=_xlfn.LET( _xlpm.data, B13:AF13, _xlpm.removeList, {" off","."," SL","xxx"}, _xlpm.cleaned, TRIM(_xlfn.REDUCE(_xlpm.data, _xlpm.removeList, _xlfn.LAMBDA(_xlpm.arr,_xlpm.str, SUBSTITUTE(_xlpm.arr, _xlpm.str, "")))), _xlpm.first, _xlfn._xlws.FILTER(_xlpm.cleaned, _xlpm.cleaned <> ""), INDEX(_xlpm.first, 1) )} -> Fong_1 | AJ13: {=_xlfn._xlws.FILTER(表格6[Full Name],(表格6[Name]=AI13)+(表格6[Name]&"_1"=AI13)+(表格6[Name]&"_2"=AI13)+(表格6[Name]&"_3"=AI13)+(表格6[Name]&"_4"=AI13)+(表格6[Name]&"_5"=AI13))} -> Ng Nga Fong | AK13: {=_xlfn._xlws.FILTER(三國演義!$C$13:$C$80,三國演義!$E$13:$E$80=Roster!AI13)} -> 9 | AL13: 60 | AM13: 0 | AN13: 0.02
A14: Diamond Hill_2 Broadway | B14: . | C14: . | D14: . | E14: . | F14: . | G14: . | H14: . | I14: . | J14: . | K14: . | L14: . | M14: . | N14: . | O14: . | P14: . | Q14: . | R14: . | S14: . | T14: . | U14: . | V14: Mui Chan_2 | W14: Mui Chan_2 | X14: . | Y14: . | Z14: . | AA14: . | AB14: . | AC14: . | AD14: . | AE14: . | AF14: . | AG14: =COUNTA(B14:AF14)-COUNTIF(B14:AF14,"."&"*")-COUNTIF(B14:AF14,"off")-COUNTIF(B14:AF14,"SL"&" "&"*")-COUNTIF(B14:AF14,"PH"&" "&"*")-COUNTIF(B14:AF14,"AL"&" "&"*")-COUNTIF(B14:AF14,"CL"&" "&"*")-COUNTIF(B14:AF14,"Typhoon"&" "&"*")-COUNTIF(B14:AF14,"*"&"off")-COUNTIF(B14:AF14," "&"*") -> 2 | AH14: =AG14*8 -> 16 | AI14: {=_xlfn.LET( _xlpm.data, B14:AF14, _xlpm.removeList, {" off","."," SL","xxx"}, _xlpm.cleaned, TRIM(_xlfn.REDUCE(_xlpm.data, _xlpm.removeList, _xlfn.LAMBDA(_xlpm.arr,_xlpm.str, SUBSTITUTE(_xlpm.arr, _xlpm.str, "")))), _xlpm.first, _xlfn._xlws.FILTER(_xlpm.cleaned, _xlpm.cleaned <> ""), INDEX(_xlpm.first, 1) )} -> Mui Chan_2 | AJ14: {=_xlfn._xlws.FILTER(表格6[Full Name],(表格6[Name]=AI14)+(表格6[Name]&"_1"=AI14)+(表格6[Name]&"_2"=AI14)+(表格6[Name]&"_3"=AI14)+(表格6[Name]&"_4"=AI14)+(表格6[Name]&"_5"=AI14))} -> Chan So Mui | AK14: {=_xlfn._xlws.FILTER(三國演義!$C$13:$C$80,三國演義!$E$13:$E$80=Roster!AI14)} -> 10 | AL14: 60 | AM14: 0
A15: TW_1 Citistore | B15: Shan_1 | C15: Shan_1 | D15: . | E15: . | F15: Shan_1 | G15: Shan_1 | H15: Shan_1 | I15: Shan_1 | J15: Shan_1 | K15: Shan_1 | L15: . | M15: . | N15: . | O15: Shan_1 | P15: Shan_1 | Q15: Shan_1 | R15: Shan_1 | S15: . | T15: . | U15: Shan_1 | V15: Shan_1 | W15: Shan_1 | X15: Shan_1 | Y15: . | Z15: . | AA15: . | AB15: . | AC15: . | AD15: . | AE15: . | AF15: . | AG15: =COUNTA(B15:AF15)-COUNTIF(B15:AF15,"."&"*")-COUNTIF(B15:AF15,"off")-COUNTIF(B15:AF15,"SL"&" "&"*")-COUNTIF(B15:AF15,"PH"&" "&"*")-COUNTIF(B15:AF15,"AL"&" "&"*")-COUNTIF(B15:AF15,"CL"&" "&"*")-COUNTIF(B15:AF15,"Typhoon"&" "&"*")-COUNTIF(B15:AF15,"*"&"off")-COUNTIF(B15:AF15," "&"*") -> 16 | AH15: =AG15*9 -> 144 | AI15: {=_xlfn.LET( _xlpm.data, B15:AF15, _xlpm.removeList, {" off","."," SL","xxx"}, _xlpm.cleaned, TRIM(_xlfn.REDUCE(_xlpm.data, _xlpm.removeList, _xlfn.LAMBDA(_xlpm.arr,_xlpm.str, SUBSTITUTE(_xlpm.arr, _xlpm.str, "")))), _xlpm.first, _xlfn._xlws.FILTER(_xlpm.cleaned, _xlpm.cleaned <> ""), INDEX(_xlpm.first, 1) )} -> Shan_1 | AJ15: {=_xlfn._xlws.FILTER(表格6[Full Name],(表格6[Name]=AI15)+(表格6[Name]&"_1"=AI15)+(表格6[Name]&"_2"=AI15)+(表格6[Name]&"_3"=AI15)+(表格6[Name]&"_4"=AI15)+(表格6[Name]&"_5"=AI15))} -> Chiu Fung Shan | AK15: {=_xlfn._xlws.FILTER(三國演義!$C$13:$C$80,三國演義!$E$13:$E$80=Roster!AI15)} -> 11 | AL15: 60 | AM15: 0 | AN15: 0.02
A16: TW_2 Citistore | B16: . | C16: . | D16: Wendy Wong_1 | E16: Wendy Wong_1 | F16: . | G16: . | H16: . | I16: . | J16: . | K16: . | L16: Wendy Wong_1 | M16: . | N16: Wendy Wong_1 | O16: . | P16: . | Q16: . | R16: . | S16: Wendy Wong_1 | T16: Wendy Wong_1 | U16: . | V16: . | W16: . | X16: . | Y16: Wendy Wong_1 | Z16: . | AA16: . | AB16: . | AC16: . | AD16: . | AE16: . | AF16: . | AG16: =COUNTA(B16:AF16)-COUNTIF(B16:AF16,"."&"*")-COUNTIF(B16:AF16,"off")-COUNTIF(B16:AF16,"SL"&" "&"*")-COUNTIF(B16:AF16,"PH"&" "&"*")-COUNTIF(B16:AF16,"AL"&" "&"*")-COUNTIF(B16:AF16,"CL"&" "&"*")-COUNTIF(B16:AF16,"Typhoon"&" "&"*")-COUNTIF(B16:AF16,"*"&"off")-COUNTIF(B16:AF16," "&"*") -> 7 | AH16: =AG16*9 -> 63 | AI16: {=_xlfn.LET( _xlpm.data, B16:AF16, _xlpm.removeList, {" off","."," SL","xxx"}, _xlpm.cleaned, TRIM(_xlfn.REDUCE(_xlpm.data, _xlpm.removeList, _xlfn.LAMBDA(_xlpm.arr,_xlpm.str, SUBSTITUTE(_xlpm.arr, _xlpm.str, "")))), _xlpm.first, _xlfn._xlws.FILTER(_xlpm.cleaned, _xlpm.cleaned <> ""), INDEX(_xlpm.first, 1) )} -> Wendy Wong_1 | AJ16: {=_xlfn._xlws.FILTER(表格6[Full Name],(表格6[Name]=AI16)+(表格6[Name]&"_1"=AI16)+(表格6[Name]&"_2"=AI16)+(表格6[Name]&"_3"=AI16)+(表格6[Name]&"_4"=AI16)+(表格6[Name]&"_5"=AI16))} -> Wong Lai Ying | AK16: {=_xlfn._xlws.FILTER(三國演義!$C$13:$C$80,三國演義!$E$13:$E$80=Roster!AI16)} -> 12 | AL16: 60 | AM16: 0 | AN16: 0.02
A17: TW_3 Citistore | B17: . | C17: . | D17: . | E17: . | F17: . | G17: . | H17: . | I17: . | J17: . | K17: . | L17: . | M17: Mandy | N17: . | O17: . | P17: . | Q17: . | R17: . | S17: . | T17: . | U17: . | V17: . | W17: . | X17: . | Y17: . | Z17: . | AA17: . | AB17: . | AC17: . | AD17: . | AE17: . | AF17: . | AG17: =COUNTA(B17:AF17)-COUNTIF(B17:AF17,"."&"*")-COUNTIF(B17:AF17,"off")-COUNTIF(B17:AF17,"SL"&" "&"*")-COUNTIF(B17:AF17,"PH"&" "&"*")-COUNTIF(B17:AF17,"AL"&" "&"*")-COUNTIF(B17:AF17,"CL"&" "&"*")-COUNTIF(B17:AF17,"Typhoon"&" "&"*")-COUNTIF(B17:AF17,"*"&"off")-COUNTIF(B17:AF17," "&"*") -> 1 | AH17: =AG17*9 -> 9 | AI17: {=_xlfn.LET( _xlpm.data, B17:AF17, _xlpm.removeList, {" off","."," SL","xxx"}, _xlpm.cleaned, TRIM(_xlfn.REDUCE(_xlpm.data, _xlpm.removeList, _xlfn.LAMBDA(_xlpm.arr,_xlpm.str, SUBSTITUTE(_xlpm.arr, _xlpm.str, "")))), _xlpm.first, _xlfn._xlws.FILTER(_xlpm.cleaned, _xlpm.cleaned <> ""), INDEX(_xlpm.first, 1) )} -> Mandy | AJ17: {=_xlfn._xlws.FILTER(表格6[Full Name],(表格6[Name]=AI17)+(表格6[Name]&"_1"=AI17)+(表格6[Name]&"_2"=AI17)+(表格6[Name]&"_3"=AI17)+(表格6[Name]&"_4"=AI17)+(表格6[Name]&"_5"=AI17))} -> Ho Lai Sim | AK17: {=_xlfn._xlws.FILTER(三國演義!$C$13:$C$80,三國演義!$E$13:$E$80=Roster!AI17)} -> 13 | AL17: 60 | AM17: 0 | AN17: 0.02
A18: TW RS_1 Citistore | B18: . | C18: . | D18: . | E18: . | F18: . | G18: . | H18: . | I18: . | J18: . | K18: . | L18: . | M18: . | N18: . | O18: . | P18: . | Q18: . | R18: . | S18: . | T18: . | U18: . | V18: . | W18: . | X18: . | Y18: . | Z18: Shan_2 | AA18: Shan_2 | AB18: Shan_2 | AC18: Shan_2 | AD18: Shan_2 | AE18: Shan_2 | AF18: Shan_2 | AG18: =COUNTA(B18:AF18)-COUNTIF(B18:AF18,"."&"*")-COUNTIF(B18:AF18,"off")-COUNTIF(B18:AF18,"SL"&" "&"*")-COUNTIF(B18:AF18,"PH"&" "&"*")-COUNTIF(B18:AF18,"AL"&" "&"*")-COUNTIF(B18:AF18,"CL"&" "&"*")-COUNTIF(B18:AF18,"Typhoon"&" "&"*")-COUNTIF(B18:AF18,"*"&"off")-COUNTIF(B18:AF18," "&"*") -> 7 | AH18: =AG18*8 -> 56 | AI18: {=_xlfn.LET( _xlpm.data, B18:AF18, _xlpm.removeList, {" off","."," SL","xxx"}, _xlpm.cleaned, TRIM(_xlfn.REDUCE(_xlpm.data, _xlpm.removeList, _xlfn.LAMBDA(_xlpm.arr,_xlpm.str, SUBSTITUTE(_xlpm.arr, _xlpm.str, "")))), _xlpm.first, _xlfn._xlws.FILTER(_xlpm.cleaned, _xlpm.cleaned <> ""), INDEX(_xlpm.first, 1) )} -> Shan_2 | AJ18: {=_xlfn._xlws.FILTER(表格6[Full Name],(表格6[Name]=AI18)+(表格6[Name]&"_1"=AI18)+(表格6[Name]&"_2"=AI18)+(表格6[Name]&"_3"=AI18)+(表格6[Name]&"_4"=AI18)+(表格6[Name]&"_5"=AI18))} -> Chiu Fung Shan | AK18: {=_xlfn._xlws.FILTER(三國演義!$C$13:$C$80,三國演義!$E$13:$E$80=Roster!AI18)} -> 14 | AL18: 60 | AM18: 0
A19: TW RS_2 Citistore | B19: . | C19: . | D19: . | E19: . | F19: . | G19: . | H19: . | I19: . | J19: . | K19: . | L19: . | M19: . | N19: . | O19: . | P19: . | Q19: . | R19: . | S19: . | T19: . | U19: . | V19: . | W19: . | X19: . | Y19: . | Z19: . | AA19: . | AB19: Wendy Wong_2 | AC19: Wendy Wong_2 | AD19: Wendy Wong_2 | AE19: . | AF19: . | AG19: =COUNTA(B19:AF19)-COUNTIF(B19:AF19,"."&"*")-COUNTIF(B19:AF19,"off")-COUNTIF(B19:AF19,"SL"&" "&"*")-COUNTIF(B19:AF19,"PH"&" "&"*")-COUNTIF(B19:AF19,"AL"&" "&"*")-COUNTIF(B19:AF19,"CL"&" "&"*")-COUNTIF(B19:AF19,"Typhoon"&" "&"*")-COUNTIF(B19:AF19,"*"&"off")-COUNTIF(B19:AF19," "&"*") -> 3 | AH19: =AG19*8 -> 24 | AI19: {=_xlfn.LET( _xlpm.data, B19:AF19, _xlpm.removeList, {" off","."," SL","xxx"}, _xlpm.cleaned, TRIM(_xlfn.REDUCE(_xlpm.data, _xlpm.removeList, _xlfn.LAMBDA(_xlpm.arr,_xlpm.str, SUBSTITUTE(_xlpm.arr, _xlpm.str, "")))), _xlpm.first, _xlfn._xlws.FILTER(_xlpm.cleaned, _xlpm.cleaned <> ""), INDEX(_xlpm.first, 1) )} -> Wendy Wong_2 | AJ19: {=_xlfn._xlws.FILTER(表格6[Full Name],(表格6[Name]=AI19)+(表格6[Name]&"_1"=AI19)+(表格6[Name]&"_2"=AI19)+(表格6[Name]&"_3"=AI19)+(表格6[Name]&"_4"=AI19)+(表格6[Name]&"_5"=AI19))} -> Wong Lai Ying | AK19: {=_xlfn._xlws.FILTER(三國演義!$C$13:$C$80,三國演義!$E$13:$E$80=Roster!AI19)} -> 15 | AL19: 60 | AM19: 0
A20: Tai Koo Fortress | B20: Kiko | C20: Kiko | D20: Kiko | E20: Kiko off | F20: Kiko off | G20: Kiko off | H20: Kiko | I20: Kiko | J20: Kiko | K20: Kiko | L20: Kiko | M20: Kiko off | N20: Kiko off | O20: Kiko | P20: Kiko | Q20: Kiko | R20: Kiko | S20: Kiko | T20: Kiko off | U20: Kiko off | V20: Kiko | W20: Kiko | X20: Kiko | Y20: Kiko | Z20: Kiko | AA20: Kiko off | AB20: Kiko off | AC20: Kiko | AD20: Kiko | AE20: Kiko | AF20: Kiko | AG20: =COUNTA(B20:AF20)-COUNTIF(B20:AF20,"."&"*")-COUNTIF(B20:AF20,"off")-COUNTIF(B20:AF20,"SL"&" "&"*")-COUNTIF(B20:AF20,"PH"&" "&"*")-COUNTIF(B20:AF20,"AL"&" "&"*")-COUNTIF(B20:AF20,"CL"&" "&"*")-COUNTIF(B20:AF20,"Typhoon"&" "&"*")-COUNTIF(B20:AF20,"*"&"off")-COUNTIF(B20:AF20," "&"*") -> 22 | AH20: =AG20*8 -> 176 | AI20: {=_xlfn.LET( _xlpm.data, B20:AF20, _xlpm.removeList, {" off","."," SL","xxx"}, _xlpm.cleaned, TRIM(_xlfn.REDUCE(_xlpm.data, _xlpm.removeList, _xlfn.LAMBDA(_xlpm.arr,_xlpm.str, SUBSTITUTE(_xlpm.arr, _xlpm.str, "")))), _xlpm.first, _xlfn._xlws.FILTER(_xlpm.cleaned, _xlpm.cleaned <> ""), INDEX(_xlpm.first, 1) )} -> Kiko | AJ20: {=_xlfn._xlws.FILTER(表格6[Full Name],(表格6[Name]=AI20)+(表格6[Name]&"_1"=AI20)+(表格6[Name]&"_2"=AI20)+(表格6[Name]&"_3"=AI20)+(表格6[Name]&"_4"=AI20)+(表格6[Name]&"_5"=AI20))} -> Chan Mei Sim | AK20: {=_xlfn._xlws.FILTER(三國演義!$C$13:$C$80,三國演義!$E$13:$E$80=Roster!AI20)} -> 16 | AL20: 60 | AM20: 0 | AN20: 0.02
A21: Tung Chun Fortress | B21: Jaco off | C21: Jaco | D21: Jaco | E21: Jaco | F21: Jaco | G21: Jaco off | H21: Jaco | I21: Jaco | J21: Jaco | K21: Jaco | L21: Jaco | M21: Jaco off | N21: Jaco off | O21: Jaco | P21: Jaco | Q21: Jaco | R21: Jaco | S21: Jaco off | T21: Jaco off | U21: Jaco | V21: Jaco | W21: Jaco | X21: Jaco | Y21: Jaco | Z21: Jaco | AA21: Jaco off | AB21: Jaco off | AC21: Jaco off | AD21: Jaco | AE21: Jaco | AF21: Jaco | AG21: =COUNTA(B21:AF21)-COUNTIF(B21:AF21,"."&"*")-COUNTIF(B21:AF21,"off")-COUNTIF(B21:AF21,"SL"&" "&"*")-COUNTIF(B21:AF21,"PH"&" "&"*")-COUNTIF(B21:AF21,"AL"&" "&"*")-COUNTIF(B21:AF21,"CL"&" "&"*")-COUNTIF(B21:AF21,"Typhoon"&" "&"*")-COUNTIF(B21:AF21,"*"&"off")-COUNTIF(B21:AF21," "&"*") -> 22 | AH21: =AG21*8-6 -> 170 | AI21: {=_xlfn.LET( _xlpm.data, B21:AF21, _xlpm.removeList, {" off","."," SL","xxx"}, _xlpm.cleaned, TRIM(_xlfn.REDUCE(_xlpm.data, _xlpm.removeList, _xlfn.LAMBDA(_xlpm.arr,_xlpm.str, SUBSTITUTE(_xlpm.arr, _xlpm.str, "")))), _xlpm.first, _xlfn._xlws.FILTER(_xlpm.cleaned, _xlpm.cleaned <> ""), INDEX(_xlpm.first, 1) )} -> Jaco | AJ21: {=_xlfn._xlws.FILTER(表格6[Full Name],(表格6[Name]=AI21)+(表格6[Name]&"_1"=AI21)+(表格6[Name]&"_2"=AI21)+(表格6[Name]&"_3"=AI21)+(表格6[Name]&"_4"=AI21)+(表格6[Name]&"_5"=AI21))} -> Ka Kui,Jaco | AK21: {=_xlfn._xlws.FILTER(三國演義!$C$13:$C$80,三國演義!$E$13:$E$80=Roster!AI21)} -> 17 | AL21: 60 | AM21: 0 | AN21: 0.02
A22: TM Suning | B22: Daisy | C22: Daisy | D22: Daisy | E22: Daisy | F22: Daisy off | G22: Daisy off | H22: Daisy | I22: Daisy | J22: Daisy | K22: Daisy | L22: Daisy off | M22: Daisy off | N22: Daisy off | O22: Daisy | P22: Daisy | Q22: Daisy | R22: Daisy | S22: Daisy | T22: Daisy off | U22: Daisy | V22: Daisy | W22: Daisy | X22: Daisy | Y22: Daisy | Z22: Daisy | AA22: Daisy off | AB22: Daisy off | AC22: Daisy | AD22: Daisy | AE22: Daisy | AF22: Daisy | AG22: =COUNTA(B22:AF22)-COUNTIF(B22:AF22,"."&"*")-COUNTIF(B22:AF22,"off")-COUNTIF(B22:AF22,"SL"&" "&"*")-COUNTIF(B22:AF22,"PH"&" "&"*")-COUNTIF(B22:AF22,"AL"&" "&"*")-COUNTIF(B22:AF22,"CL"&" "&"*")-COUNTIF(B22:AF22,"Typhoon"&" "&"*")-COUNTIF(B22:AF22,"*"&"off")-COUNTIF(B22:AF22," "&"*") -> 23 | AH22: =AG22*8 -> 184 | AI22: {=_xlfn.LET( _xlpm.data, B22:AF22, _xlpm.removeList, {" off","."," SL","xxx"}, _xlpm.cleaned, TRIM(_xlfn.REDUCE(_xlpm.data, _xlpm.removeList, _xlfn.LAMBDA(_xlpm.arr,_xlpm.str, SUBSTITUTE(_xlpm.arr, _xlpm.str, "")))), _xlpm.first, _xlfn._xlws.FILTER(_xlpm.cleaned, _xlpm.cleaned <> ""), INDEX(_xlpm.first, 1) )} -> Daisy | AJ22: {=_xlfn._xlws.FILTER(表格6[Full Name],(表格6[Name]=AI22)+(表格6[Name]&"_1"=AI22)+(表格6[Name]&"_2"=AI22)+(表格6[Name]&"_3"=AI22)+(表格6[Name]&"_4"=AI22)+(表格6[Name]&"_5"=AI22))} -> Yeung Kwai Lin | AK22: {=_xlfn._xlws.FILTER(三國演義!$C$13:$C$80,三國演義!$E$13:$E$80=Roster!AI22)} -> 18 | AL22: 60 | AM22: 0 | AN22: 0.02
A23: Mos_1 Citistore | B23: Pam | C23: Pam off | D23: Pam | E23: Pam | F23: Pam | G23: Pam off | H23: Pam | I23: Pam | J23: Pam | K23: Pam | L23: Pam off | M23: Pam | N23: Pam | O23: Pam | P23: Pam | Q23: Pam | R23: Pam off | S23: Pam | T23: Pam off | U23: Pam off | V23: . | W23: . | X23: Pam off | Y23: Pam | Z23: Pam | AA23: Pam | AB23: Pam off | AC23: Pam | AD23: Pam | AE23: Pam | AF23: Pam | AG23: =COUNTA(B23:AF23)-COUNTIF(B23:AF23,"."&"*")-COUNTIF(B23:AF23,"off")-COUNTIF(B23:AF23,"SL"&" "&"*")-COUNTIF(B23:AF23,"PH"&" "&"*")-COUNTIF(B23:AF23,"AL"&" "&"*")-COUNTIF(B23:AF23,"CL"&" "&"*")-COUNTIF(B23:AF23,"Typhoon"&" "&"*")-COUNTIF(B23:AF23,"*"&"off")-COUNTIF(B23:AF23," "&"*") -> 21 | AH23: =AG23*8 -> 168 | AI23: {=_xlfn.LET( _xlpm.data, B23:AF23, _xlpm.removeList, {" off","."," SL","xxx"}, _xlpm.cleaned, TRIM(_xlfn.REDUCE(_xlpm.data, _xlpm.removeList, _xlfn.LAMBDA(_xlpm.arr,_xlpm.str, SUBSTITUTE(_xlpm.arr, _xlpm.str, "")))), _xlpm.first, _xlfn._xlws.FILTER(_xlpm.cleaned, _xlpm.cleaned <> ""), INDEX(_xlpm.first, 1) )} -> Pam | AJ23: {=_xlfn._xlws.FILTER(表格6[Full Name],(表格6[Name]=AI23)+(表格6[Name]&"_1"=AI23)+(表格6[Name]&"_2"=AI23)+(表格6[Name]&"_3"=AI23)+(表格6[Name]&"_4"=AI23)+(表格6[Name]&"_5"=AI23))} -> Tam Wing Lam | AK23: {=_xlfn._xlws.FILTER(三國演義!$C$13:$C$80,三國演義!$E$13:$E$80=Roster!AI23)} -> 19 | AL23: 55 | AM23: 0 | AN23: 0.02
A24: Mos_2 Citistore | B24: . | C24: . | D24: . | E24: . | F24: . | G24: . | H24: . | I24: . | J24: . | K24: . | L24: . | M24: . | N24: . | O24: . | P24: . | Q24: . | R24: . | S24: . | T24: . | U24: . | V24: Tony_4 | W24: Tony_4 | X24: . | Y24: . | Z24: . | AA24: . | AB24: . | AC24: . | AD24: . | AE24: . | AF24: . | AG24: =COUNTA(B24:AF24)-COUNTIF(B24:AF24,"."&"*")-COUNTIF(B24:AF24,"off")-COUNTIF(B24:AF24,"SL"&" "&"*")-COUNTIF(B24:AF24,"PH"&" "&"*")-COUNTIF(B24:AF24,"AL"&" "&"*")-COUNTIF(B24:AF24,"CL"&" "&"*")-COUNTIF(B24:AF24,"Typhoon"&" "&"*")-COUNTIF(B24:AF24,"*"&"off")-COUNTIF(B24:AF24," "&"*") -> 2 | AH24: =AG24*8 -> 16 | AI24: {=_xlfn.LET( _xlpm.data, B24:AF24, _xlpm.removeList, {" off","."," SL","xxx"}, _xlpm.cleaned, TRIM(_xlfn.REDUCE(_xlpm.data, _xlpm.removeList, _xlfn.LAMBDA(_xlpm.arr,_xlpm.str, SUBSTITUTE(_xlpm.arr, _xlpm.str, "")))), _xlpm.first, _xlfn._xlws.FILTER(_xlpm.cleaned, _xlpm.cleaned <> ""), INDEX(_xlpm.first, 1) )} -> Tony_4 | AJ24: {=_xlfn._xlws.FILTER(表格6[Full Name],(表格6[Name]=AI24)+(表格6[Name]&"_1"=AI24)+(表格6[Name]&"_2"=AI24)+(表格6[Name]&"_3"=AI24)+(表格6[Name]&"_4"=AI24)+(表格6[Name]&"_5"=AI24))} -> Wong Tak Chung | AK24: {=_xlfn._xlws.FILTER(三國演義!$C$13:$C$80,三國演義!$E$13:$E$80=Roster!AI24)} -> 20 | AL24: 60 | AM24: 0
A25: TM_1 Aeon | B25: Lily Hon | C25: Lily Hon | D25: Lily Hon off | E25: Lily Hon | F25: Lily Hon off | G25: Lily Hon | H25: Lily Hon off | I25: Lily Hon | J25: Lily Hon | K25: Lily Hon off | L25: Lily Hon | M25: Lily Hon off | N25: Lily Hon | O25: Lily Hon off | P25: Lily Hon off | Q25: Lily Hon off | R25: . | S25: . | T25: Lily Hon off | U25: Lily Hon off | V25: Lily Hon off | W25: Lily Hon | X25: Lily Hon | Y25: Lily Hon | Z25: Lily Hon | AA25: . | AB25: Lily Hon | AC25: Lily Hon | AD25: Lily Hon | AE25: . | AF25: Lily Hon | AG25: =COUNTA(B25:AF25)-COUNTIF(B25:AF25,"."&"*")-COUNTIF(B25:AF25,"off")-COUNTIF(B25:AF25,"SL"&" "&"*")-COUNTIF(B25:AF25,"PH"&" "&"*")-COUNTIF(B25:AF25,"AL"&" "&"*")-COUNTIF(B25:AF25,"CL"&" "&"*")-COUNTIF(B25:AF25,"Typhoon"&" "&"*")-COUNTIF(B25:AF25,"*"&"off")-COUNTIF(B25:AF25," "&"*") -> 16 | AH25: =AG25*8 -> 128 | AI25: {=_xlfn.LET( _xlpm.data, B25:AF25, _xlpm.removeList, {" off","."," SL","xxx"}, _xlpm.cleaned, TRIM(_xlfn.REDUCE(_xlpm.data, _xlpm.removeList, _xlfn.LAMBDA(_xlpm.arr,_xlpm.str, SUBSTITUTE(_xlpm.arr, _xlpm.str, "")))), _xlpm.first, _xlfn._xlws.FILTER(_xlpm.cleaned, _xlpm.cleaned <> ""), INDEX(_xlpm.first, 1) )} -> Lily Hon | AJ25: {=_xlfn._xlws.FILTER(表格6[Full Name],(表格6[Name]=AI25)+(表格6[Name]&"_1"=AI25)+(表格6[Name]&"_2"=AI25)+(表格6[Name]&"_3"=AI25)+(表格6[Name]&"_4"=AI25)+(表格6[Name]&"_5"=AI25))} -> Hon Lily | AK25: {=_xlfn._xlws.FILTER(三國演義!$C$13:$C$80,三國演義!$E$13:$E$80=Roster!AI25)} -> 21 | AL25: 55 | AM25: 30 | AN25: 0.02
A26: TM_2 Aeon | B26: . | C26: . | D26: . | E26: . | F26: . | G26: . | H26: . | I26: . | J26: . | K26: . | L26: . | M26: . | N26: . | O26: . | P26: . | Q26: . | R26: Ho_3 | S26: Ho_3 | T26: . | U26: . | V26: . | W26: . | X26: . | Y26: . | Z26: . | AA26: Ho_3 | AB26: . | AC26: . | AD26: . | AE26: Ho_3 | AF26: . | AG26: =COUNTA(B26:AF26)-COUNTIF(B26:AF26,"."&"*")-COUNTIF(B26:AF26,"off")-COUNTIF(B26:AF26,"SL"&" "&"*")-COUNTIF(B26:AF26,"PH"&" "&"*")-COUNTIF(B26:AF26,"AL"&" "&"*")-COUNTIF(B26:AF26,"CL"&" "&"*")-COUNTIF(B26:AF26,"Typhoon"&" "&"*")-COUNTIF(B26:AF26,"*"&"off")-COUNTIF(B26:AF26," "&"*") -> 4 | AH26: =AG26*8 -> 32 | AI26: {=_xlfn.LET( _xlpm.data, B26:AF26, _xlpm.removeList, {" off","."," SL","xxx"}, _xlpm.cleaned, TRIM(_xlfn.REDUCE(_xlpm.data, _xlpm.removeList, _xlfn.LAMBDA(_xlpm.arr,_xlpm.str, SUBSTITUTE(_xlpm.arr, _xlpm.str, "")))), _xlpm.first, _xlfn._xlws.FILTER(_xlpm.cleaned, _xlpm.cleaned <> ""), INDEX(_xlpm.first, 1) )} -> Ho_3 | AJ26: {=_xlfn._xlws.FILTER(表格6[Full Name],(表格6[Name]=AI26)+(表格6[Name]&"_1"=AI26)+(表格6[Name]&"_2"=AI26)+(表格6[Name]&"_3"=AI26)+(表格6[Name]&"_4"=AI26)+(表格6[Name]&"_5"=AI26))} -> Kwan Tit Ho | AK26: {=_xlfn._xlws.FILTER(三國演義!$C$13:$C$80,三國演義!$E$13:$E$80=Roster!AI26)} -> 22 | AL26: 55 | AM26: 0 | AN26: 0.02
A27: TW Fortress | B27: Kandy | C27: . | D27: . | E27: . | F27: . | G27: . | H27: Kandy | I27: Kandy | J27: . | K27: . | L27: . | M27: . | N27: . | O27: . | P27: . | Q27: . | R27: . | S27: . | T27: . | U27: . | V27: Kandy | W27: Kandy | X27: . | Y27: . | Z27: . | AA27: . | AB27: . | AC27: Kandy | AD27: Kandy | AE27: . | AF27: . | AG27: =COUNTA(B27:AF27)-COUNTIF(B27:AF27,"."&"*")-COUNTIF(B27:AF27,"off")-COUNTIF(B27:AF27,"SL"&" "&"*")-COUNTIF(B27:AF27,"PH"&" "&"*")-COUNTIF(B27:AF27,"AL"&" "&"*")-COUNTIF(B27:AF27,"CL"&" "&"*")-COUNTIF(B27:AF27,"Typhoon"&" "&"*")-COUNTIF(B27:AF27,"*"&"off")-COUNTIF(B27:AF27," "&"*") -> 7 | AH27: =AG27*8 -> 56 | AI27: {=_xlfn.LET( _xlpm.data, B27:AF27, _xlpm.removeList, {" off","."," SL","xxx"}, _xlpm.cleaned, TRIM(_xlfn.REDUCE(_xlpm.data, _xlpm.removeList, _xlfn.LAMBDA(_xlpm.arr,_xlpm.str, SUBSTITUTE(_xlpm.arr, _xlpm.str, "")))), _xlpm.first, _xlfn._xlws.FILTER(_xlpm.cleaned, _xlpm.cleaned <> ""), INDEX(_xlpm.first, 1) )} -> Kandy | AJ27: {=_xlfn._xlws.FILTER(表格6[Full Name],(表格6[Name]=AI27)+(表格6[Name]&"_1"=AI27)+(表格6[Name]&"_2"=AI27)+(表格6[Name]&"_3"=AI27)+(表格6[Name]&"_4"=AI27)+(表格6[Name]&"_5"=AI27))} -> Sin Hoi Yam | AK27: {=_xlfn._xlws.FILTER(三國演義!$C$13:$C$80,三國演義!$E$13:$E$80=Roster!AI27)} -> 23 | AL27: 55 | AM27: 0 | AN27: 0.02
A28: TW Suning | B28: Hung | C28: Hung | D28: Hung | E28: Hung | F28: Hung off | G28: Hung | H28: Hung | I28: Hung | J28: Hung | K28: Hung | L28: Hung | M28: Hung | N28: Hung off | O28: Hung | P28: Hung | Q28: Hung | R28: Hung | S28: Hung | T28: Hung off | U28: Hung | V28: Hung | W28: Hung | X28: Hung | Y28: Hung | Z28: Hung | AA28: Hung off | AB28: Hung off | AC28: Hung off | AD28: Hung off | AE28: Hung off | AF28: Hung off | AG28: =COUNTA(B28:AF28)-COUNTIF(B28:AF28,"."&"*")-COUNTIF(B28:AF28,"off")-COUNTIF(B28:AF28,"SL"&" "&"*")-COUNTIF(B28:AF28,"PH"&" "&"*")-COUNTIF(B28:AF28,"AL"&" "&"*")-COUNTIF(B28:AF28,"CL"&" "&"*")-COUNTIF(B28:AF28,"Typhoon"&" "&"*")-COUNTIF(B28:AF28,"*"&"off")-COUNTIF(B28:AF28," "&"*") -> 22 | AH28: =AG28*8 -> 176 | AI28: {=_xlfn.LET( _xlpm.data, B28:AF28, _xlpm.removeList, {" off","."," SL","xxx"}, _xlpm.cleaned, TRIM(_xlfn.REDUCE(_xlpm.data, _xlpm.removeList, _xlfn.LAMBDA(_xlpm.arr,_xlpm.str, SUBSTITUTE(_xlpm.arr, _xlpm.str, "")))), _xlpm.first, _xlfn._xlws.FILTER(_xlpm.cleaned, _xlpm.cleaned <> ""), INDEX(_xlpm.first, 1) )} -> Hung | AJ28: {=_xlfn._xlws.FILTER(表格6[Full Name],(表格6[Name]=AI28)+(表格6[Name]&"_1"=AI28)+(表格6[Name]&"_2"=AI28)+(表格6[Name]&"_3"=AI28)+(表格6[Name]&"_4"=AI28)+(表格6[Name]&"_5"=AI28))} -> Hui Man Hung | AK28: {=_xlfn._xlws.FILTER(三國演義!$C$13:$C$80,三國演義!$E$13:$E$80=Roster!AI28)} -> 24 | AL28: 60 | AM28: 0 | AN28: 0.02
A29: Yoho Suning | B29: Leo off | C29: Leo | D29: Leo | E29: Leo off | F29: Leo | G29: Leo off | H29: Leo | I29: Leo | J29: Leo | K29: Leo | L29: Leo off | M29: Leo | N29: Leo | O29: Leo | P29: Leo | Q29: Leo | R29: Leo | S29: Leo off | T29: Leo | U29: Leo | V29: Leo | W29: Leo | X29: Leo | Y29: Leo | Z29: Leo off | AA29: Leo | AB29: Leo off | AC29: Leo off | AD29: Leo | AE29: Leo | AF29: Leo | AG29: =COUNTA(B29:AF29)-COUNTIF(B29:AF29,"."&"*")-COUNTIF(B29:AF29,"off")-COUNTIF(B29:AF29,"SL"&" "&"*")-COUNTIF(B29:AF29,"PH"&" "&"*")-COUNTIF(B29:AF29,"AL"&" "&"*")-COUNTIF(B29:AF29,"CL"&" "&"*")-COUNTIF(B29:AF29,"Typhoon"&" "&"*")-COUNTIF(B29:AF29,"*"&"off")-COUNTIF(B29:AF29," "&"*") -> 23 | AH29: =AG29*8 -> 184 | AI29: {=_xlfn.LET( _xlpm.data, B29:AF29, _xlpm.removeList, {" off","."," SL","xxx"}, _xlpm.cleaned, TRIM(_xlfn.REDUCE(_xlpm.data, _xlpm.removeList, _xlfn.LAMBDA(_xlpm.arr,_xlpm.str, SUBSTITUTE(_xlpm.arr, _xlpm.str, "")))), _xlpm.first, _xlfn._xlws.FILTER(_xlpm.cleaned, _xlpm.cleaned <> ""), INDEX(_xlpm.first, 1) )} -> Leo | AJ29: {=_xlfn._xlws.FILTER(表格6[Full Name],(表格6[Name]=AI29)+(表格6[Name]&"_1"=AI29)+(表格6[Name]&"_2"=AI29)+(表格6[Name]&"_3"=AI29)+(表格6[Name]&"_4"=AI29)+(表格6[Name]&"_5"=AI29))} -> Lam King Chung | AK29: {=_xlfn._xlws.FILTER(三國演義!$C$13:$C$80,三國演義!$E$13:$E$80=Roster!AI29)} -> 25 | AL29: 55 | AM29: 0 | AN29: 0.02
A30: YL Citistore | B30: Yee | C30: Yee off | D30: Yee off | E30: Yee off | F30: Yee | G30: Yee | H30: Yee | I30: Yee | J30: Yee | K30: Yee off | L30: Yee off | M30: Yee | N30: Yee | O30: Yee | P30: Yee | Q30: Yee | R30: Yee off | S30: Yee off | T30: Yee | U30: Yee | V30: Yee | W30: Yee | X30: Yee off | Y30: Yee off | Z30: Yee off | AA30: Yee | AB30: Yee | AC30: Yee | AD30: Yee | AE30: Yee | AF30: Yee off | AG30: =COUNTA(B30:AF30)-COUNTIF(B30:AF30,"."&"*")-COUNTIF(B30:AF30,"off")-COUNTIF(B30:AF30,"SL"&" "&"*")-COUNTIF(B30:AF30,"PH"&" "&"*")-COUNTIF(B30:AF30,"AL"&" "&"*")-COUNTIF(B30:AF30,"CL"&" "&"*")-COUNTIF(B30:AF30,"Typhoon"&" "&"*")-COUNTIF(B30:AF30,"*"&"off")-COUNTIF(B30:AF30," "&"*") -> 20 | AH30: =AG30*8 -> 160 | AI30: {=_xlfn.LET( _xlpm.data, B30:AF30, _xlpm.removeList, {" off","."," SL","xxx"}, _xlpm.cleaned, TRIM(_xlfn.REDUCE(_xlpm.data, _xlpm.removeList, _xlfn.LAMBDA(_xlpm.arr,_xlpm.str, SUBSTITUTE(_xlpm.arr, _xlpm.str, "")))), _xlpm.first, _xlfn._xlws.FILTER(_xlpm.cleaned, _xlpm.cleaned <> ""), INDEX(_xlpm.first, 1) )} -> Yee | AJ30: {=_xlfn._xlws.FILTER(表格6[Full Name],(表格6[Name]=AI30)+(表格6[Name]&"_1"=AI30)+(表格6[Name]&"_2"=AI30)+(表格6[Name]&"_3"=AI30)+(表格6[Name]&"_4"=AI30)+(表格6[Name]&"_5"=AI30))} -> Cheung Yu Wing Yee | AK30: {=_xlfn._xlws.FILTER(三國演義!$C$13:$C$80,三國演義!$E$13:$E$80=Roster!AI30)} -> 26 | AL30: 60 | AM30: 0 | AN30: 0.02
A31: TM Citistore | B31: Ling Ho | C31: Ling Ho off | D31: Ling Ho | E31: Ling Ho | F31: Ling Ho off | G31: Ling Ho | H31: Ling Ho | I31: Ling Ho | J31: Ling Ho | K31: Ling Ho off | L31: Ling Ho | M31: Ling Ho | N31: Ling Ho off | O31: Ling Ho | P31: Ling Ho | Q31: Ling Ho | R31: Ling Ho | S31: Ling Ho off | T31: Ling Ho off | U31: Ling Ho | V31: Ling Ho | W31: Ling Ho | X31: Ling Ho | Y31: Ling Ho | Z31: Ling Ho off | AA31: Ling Ho | AB31: Ling Ho | AC31: Ling Ho | AD31: Ling Ho | AE31: Ling Ho | AF31: Ling Ho | AG31: =COUNTA(B31:AF31)-COUNTIF(B31:AF31,"."&"*")-COUNTIF(B31:AF31,"off")-COUNTIF(B31:AF31,"SL"&" "&"*")-COUNTIF(B31:AF31,"PH"&" "&"*")-COUNTIF(B31:AF31,"AL"&" "&"*")-COUNTIF(B31:AF31,"CL"&" "&"*")-COUNTIF(B31:AF31,"Typhoon"&" "&"*")-COUNTIF(B31:AF31,"*"&"off")-COUNTIF(B31:AF31," "&"*") -> 24 | AH31: =AG31*8 -> 192 | AI31: {=_xlfn.LET( _xlpm.data, B31:AF31, _xlpm.removeList, {" off","."," SL","xxx"}, _xlpm.cleaned, TRIM(_xlfn.REDUCE(_xlpm.data, _xlpm.removeList, _xlfn.LAMBDA(_xlpm.arr,_xlpm.str, SUBSTITUTE(_xlpm.arr, _xlpm.str, "")))), _xlpm.first, _xlfn._xlws.FILTER(_xlpm.cleaned, _xlpm.cleaned <> ""), INDEX(_xlpm.first, 1) )} -> Ling Ho | AJ31: {=_xlfn._xlws.FILTER(表格6[Full Name],(表格6[Name]=AI31)+(表格6[Name]&"_1"=AI31)+(表格6[Name]&"_2"=AI31)+(表格6[Name]&"_3"=AI31)+(表格6[Name]&"_4"=AI31)+(表格6[Name]&"_5"=AI31))} -> Ho Wai Ling | AK31: {=_xlfn._xlws.FILTER(三國演義!$C$13:$C$80,三國演義!$E$13:$E$80=Roster!AI31)} -> 27 | AL31: 60 | AM31: 0 | AN31: 0.02
A32: APM Broadway | B32: Happy | C32: Happy off | D32: Happy | E32: Happy | F32: Happy | G32: Happy off | H32: Happy | I32: Happy | J32: Happy | K32: Happy off | L32: Happy | M32: Happy | N32: Happy off | O32: Happy off | P32: Happy | Q32: Happy | R32: Happy off | S32: Happy off | T32: Happy | U32: Happy | V32: Happy | W32: Happy | X32: Happy off | Y32: Happy off | Z32: Happy | AA32: Happy | AB32: Happy | AC32: Happy | AD32: Happy | AE32: Happy | AF32: Happy | AG32: =COUNTA(B32:AF32)-COUNTIF(B32:AF32,"."&"*")-COUNTIF(B32:AF32,"off")-COUNTIF(B32:AF32,"SL"&" "&"*")-COUNTIF(B32:AF32,"PH"&" "&"*")-COUNTIF(B32:AF32,"AL"&" "&"*")-COUNTIF(B32:AF32,"CL"&" "&"*")-COUNTIF(B32:AF32,"Typhoon"&" "&"*")-COUNTIF(B32:AF32,"*"&"off")-COUNTIF(B32:AF32," "&"*") -> 22 | AH32: =AG32*8 -> 176 | AI32: {=_xlfn.LET( _xlpm.data, B32:AF32, _xlpm.removeList, {" off","."," SL","xxx"}, _xlpm.cleaned, TRIM(_xlfn.REDUCE(_xlpm.data, _xlpm.removeList, _xlfn.LAMBDA(_xlpm.arr,_xlpm.str, SUBSTITUTE(_xlpm.arr, _xlpm.str, "")))), _xlpm.first, _xlfn._xlws.FILTER(_xlpm.cleaned, _xlpm.cleaned <> ""), INDEX(_xlpm.first, 1) )} -> Happy | AJ32: {=_xlfn._xlws.FILTER(表格6[Full Name],(表格6[Name]=AI32)+(表格6[Name]&"_1"=AI32)+(表格6[Name]&"_2"=AI32)+(表格6[Name]&"_3"=AI32)+(表格6[Name]&"_4"=AI32)+(表格6[Name]&"_5"=AI32))} -> Chun Yin Ling | AK32: {=_xlfn._xlws.FILTER(三國演義!$C$13:$C$80,三國演義!$E$13:$E$80=Roster!AI32)} -> 28 | AL32: 60 | AM32: 0 | AN32: 0.02
A33: APM Fortress | B33: Tiffany | C33: Tiffany off | D33: Tiffany off | E33: Tiffany off | F33: Tiffany | G33: Tiffany | H33: Tiffany off | I33: Tiffany | J33: Tiffany | K33: Tiffany off | L33: Tiffany | M33: Tiffany | N33: Tiffany off | O33: Tiffany | P33: Tiffany off | Q33: Tiffany | R33: Tiffany off | S33: Tiffany off | T33: Tiffany | U33: Tiffany | V33: Tiffany | W33: Tiffany | X33: Tiffany off | Y33: Tiffany | Z33: Tiffany | AA33: Tiffany | AB33: Tiffany off | AC33: Tiffany off | AD33: Tiffany | AE33: Tiffany off | AF33: Tiffany | AG33: =COUNTA(B33:AF33)-COUNTIF(B33:AF33,"."&"*")-COUNTIF(B33:AF33,"off")-COUNTIF(B33:AF33,"SL"&" "&"*")-COUNTIF(B33:AF33,"PH"&" "&"*")-COUNTIF(B33:AF33,"AL"&" "&"*")-COUNTIF(B33:AF33,"CL"&" "&"*")-COUNTIF(B33:AF33,"Typhoon"&" "&"*")-COUNTIF(B33:AF33,"*"&"off")-COUNTIF(B33:AF33," "&"*") -> 18 | AH33: =AG33*8 -> 144 | AI33: {=_xlfn.LET( _xlpm.data, B33:AF33, _xlpm.removeList, {" off","."," SL","xxx"}, _xlpm.cleaned, TRIM(_xlfn.REDUCE(_xlpm.data, _xlpm.removeList, _xlfn.LAMBDA(_xlpm.arr,_xlpm.str, SUBSTITUTE(_xlpm.arr, _xlpm.str, "")))), _xlpm.first, _xlfn._xlws.FILTER(_xlpm.cleaned, _xlpm.cleaned <> ""), INDEX(_xlpm.first, 1) )} -> Tiffany | AJ33: {=_xlfn._xlws.FILTER(表格6[Full Name],(表格6[Name]=AI33)+(表格6[Name]&"_1"=AI33)+(表格6[Name]&"_2"=AI33)+(表格6[Name]&"_3"=AI33)+(表格6[Name]&"_4"=AI33)+(表格6[Name]&"_5"=AI33))} -> Man Wai Han | AK33: {=_xlfn._xlws.FILTER(三國演義!$C$13:$C$80,三國演義!$E$13:$E$80=Roster!AI33)} -> 29 | AL33: 60 | AM33: 0 | AN33: 0.02
A34: TKO Suning | B34: Coco | C34: Coco off | D34: Coco | E34: Coco | F34: Coco | G34: Coco off | H34: Coco | I34: Coco | J34: Coco off | K34: Coco off | L34: Coco | M34: Coco | N34: Coco off | O34: Coco | P34: Coco | Q34: Coco off | R34: Coco | S34: Coco | T34: Coco | U34: Coco off | V34: Coco off | W34: Coco off | X34: Coco off | Y34: Coco | Z34: Coco | AA34: Coco | AB34: Coco off | AC34: Coco | AD34: Coco | AE34: Coco | AF34: Coco | AG34: =COUNTA(B34:AF34)-COUNTIF(B34:AF34,"."&"*")-COUNTIF(B34:AF34,"off")-COUNTIF(B34:AF34,"SL"&" "&"*")-COUNTIF(B34:AF34,"PH"&" "&"*")-COUNTIF(B34:AF34,"AL"&" "&"*")-COUNTIF(B34:AF34,"CL"&" "&"*")-COUNTIF(B34:AF34,"Typhoon"&" "&"*")-COUNTIF(B34:AF34,"*"&"off")-COUNTIF(B34:AF34," "&"*") -> 20 | AH34: =AG34*8 -> 160 | AI34: {=_xlfn.LET( _xlpm.data, B34:AF34, _xlpm.removeList, {" off","."," SL","xxx"}, _xlpm.cleaned, TRIM(_xlfn.REDUCE(_xlpm.data, _xlpm.removeList, _xlfn.LAMBDA(_xlpm.arr,_xlpm.str, SUBSTITUTE(_xlpm.arr, _xlpm.str, "")))), _xlpm.first, _xlfn._xlws.FILTER(_xlpm.cleaned, _xlpm.cleaned <> ""), INDEX(_xlpm.first, 1) )} -> Coco | AJ34: {=_xlfn._xlws.FILTER(表格6[Full Name],(表格6[Name]=AI34)+(表格6[Name]&"_1"=AI34)+(表格6[Name]&"_2"=AI34)+(表格6[Name]&"_3"=AI34)+(表格6[Name]&"_4"=AI34)+(表格6[Name]&"_5"=AI34))} -> Yuen Lai Ying | AK34: {=_xlfn._xlws.FILTER(三國演義!$C$13:$C$80,三國演義!$E$13:$E$80=Roster!AI34)} -> 30 | AL34: 60 | AM34: 0 | AN34: 0.02
A35: Times Fortress | B35: Raymond | C35: Raymond | D35: Raymond | E35: Raymond | F35: Raymond | G35: Raymond off | H35: Raymond | I35: Raymond off | J35: Raymond | K35: Raymond | L35: Raymond | M35: Raymond | N35: Raymond off | O35: Raymond off | P35: Raymond | Q35: Raymond | R35: Raymond | S35: Raymond | T35: Raymond off | U35: Raymond off | V35: Raymond | W35: Raymond | X35: Raymond | Y35: Raymond | Z35: Raymond | AA35: Raymond | AB35: Raymond off | AC35: Raymond | AD35: Raymond | AE35: Raymond | AF35: Raymond | AG35: =COUNTA(B35:AF35)-COUNTIF(B35:AF35,"."&"*")-COUNTIF(B35:AF35,"off")-COUNTIF(B35:AF35,"SL"&" "&"*")-COUNTIF(B35:AF35,"PH"&" "&"*")-COUNTIF(B35:AF35,"AL"&" "&"*")-COUNTIF(B35:AF35,"CL"&" "&"*")-COUNTIF(B35:AF35,"Typhoon"&" "&"*")-COUNTIF(B35:AF35,"*"&"off")-COUNTIF(B35:AF35," "&"*") -> 24 | AH35: =AG35*8 -> 192 | AI35: {=_xlfn.LET( _xlpm.data, B35:AF35, _xlpm.removeList, {" off","."," SL","xxx"}, _xlpm.cleaned, TRIM(_xlfn.REDUCE(_xlpm.data, _xlpm.removeList, _xlfn.LAMBDA(_xlpm.arr,_xlpm.str, SUBSTITUTE(_xlpm.arr, _xlpm.str, "")))), _xlpm.first, _xlfn._xlws.FILTER(_xlpm.cleaned, _xlpm.cleaned <> ""), INDEX(_xlpm.first, 1) )} -> Raymond | AJ35: {=_xlfn._xlws.FILTER(表格6[Full Name],(表格6[Name]=AI35)+(表格6[Name]&"_1"=AI35)+(表格6[Name]&"_2"=AI35)+(表格6[Name]&"_3"=AI35)+(表格6[Name]&"_4"=AI35)+(表格6[Name]&"_5"=AI35))} -> Kwok Chun Wah | AK35: {=_xlfn._xlws.FILTER(三國演義!$C$13:$C$80,三國演義!$E$13:$E$80=Roster!AI35)} -> 31 | AL35: 60 | AM35: 0 | AN35: 0.02
A36: Shatin_1 Yata | B36: Maggie Yip | C36: Maggie Yip | D36: . | E36: . | F36: Maggie Yip | G36: Maggie Yip | H36: Maggie Yip | I36: Maggie Yip | J36: Maggie Yip | K36: Maggie Yip | L36: . | M36: . | N36: . | O36: Maggie Yip | P36: Maggie Yip | Q36: Maggie Yip | R36: Maggie Yip | S36: . | T36: . | U36: Maggie Yip | V36: Maggie Yip | W36: Maggie Yip | X36: Maggie Yip | Y36: Maggie Yip | Z36: . | AA36: . | AB36: Maggie Yip | AC36: Maggie Yip | AD36: Maggie Yip | AE36: Maggie Yip | AF36: Maggie Yip | AG36: =COUNTA(B36:AF36)-COUNTIF(B36:AF36,"."&"*")-COUNTIF(B36:AF36,"off")-COUNTIF(B36:AF36,"SL"&" "&"*")-COUNTIF(B36:AF36,"PH"&" "&"*")-COUNTIF(B36:AF36,"AL"&" "&"*")-COUNTIF(B36:AF36,"CL"&" "&"*")-COUNTIF(B36:AF36,"Typhoon"&" "&"*")-COUNTIF(B36:AF36,"*"&"off")-COUNTIF(B36:AF36," "&"*") -> 22 | AH36: =AG36*8 -> 176 | AI36: {=_xlfn.LET( _xlpm.data, B36:AF36, _xlpm.removeList, {" off","."," SL","xxx"}, _xlpm.cleaned, TRIM(_xlfn.REDUCE(_xlpm.data, _xlpm.removeList, _xlfn.LAMBDA(_xlpm.arr,_xlpm.str, SUBSTITUTE(_xlpm.arr, _xlpm.str, "")))), _xlpm.first, _xlfn._xlws.FILTER(_xlpm.cleaned, _xlpm.cleaned <> ""), INDEX(_xlpm.first, 1) )} -> Maggie Yip | AJ36: {=_xlfn._xlws.FILTER(表格6[Full Name],(表格6[Name]=AI36)+(表格6[Name]&"_1"=AI36)+(表格6[Name]&"_2"=AI36)+(表格6[Name]&"_3"=AI36)+(表格6[Name]&"_4"=AI36)+(表格6[Name]&"_5"=AI36))} -> Yip Mei King | AK36: {=_xlfn._xlws.FILTER(三國演義!$C$13:$C$80,三國演義!$E$13:$E$80=Roster!AI36)} -> 32 | AL36: 60 | AM36: 0 | AN36: 0.02
A37: Shatin_2 Yata | B37: . | C37: . | D37: Emma | E37: Emma | F37: . | G37: . | H37: . | I37: . | J37: . | K37: . | L37: . | M37: . | N37: . | O37: . | P37: . | Q37: . | R37: . | S37: Emma | T37: Emma | U37: . | V37: . | W37: . | X37: . | Y37: . | Z37: . | AA37: . | AB37: . | AC37: . | AD37: . | AE37: . | AF37: . | AG37: =COUNTA(B37:AF37)-COUNTIF(B37:AF37,"."&"*")-COUNTIF(B37:AF37,"off")-COUNTIF(B37:AF37,"SL"&" "&"*")-COUNTIF(B37:AF37,"PH"&" "&"*")-COUNTIF(B37:AF37,"AL"&" "&"*")-COUNTIF(B37:AF37,"CL"&" "&"*")-COUNTIF(B37:AF37,"Typhoon"&" "&"*")-COUNTIF(B37:AF37,"*"&"off")-COUNTIF(B37:AF37," "&"*") -> 4 | AH37: =AG37*8 -> 32 | AI37: {=_xlfn.LET( _xlpm.data, B37:AF37, _xlpm.removeList, {" off","."," SL","xxx"}, _xlpm.cleaned, TRIM(_xlfn.REDUCE(_xlpm.data, _xlpm.removeList, _xlfn.LAMBDA(_xlpm.arr,_xlpm.str, SUBSTITUTE(_xlpm.arr, _xlpm.str, "")))), _xlpm.first, _xlfn._xlws.FILTER(_xlpm.cleaned, _xlpm.cleaned <> ""), INDEX(_xlpm.first, 1) )} -> Emma | AJ37: {=_xlfn._xlws.FILTER(表格6[Full Name],(表格6[Name]=AI37)+(表格6[Name]&"_1"=AI37)+(表格6[Name]&"_2"=AI37)+(表格6[Name]&"_3"=AI37)+(表格6[Name]&"_4"=AI37)+(表格6[Name]&"_5"=AI37))} -> Ng Yuk Ying | AK37: {=_xlfn._xlws.FILTER(三國演義!$C$13:$C$80,三國演義!$E$13:$E$80=Roster!AI37)} -> 33 | AL37: 60 | AM37: 0 | AN37: 0.02
A38: Shatin_3 Yata | B38: . | C38: . | D38: . | E38: . | F38: . | G38: . | H38: . | I38: . | J38: . | K38: . | L38: . | M38: . | N38: . | O38: . | P38: . | Q38: . | R38: . | S38: . | T38: . | U38: . | V38: . | W38: . | X38: . | Y38: . | Z38: Tony_1 | AA38: Tony_1 | AB38: . | AC38: . | AD38: . | AE38: . | AF38: . | AG38: =COUNTA(B38:AF38)-COUNTIF(B38:AF38,"."&"*")-COUNTIF(B38:AF38,"off")-COUNTIF(B38:AF38,"SL"&" "&"*")-COUNTIF(B38:AF38,"PH"&" "&"*")-COUNTIF(B38:AF38,"AL"&" "&"*")-COUNTIF(B38:AF38,"CL"&" "&"*")-COUNTIF(B38:AF38,"Typhoon"&" "&"*")-COUNTIF(B38:AF38,"*"&"off")-COUNTIF(B38:AF38," "&"*") -> 2 | AH38: =AG38*8 -> 16 | AI38: {=_xlfn.LET( _xlpm.data, B38:AF38, _xlpm.removeList, {" off","."," SL","xxx"}, _xlpm.cleaned, TRIM(_xlfn.REDUCE(_xlpm.data, _xlpm.removeList, _xlfn.LAMBDA(_xlpm.arr,_xlpm.str, SUBSTITUTE(_xlpm.arr, _xlpm.str, "")))), _xlpm.first, _xlfn._xlws.FILTER(_xlpm.cleaned, _xlpm.cleaned <> ""), INDEX(_xlpm.first, 1) )} -> Tony_1 | AJ38: {=_xlfn._xlws.FILTER(表格6[Full Name],(表格6[Name]=AI38)+(表格6[Name]&"_1"=AI38)+(表格6[Name]&"_2"=AI38)+(表格6[Name]&"_3"=AI38)+(表格6[Name]&"_4"=AI38)+(表格6[Name]&"_5"=AI38))} -> Wong Tak Chung | AK38: {=_xlfn._xlws.FILTER(三國演義!$C$13:$C$80,三國演義!$E$13:$E$80=Roster!AI38)} -> 34 | AL38: 60 | AM38: 0
A39: Shatin_4 Yata | B39: . | C39: . | D39: . | E39: . | F39: . | G39: . | H39: . | I39: . | J39: . | K39: . | L39: Kit_1 | M39: Kit_1 | N39: Kit_1 | O39: . | P39: . | Q39: . | R39: . | S39: . | T39: . | U39: . | V39: . | W39: . | X39: . | Y39: . | Z39: . | AA39: . | AB39: . | AC39: . | AD39: . | AE39: . | AF39: . | AG39: =COUNTA(B39:AF39)-COUNTIF(B39:AF39,"."&"*")-COUNTIF(B39:AF39,"off")-COUNTIF(B39:AF39,"SL"&" "&"*")-COUNTIF(B39:AF39,"PH"&" "&"*")-COUNTIF(B39:AF39,"AL"&" "&"*")-COUNTIF(B39:AF39,"CL"&" "&"*")-COUNTIF(B39:AF39,"Typhoon"&" "&"*")-COUNTIF(B39:AF39,"*"&"off")-COUNTIF(B39:AF39," "&"*") -> 3 | AH39: =AG39*8 -> 24 | AI39: {=_xlfn.LET( _xlpm.data, B39:AF39, _xlpm.removeList, {" off","."," SL","xxx"}, _xlpm.cleaned, TRIM(_xlfn.REDUCE(_xlpm.data, _xlpm.removeList, _xlfn.LAMBDA(_xlpm.arr,_xlpm.str, SUBSTITUTE(_xlpm.arr, _xlpm.str, "")))), _xlpm.first, _xlfn._xlws.FILTER(_xlpm.cleaned, _xlpm.cleaned <> ""), INDEX(_xlpm.first, 1) )} -> Kit_1 | AJ39: {=_xlfn._xlws.FILTER(表格6[Full Name],(表格6[Name]=AI39)+(表格6[Name]&"_1"=AI39)+(表格6[Name]&"_2"=AI39)+(表格6[Name]&"_3"=AI39)+(表格6[Name]&"_4"=AI39)+(表格6[Name]&"_5"=AI39))} -> Li Wenjie | AK39: {=_xlfn._xlws.FILTER(三國演義!$C$13:$C$80,三國演義!$E$13:$E$80=Roster!AI39)} -> 35 | AL39: 60 | AM39: 0
A40: TP_1 Yata | B40: Gloria | C40: . | D40: . | E40: Gloria | F40: Gloria | G40: Gloria | H40: Gloria | I40: Gloria | J40: . | K40: . | L40: Gloria | M40: Gloria | N40: Gloria | O40: Gloria | P40: Gloria | Q40: . | R40: . | S40: Gloria | T40: Gloria | U40: Gloria | V40: Gloria | W40: Gloria | X40: . | Y40: . | Z40: Gloria | AA40: Gloria | AB40: Gloria | AC40: Gloria | AD40: Gloria | AE40: . | AF40: . | AG40: =COUNTA(B40:AF40)-COUNTIF(B40:AF40,"."&"*")-COUNTIF(B40:AF40,"off")-COUNTIF(B40:AF40,"SL"&" "&"*")-COUNTIF(B40:AF40,"PH"&" "&"*")-COUNTIF(B40:AF40,"AL"&" "&"*")-COUNTIF(B40:AF40,"CL"&" "&"*")-COUNTIF(B40:AF40,"Typhoon"&" "&"*")-COUNTIF(B40:AF40,"*"&"off")-COUNTIF(B40:AF40," "&"*") -> 21 | AH40: =AG40*8 -> 168 | AI40: {=_xlfn.LET( _xlpm.data, B40:AF40, _xlpm.removeList, {" off","."," SL","xxx"}, _xlpm.cleaned, TRIM(_xlfn.REDUCE(_xlpm.data, _xlpm.removeList, _xlfn.LAMBDA(_xlpm.arr,_xlpm.str, SUBSTITUTE(_xlpm.arr, _xlpm.str, "")))), _xlpm.first, _xlfn._xlws.FILTER(_xlpm.cleaned, _xlpm.cleaned <> ""), INDEX(_xlpm.first, 1) )} -> Gloria | AJ40: {=_xlfn._xlws.FILTER(表格6[Full Name],(表格6[Name]=AI40)+(表格6[Name]&"_1"=AI40)+(表格6[Name]&"_2"=AI40)+(表格6[Name]&"_3"=AI40)+(表格6[Name]&"_4"=AI40)+(表格6[Name]&"_5"=AI40))} -> Yeung Chor Mui | AK40: {=_xlfn._xlws.FILTER(三國演義!$C$13:$C$80,三國演義!$E$13:$E$80=Roster!AI40)} -> 36 | AL40: 60 | AM40: 0 | AN40: 0.02
...

Sheet editable-sales-form
L1: =SUBTOTAL(9,L3:L5502) -> 405 | N1: =SUBTOTAL(9,N3:N5502) -> 455239.6 | Q1: =+N1*0.02 -> 9104.792
A2: No. | B2: Shop | C2: Location | D2: Name | E2: month | F2: date | G2: Model | H2: Product Line | I2: 大/細電 | J2: Catalog | K2: Input | L2: QTY | M2: Unit Price | N2: Total Amount | O2: inv no | P2: apps report no. | Q2: remark2 | R2: Check | S2: SRP | T2: % | U2: 欄3 | V2: 欄4 | W2: 欄5
A3: 1 | B3: Aeon | C3: Panda | D3: =OFFSET(Roster!$A$3,MATCH(表格1[[#This Row],[Location]]&" "&表格1[[#This Row],[Shop]]&"*",Roster!$A$4:$A$72,0),DAY(表格1[[#This Row],[date]]),1,1) -> Winnie | E3: =MONTH(表格1[[#This Row],[date]]) -> 3 | F3: 46082 | G3: =VLOOKUP("*"&表格1[[#This Row],[Input]]&"*",'Ref-List'!$B:$D,2,) -> TWD-BN90GF4H(WK) | H3: =_xlfn.XLOOKUP(表格1[[#This Row],[Model]],表格3[Model-Input-Ref2],表格3[Product Line]) -> 超薄身前置式洗衣乾衣機 (洗8公斤 乾5公斤) | I3: =_xlfn.XLOOKUP(表格1[[#This Row],[Model]],表格3[Model-Input-Ref2],表格3[大小電]) -> 大電 | J3: =_xlfn.XLOOKUP(表格1[[#This Row],[Model]],表格3[Model-Input-Ref2],表格3[Code]) -> WM | K3: bn90 | L3: 1 | M3: 3588 | N3: =IFERROR(表格1[[#This Row],[QTY]]*表格1[[#This Row],[Unit Price]],"-") -> 3588 | O3: 5817993 | R3: =_xlfn.CONCAT(表格1[[#This Row],[Model]]," ",表格1[[#This Row],[inv no]]) -> TWD-BN90GF4H(WK) 5817993 | S3: =_xlfn.XLOOKUP(表格1[[#This Row],[Model]],表格3[Model-Input-Ref2],表格3[SRP PRICE]) -> 5980 | T3: =表格1[[#This Row],[Unit Price]]/表格1[[#This Row],[SRP]] -> 0.6 | U3: =_xlfn.XLOOKUP(表格1[[#This Row],[Model]],表格3[Model-Input-Ref2],表格3[TOSHIBA/HIGHEST]) -> Toshiba SRP | W3: =_xlfn.CONCAT(表格1[[#This Row],[欄4]],表格1[[#This Row],[inv no]]) -> 5817993
A4: 2 | B4: Aeon | C4: Panda | D4: =OFFSET(Roster!$A$3,MATCH(表格1[[#This Row],[Location]]&" "&表格1[[#This Row],[Shop]]&"*",Roster!$A$4:$A$72,0),DAY(表格1[[#This Row],[date]]),1,1) -> Winnie | E4: =MONTH(表格1[[#This Row],[date]]) -> 3 | F4: 46082 | G4: =VLOOKUP("*"&表格1[[#This Row],[Input]]&"*",'Ref-List'!$B:$D,2,) -> RC-15ISTHK(W) | H4: =_xlfn.XLOOKUP(表格1[[#This Row],[Model]],表格3[Model-Input-Ref2],表格3[Product Line]) -> 磁應電飯煲(1.5公升) | I4: =_xlfn.XLOOKUP(表格1[[#This Row],[Model]],表格3[Model-Input-Ref2],表格3[大小電]) -> 細電 | J4: =_xlfn.XLOOKUP(表格1[[#This Row],[Model]],表格3[Model-Input-Ref2],表格3[Code]) -> SDA | K4: 15ist | L4: 1 | M4: 500 | N4: =IFERROR(表格1[[#This Row],[QTY]]*表格1[[#This Row],[Unit Price]],"-") -> 500 | O4: 5817988 | R4: =_xlfn.CONCAT(表格1[[#This Row],[Model]]," ",表格1[[#This Row],[inv no]]) -> RC-15ISTHK(W) 5817988 | S4: =_xlfn.XLOOKUP(表格1[[#This Row],[Model]],表格3[Model-Input-Ref2],表格3[SRP PRICE]) -> 1688 | T4: =表格1[[#This Row],[Unit Price]]/表格1[[#This Row],[SRP]] -> 0.29620853 | U4: =_xlfn.XLOOKUP(表格1[[#This Row],[Model]],表格3[Model-Input-Ref2],表格3[TOSHIBA/HIGHEST]) -> Toshiba SRP | W4: =_xlfn.CONCAT(表格1[[#This Row],[欄4]],表格1[[#This Row],[inv no]]) -> 5817988
A5: 3 | B5: Aeon | C5: Panda | D5: =OFFSET(Roster!$A$3,MATCH(表格1[[#This Row],[Location]]&" "&表格1[[#This Row],[Shop]]&"*",Roster!$A$4:$A$72,0),DAY(表格1[[#This Row],[date]]),1,1) -> Winnie | E5: =MONTH(表格1[[#This Row],[date]]) -> 3 | F5: 46082 | G5: =VLOOKUP("*"&表格1[[#This Row],[Input]]&"*",'Ref-List'!$B:$D,2,) -> RC-15ISTHK(W) | H5: =_xlfn.XLOOKUP(表格1[[#This Row],[Model]],表格3[Model-Input-Ref2],表格3[Product Line]) -> 磁應電飯煲(1.5公升) | I5: =_xlfn.XLOOKUP(表格1[[#This Row],[Model]],表格3[Model-Input-Ref2],表格3[大小電]) -> 細電 | J5: =_xlfn.XLOOKUP(表格1[[#This Row],[Model]],表格3[Model-Input-Ref2],表格3[Code]) -> SDA | K5: 15ist | L5: 1 | M5: 500 | N5: =IFERROR(表格1[[#This Row],[QTY]]*表格1[[#This Row],[Unit Price]],"-") -> 500 | O5: 5817996 | R5: =_xlfn.CONCAT(表格1[[#This Row],[Model]]," ",表格1[[#This Row],[inv no]]) -> RC-15ISTHK(W) 5817996 | S5: =_xlfn.XLOOKUP(表格1[[#This Row],[Model]],表格3[Model-Input-Ref2],表格3[SRP PRICE]) -> 1688 | T5: =表格1[[#This Row],[Unit Price]]/表格1[[#This Row],[SRP]] -> 0.29620853 | U5: =_xlfn.XLOOKUP(表格1[[#This Row],[Model]],表格3[Model-Input-Ref2],表格3[TOSHIBA/HIGHEST]) -> Toshiba SRP | V5: 110 | W5: =_xlfn.CONCAT(表格1[[#This Row],[欄4]],表格1[[#This Row],[inv no]]) -> 1105817996
A6: 4 | B6: Aeon | C6: Panda | D6: =OFFSET(Roster!$A$3,MATCH(表格1[[#This Row],[Location]]&" "&表格1[[#This Row],[Shop]]&"*",Roster!$A$4:$A$72,0),DAY(表格1[[#This Row],[date]]),1,1) -> Winnie | E6: =MONTH(表格1[[#This Row],[date]]) -> 3 | F6: 46082 | G6: =VLOOKUP("*"&表格1[[#This Row],[Input]]&"*",'Ref-List'!$B:$D,2,) -> GR-A26HSZ(DS) | H6: =_xlfn.XLOOKUP(表格1[[#This Row],[Model]],表格3[Model-Input-Ref2],表格3[Product Line]) -> 雙門變頻式環保雪櫃 | I6: =_xlfn.XLOOKUP(表格1[[#This Row],[Model]],表格3[Model-Input-Ref2],表格3[大小電]) -> 大電 | J6: =_xlfn.XLOOKUP(表格1[[#This Row],[Model]],表格3[Model-Input-Ref2],表格3[Code]) -> AC | K6: a26hsz | L6: 1 | M6: 1500 | N6: =IFERROR(表格1[[#This Row],[QTY]]*表格1[[#This Row],[Unit Price]],"-") -> 1500 | O6: 5817973 | R6: =_xlfn.CONCAT(表格1[[#This Row],[Model]]," ",表格1[[#This Row],[inv no]]) -> GR-A26HSZ(DS) 5817973 | S6: =_xlfn.XLOOKUP(表格1[[#This Row],[Model]],表格3[Model-Input-Ref2],表格3[SRP PRICE]) -> 3780 | T6: =表格1[[#This Row],[Unit Price]]/表格1[[#This Row],[SRP]] -> 0.3968254 | U6: =_xlfn.XLOOKUP(表格1[[#This Row],[Model]],表格3[Model-Input-Ref2],表格3[TOSHIBA/HIGHEST]) -> Toshiba SRP | V6: 110 | W6: =_xlfn.CONCAT(表格1[[#This Row],[欄4]],表格1[[#This Row],[inv no]]) -> 1105817973
A7: 5 | B7: Aeon | C7: Panda | D7: =OFFSET(Roster!$A$3,MATCH(表格1[[#This Row],[Location]]&" "&表格1[[#This Row],[Shop]]&"*",Roster!$A$4:$A$72,0),DAY(表格1[[#This Row],[date]]),1,1) -> Winnie | E7: =MONTH(表格1[[#This Row],[date]]) -> 3 | F7: 46082 | G7: =VLOOKUP("*"&表格1[[#This Row],[Input]]&"*",'Ref-List'!$B:$D,2,) -> RC-15ISTHK(W) | H7: =_xlfn.XLOOKUP(表格1[[#This Row],[Model]],表格3[Model-Input-Ref2],表格3[Product Line]) -> 磁應電飯煲(1.5公升) | I7: =_xlfn.XLOOKUP(表格1[[#This Row],[Model]],表格3[Model-Input-Ref2],表格3[大小電]) -> 細電 | J7: =_xlfn.XLOOKUP(表格1[[#This Row],[Model]],表格3[Model-Input-Ref2],表格3[Code]) -> SDA | K7: 15ist | L7: 1 | M7: 500 | N7: =IFERROR(表格1[[#This Row],[QTY]]*表格1[[#This Row],[Unit Price]],"-") -> 500 | O7: 5817973 | R7: =_xlfn.CONCAT(表格1[[#This Row],[Model]]," ",表格1[[#This Row],[inv no]]) -> RC-15ISTHK(W) 5817973 | S7: =_xlfn.XLOOKUP(表格1[[#This Row],[Model]],表格3[Model-Input-Ref2],表格3[SRP PRICE]) -> 1688 | T7: =表格1[[#This Row],[Unit Price]]/表格1[[#This Row],[SRP]] -> 0.29620853 | U7: =_xlfn.XLOOKUP(表格1[[#This Row],[Model]],表格3[Model-Input-Ref2],表格3[TOSHIBA/HIGHEST]) -> Toshiba SRP | V7: 110 | W7: =_xlfn.CONCAT(表格1[[#This Row],[欄4]],表格1[[#This Row],[inv no]]) -> 1105817973
A8: 6 | B8: Aeon | C8: Panda | D8: =OFFSET(Roster!$A$3,MATCH(表格1[[#This Row],[Location]]&" "&表格1[[#This Row],[Shop]]&"*",Roster!$A$4:$A$72,0),DAY(表格1[[#This Row],[date]]),1,1) -> Winnie | E8: =MONTH(表格1[[#This Row],[date]]) -> 3 | F8: 46082 | G8: =VLOOKUP("*"&表格1[[#This Row],[Input]]&"*",'Ref-List'!$B:$D,2,) -> TW-BL85A2H(WW) | H8: =_xlfn.XLOOKUP(表格1[[#This Row],[Model]],表格3[Model-Input-Ref2],表格3[Product Line]) -> 7.5KG超薄身前置式變頻洗衣機 | I8: =_xlfn.XLOOKUP(表格1[[#This Row],[Model]],表格3[Model-Input-Ref2],表格3[大小電]) -> 大電 | J8: =_xlfn.XLOOKUP(表格1[[#This Row],[Model]],表格3[Model-Input-Ref2],表格3[Code]) -> WM | K8: bl85a2 | L8: 1 | M8: 2588 | N8: =IFERROR(表格1[[#This Row],[QTY]]*表格1[[#This Row],[Unit Price]],"-") -> 2588 | O8: 5817997 | R8: =_xlfn.CONCAT(表格1[[#This Row],[Model]]," ",表格1[[#This Row],[inv no]]) -> TW-BL85A2H(WW) 5817997 | S8: =_xlfn.XLOOKUP(表格1[[#This Row],[Model]],表格3[Model-Input-Ref2],表格3[SRP PRICE]) -> 5080 | T8: =表格1[[#This Row],[Unit Price]]/表格1[[#This Row],[SRP]] -> 0.50944882 | U8: =_xlfn.XLOOKUP(表格1[[#This Row],[Model]],表格3[Model-Input-Ref2],表格3[TOSHIBA/HIGHEST]) -> Toshiba SRP | V8: 110 | W8: =_xlfn.CONCAT(表格1[[#This Row],[欄4]],表格1[[#This Row],[inv no]]) -> 1105817997
A9: 7 | B9: Aeon | C9: Panda | D9: =OFFSET(Roster!$A$3,MATCH(表格1[[#This Row],[Location]]&" "&表格1[[#This Row],[Shop]]&"*",Roster!$A$4:$A$72,0),DAY(表格1[[#This Row],[date]]),1,1) -> Winnie | E9: =MONTH(表格1[[#This Row],[date]]) -> 3 | F9: 46082 | G9: =VLOOKUP("*"&表格1[[#This Row],[Input]]&"*",'Ref-List'!$B:$D,2,) -> TWP-TSR76THK(W) | H9: =_xlfn.XLOOKUP(表格1[[#This Row],[Model]],表格3[Model-Input-Ref2],表格3[Product Line]) -> RO座檯式飲水機 | I9: =_xlfn.XLOOKUP(表格1[[#This Row],[Model]],表格3[Model-Input-Ref2],表格3[大小電]) -> 細電 | J9: =_xlfn.XLOOKUP(表格1[[#This Row],[Model]],表格3[Model-Input-Ref2],表格3[Code]) -> KWH | K9: tsr76 | L9: 1 | M9: 1500 | N9: =IFERROR(表格1[[#This Row],[QTY]]*表格1[[#This Row],[Unit Price]],"-") -> 1500 | O9: 6053083 | R9: =_xlfn.CONCAT(表格1[[#This Row],[Model]]," ",表格1[[#This Row],[inv no]]) -> TWP-TSR76THK(W) 6053083 | S9: =_xlfn.XLOOKUP(表格1[[#This Row],[Model]],表格3[Model-Input-Ref2],表格3[SRP PRICE]) -> 2680 | T9: =表格1[[#This Row],[Unit Price]]/表格1[[#This Row],[SRP]] -> 0.55970149 | U9: =_xlfn.XLOOKUP(表格1[[#This Row],[Model]],表格3[Model-Input-Ref2],表格3[TOSHIBA/HIGHEST]) -> Toshiba SRP | V9: 110 | W9: =_xlfn.CONCAT(表格1[[#This Row],[欄4]],表格1[[#This Row],[inv no]]) -> 1106053083
A10: 8 | B10: Aeon | C10: Panda | D10: =OFFSET(Roster!$A$3,MATCH(表格1[[#This Row],[Location]]&" "&表格1[[#This Row],[Shop]]&"*",Roster!$A$4:$A$72,0),DAY(表格1[[#This Row],[date]]),1,1) -> Winnie | E10: =MONTH(表格1[[#This Row],[date]]) -> 3 | F10: 46082 | G10: =VLOOKUP("*"&表格1[[#This Row],[Input]]&"*",'Ref-List'!$B:$D,2,) -> RC-15ISTHK(W) | H10: =_xlfn.XLOOKUP(表格1[[#This Row],[Model]],表格3[Model-Input-Ref2],表格3[Product Line]) -> 磁應電飯煲(1.5公升) | I10: =_xlfn.XLOOKUP(表格1[[#This Row],[Model]],表格3[Model-Input-Ref2],表格3[大小電]) -> 細電 | J10: =_xlfn.XLOOKUP(表格1[[#This Row],[Model]],表格3[Model-Input-Ref2],表格3[Code]) -> SDA | K10: 15ist | L10: 1 | M10: 500 | N10: =IFERROR(表格1[[#This Row],[QTY]]*表格1[[#This Row],[Unit Price]],"-") -> 500 | O10: 6053082 | R10: =_xlfn.CONCAT(表格1[[#This Row],[Model]]," ",表格1[[#This Row],[inv no]]) -> RC-15ISTHK(W) 6053082 | S10: =_xlfn.XLOOKUP(表格1[[#This Row],[Model]],表格3[Model-Input-Ref2],表格3[SRP PRICE]) -> 1688 | T10: =表格1[[#This Row],[Unit Price]]/表格1[[#This Row],[SRP]] -> 0.29620853 | U10: =_xlfn.XLOOKUP(表格1[[#This Row],[Model]],表格3[Model-Input-Ref2],表格3[TOSHIBA/HIGHEST]) -> Toshiba SRP | V10: 110 | W10: =_xlfn.CONCAT(表格1[[#This Row],[欄4]],表格1[[#This Row],[inv no]]) -> 1106053082
