Workbook
Name Slicer_Full_Name1: #N/A
Name Slicer_Name.: #N/A

Sheet 1-10
A2: i Wall@
A3: SharpSing Limited
A4: Room 1609, 16/F., Golden Era Plaza, No. 39 Sai Yee Street, Mongkok, KLN. Tel:35868635 Fax:31889330
B6: 2025' Toshiba Promoter Salary Summary
B8: Name/姓名 | C8: =Total!$D$48 -> Chan So Mui | D8: {=INDEX(Total!$C$8:$C$992,MATCH($C8&$G8,Total!$D$8:$D$992&Total!$E$8:$E$992,0))} -> Mui Chan_2 | F8: CQ NO. | G8: =Total!$E$48 -> Autopay
B10: Job Detail | E10: Content
B11: Job Categories/工作類別 | E11: Promoter
B12: Location/工作地點 | E12: {=INDEX(Total!$F$8:$F$891,MATCH($C8&$G8,Total!$D$8:$D$891&Total!$E$8:$E$891,0))} -> Diamond Hill_2 Broadway
B13: Period/工作日子 | E13: {=INDEX(Total!$G$8:$G$891,MATCH($C8&$G8,Total!$D$8:$D$891&Total!$E$8:$E$891,0))} -> Mar/21-22
B14: Reg.Day/工作日數 | E14: {=INDEX(Total!$H$8:$H$891,MATCH($C8&$G8,Total!$D$8:$D$891&Total!$E$8:$E$891,0))} -> 2
B15: Reg.Hour/工作時數 | E15: {=INDEX(Total!$I$8:$I$891,MATCH($C8&$G8,Total!$D$8:$D$891&Total!$E$8:$E$891,0))} -> 16
B16: HK$/時薪 | E16: {=INDEX(Total!$J$8:$J$891,MATCH($C8&$G8,Total!$D$8:$D$891&Total!$E$8:$E$891,0))} -> 60
B17: Sales Record/銷售紀錄 | E17: {=INDEX(Total!$L$8:$L$891,MATCH($C8&$G8,Total!$D$8:$D$891&Total!$E$8:$E$891,0))} -> 17304
C19: Salary Detail | F19: Sub. Total
C20: Basic/酬金 | G20: {=INDEX(Total!$K$8:$K$891,MATCH($C8&$G8,Total!$D$8:$D$891&Total!$E$8:$E$891,0))} -> 960
C21: =表格1[[#Headers],[三門雪櫃特佣 GR-RM469WE-PGA(B3)]] -> 三門雪櫃特佣 GR-RM469WE-PGA(B3) | G21: {=INDEX(Total!$AH$8:$AH$891,MATCH($C8&$G8,Total!$D$8:$D$891&Total!$E$8:$E$891,0))} -> 1336
C22: Commission/佣金 | G22: {=INDEX(Total!$N$8:$N$891,MATCH($C8&$G8,Total!$D$8:$D$891&Total!$E$8:$E$891,0))} -> 346.08
C23: Allowance/津貼 | G23: {=INDEX(Total!$P$8:$P$891,MATCH($C8&$G8,Total!$D$8:$D$891&Total!$E$8:$E$891,0))} -> 0
C24: =表格1[[#Headers],[嵌入式微波氣炸蒸焗爐特佣 EB-T500APW]] -> 嵌入式微波氣炸蒸焗爐特佣 EB-T500APW | G24: {=INDEX(Total!$S$8:$S$891,MATCH($C8&$G8,Total!$D$8:$D$891&Total!$E$8:$E$891,0))} -> 0
C25: =表格1[[#Headers],[蒸氣烤焗水波爐特佣 ER-VD7000HK(XK)]] -> 蒸氣烤焗水波爐特佣 ER-VD7000HK(XK) | G25: {=INDEX(Total!$T$8:$T$891,MATCH($C8&$G8,Total!$D$8:$D$891&Total!$E$8:$E$891,0))} -> 0
C26: =表格1[[#Headers],[日本飯煲 RC-DS10K/18K]] -> 日本飯煲 RC-DS10K/18K | G26: {=INDEX(Total!$Q$8:$Q$891,MATCH($C8&$G8,Total!$D$8:$D$891&Total!$E$8:$E$891,0))} -> 0
C27: =表格1[[#Headers],[TWDT21BU95 ]] -> TWDT21BU95 | G27: {=INDEX(Total!$U$8:$U$891,MATCH($C8&$G8,Total!$D$8:$D$891&Total!$E$8:$E$891,0))} -> 0
C28: =表格1[[#Headers],[日式洗衣機二特佣 AW-Q801APH(WW)]] -> 日式洗衣機二特佣 AW-Q801APH(WW) | G28: {=INDEX(Total!$Z$8:$Z$1002,MATCH($C8&$G8,Total!$D$8:$D$1002&Total!$E$8:$E$1002,0))} -> 0
C29: Expenses/支出 | G29: {=INDEX(Total!$W$8:$W$891,MATCH($C8&$G8,Total!$D$8:$D$891&Total!$E$8:$E$891,0))} -> 0
E30: Total | F30: =SUM($G20:$G29) -> 2642.08 | J30: {=INDEX(Total!$AJ$8:$AJ$1002,MATCH($C8&$G8,Total!$D$8:$D$1002&Total!$E$8:$E$1002,0))} -> 1306.08
B32: **如屬自僱人仕必須自行購買勞工保險及強積金；
B33: 註 1：如所支付之金額有錯誤，請在兩天內提出；
B34: 註 2：請自行核對清楚支票上的姓名及金額；
E35: Promoter 確認簽名 :
F37: I.D. Card No. :
A40: i Wall@
A41: SharpSing Limited
A42: Room 1609, 16/F., Golden Era Plaza, No. 39 Sai Yee Street, Mongkok, KLN. Tel:35868635 Fax:31889330
B44: 2025' Toshiba Promoter Salary Summary
B46: Name/姓名 | C46: =Total!$D$9 -> Wong Wai Chu | D46: {=INDEX(Total!$C$8:$C$1002,MATCH($C46&$G46,Total!$D$8:$D$1002&Total!$E$8:$E$1002,0))} -> Ivy Wong_1 | F46: CQ NO. | G46: =Total!$E$9 -> Autopay
B48: Job Detail | E48: Content
B49: Job Categories/工作類別 | E49: Promoter
B50: Location/工作地點 | E50: {=INDEX(Total!$F$8:$F$1002,MATCH($C46&$G46,Total!$D$8:$D$1002&Total!$E$8:$E$1002,0))} -> Vcity_1 Fortress
B51: Period/工作日子 | E51: {=INDEX(Total!$G$8:$G$1002,MATCH($C46&$G46,Total!$D$8:$D$1002&Total!$E$8:$E$1002,0))} -> Mar/1,14-15,21-22,25,28
B52: Reg.Day/工作日數 | E52: {=INDEX(Total!$H$8:$H$1002,MATCH($C46&$G46,Total!$D$8:$D$1002&Total!$E$8:$E$1002,0))} -> 7
...

Sheet 1-10 (2)
A2: i Wall@
A3: SharpSing Limited
A4: Room 1609, 16/F., Golden Era Plaza, No. 39 Sai Yee Street, Mongkok, KLN. Tel:35868635 Fax:31889330
B6: 2023' Toshiba Promoter Salary Summary
B8: Name/姓名 | C8: =Total!$D$20 -> Ho Lai Sim | D8: {=INDEX(Total!$C$8:$C$992,MATCH($C8&$G8,Total!$D$8:$D$992&Total!$E$8:$E$992,0))} -> Mandy | F8: CQ NO. | G8: =Total!$E$20 -> Autopay
B10: Job Detail | E10: Content
B11: Job Categories/工作類別 | E11: Promoter
B12: Location/工作地點 | E12: {=INDEX(Total!$F$8:$F$891,MATCH($C8&$G8,Total!$D$8:$D$891&Total!$E$8:$E$891,0))} -> TW_3 Citistore
B13: Period/工作日子 | E13: {=INDEX(Total!$G$8:$G$891,MATCH($C8&$G8,Total!$D$8:$D$891&Total!$E$8:$E$891,0))} -> Mar/12
B14: Reg.Day/工作日數 | E14: {=INDEX(Total!$H$8:$H$891,MATCH($C8&$G8,Total!$D$8:$D$891&Total!$E$8:$E$891,0))} -> 1
B15: Reg.Hour/工作時數 | E15: {=INDEX(Total!$I$8:$I$891,MATCH($C8&$G8,Total!$D$8:$D$891&Total!$E$8:$E$891,0))} -> 9
B16: HK$/時薪 | E16: {=INDEX(Total!$J$8:$J$891,MATCH($C8&$G8,Total!$D$8:$D$891&Total!$E$8:$E$891,0))} -> 60
B17: Sales Record/銷售紀錄 | E17: {=INDEX(Total!$L$8:$L$891,MATCH($C8&$G8,Total!$D$8:$D$891&Total!$E$8:$E$891,0))} -> 4664
C19: Salary Detail | F19: Sub. Total
C20: Basic/酬金 | G20: {=INDEX(Total!$K$8:$K$891,MATCH($C8&$G8,Total!$D$8:$D$891&Total!$E$8:$E$891,0))} -> 540
C21: Attendance/出勤 | G21: {=INDEX(Total!$AH$8:$AH$891,MATCH($C8&$G8,Total!$D$8:$D$891&Total!$E$8:$E$891,0))} -> 633
C22: Commission/佣金 | G22: {=INDEX(Total!$N$8:$N$891,MATCH($C8&$G8,Total!$D$8:$D$891&Total!$E$8:$E$891,0))} -> 93.28
C23: Allowance/津貼 | G23: {=INDEX(Total!$P$8:$P$891,MATCH($C8&$G8,Total!$D$8:$D$891&Total!$E$8:$E$891,0))} -> 0
C24: Award/獎金 | G24: {=INDEX(Total!$S$8:$S$891,MATCH($C8&$G8,Total!$D$8:$D$891&Total!$E$8:$E$891,0))} -> 0
C25: Expenses/支出 | G25: {=INDEX(Total!$T$8:$T$891,MATCH($C8&$G8,Total!$D$8:$D$891&Total!$E$8:$E$891,0))} -> 0
C26: Other/其他 | G26: {=INDEX(Total!$W$8:$W$891,MATCH($C8&$G8,Total!$D$8:$D$891&Total!$E$8:$E$891,0))} -> 0
C27: Adjustment/調整 | G27: {=INDEX(Total!$U$8:$U$891,MATCH($C8&$G8,Total!$D$8:$D$891&Total!$E$8:$E$891,0))} -> 0
C28: MPF/強積金** | G28: {=-INDEX(Total!$Z$8:$Z$891,MATCH($C8&$G8,Total!$D$8:$D$891&Total!$E$8:$E$891,0))} -> 0
E29: Total | F29: =SUM($G20:$G28) -> 1266.28 | J29: {=INDEX(Total!$AJ$8:$AJ$1002,MATCH($C8&$G8,Total!$D$8:$D$1002&Total!$E$8:$E$1002,0))} -> 633.28
B31: **如屬自僱人仕必須自行購買勞工保險及強積金；
B32: 註 1：如所支付之金額有錯誤，請在兩天內提出；
B33: 註 2：請自行核對清楚支票上的姓名及金額；
E34: Promoter 確認簽名 :
F36: I.D. Card No. :
A39: i Wall@
A40: SharpSing Limited
A41: Room 1609, 16/F., Golden Era Plaza, No. 39 Sai Yee Street, Mongkok, KLN. Tel:35868635 Fax:31889330
B43: 2023' Toshiba Promoter Salary Summary
B45: Name/姓名 | C45: =Total!$D$21 -> Chiu Fung Shan | D45: {=INDEX(Total!$C$8:$C$1002,MATCH($C45&$G45,Total!$D$8:$D$1002&Total!$E$8:$E$1002,0))} -> Shan_2 | F45: CQ NO. | G45: =Total!$E$21 -> 20856
B47: Job Detail | E47: Content
B48: Job Categories/工作類別 | E48: Promoter
B49: Location/工作地點 | E49: {=INDEX(Total!$F$8:$F$1002,MATCH($C45&$G45,Total!$D$8:$D$1002&Total!$E$8:$E$1002,0))} -> TW RS_1 Citistore
B50: Period/工作日子 | E50: {=INDEX(Total!$G$8:$G$1002,MATCH($C45&$G45,Total!$D$8:$D$1002&Total!$E$8:$E$1002,0))} -> Mar/25-31
B51: Reg.Day/工作日數 | E51: {=INDEX(Total!$H$8:$H$1002,MATCH($C45&$G45,Total!$D$8:$D$1002&Total!$E$8:$E$1002,0))} -> 7
B52: Reg.Hour/工作時數 | E52: {=INDEX(Total!$I$8:$I$1002,MATCH($C45&$G45,Total!$D$8:$D$1002&Total!$E$8:$E$1002,0))} -> 56
...

Sheet Total
F1: Toshiba AC | G1: SSPT20220440 - Toshiba AC | AU1: Invoice No. | AV1: MPF | AW1: Total
AG2: Invoice No. | AU2: =AH2 -> 0 | AV2: 0 | AW2: =AH6 -> 525200
AG3: Income | AH3: 576057
AG4: Pay | AH4: =AH6 -> 525200
N5: 36453.96 | P5: MCA Oven | R5: LAD | S5: SDA JP RCK | T5: REF RM612 | V5: Comfee RAC | W5: LAD BN90 | AG5: GP | AH5: =AH3-AH4 -> 50857
A6: 2026 | B6: March | C6: Toshiba | H6: =SUM(H8:H133) -> 652 | I6: =SUM(I8:I133) -> 5330.5 | J6: =SUM(J8:J133) -> 3810 | K6: =SUM(K8:K133) -> 312060 | L6: =SUM(L8:L133) -> 9587202.9 | M6: =SUM(M8:M133) -> 0 | N6: =SUM(N8:N133) -> 183924.79 | O6: =SUM(O8:O133) -> 10820.54 | ... AH6: =SUM(AH8:AH133) -> 525200
A7: No. | B7: 欄1 | C7: Name. | D7: Full Name. | E7: CQ No. | F7: Shop | G7: Period | H7: Days | I7: Reg.Hrs | J7: $ | K7: Basic | L7: Sales | M7: QTY | N7: Commission (1% OR 2%) | O7: Allowance | P7: 日本飯煲 RC-DS10K/18K | Q7: 酵活炊電飯煲特佣 RC-18AMXH(W) | R7: 嵌入式微波氣炸蒸焗爐特佣 EB-T500APW | S7: 蒸氣烤焗水波爐特佣 ER-VD7000HK(XK) | T7: TWDT21BU95 | U7: 日式洗衣機一特佣 AW-Q800APH(WW) | V7: 日式洗衣機二特佣 AW-Q801APH(WW) | W7: 三門雪櫃特佣 GR-RM469WE-PGA(B3) | X7: 雙門雪櫃一特佣 GR-RB449WE-PMA(57) | Y7: 雙門雪櫃一特佣 GR-RB410WE-PMA(06) | Z7: 十字門雪櫃 GR-RF698WI | AA7: 水機 TWP-W2265THK(W) | AB7: 抽濕機特佣 | AC7: (Fortress ONLY)TW-T25BZU115MWH(MG) | AD7: 開門紅(三月) | AE7: 開門紅(第一季) | AF7: Expenses/支出 | AG7: Total | AH7: Input | AI7: 欄2 | AJ7: Double check | AK7: Double check2 | AL7: 欄5
A8: 1 | B8: =IF(表格1[[#This Row],[Full Name.]]=工作表1!F2,"OK") -> OK | C8: May C | D8: Cheng Muk Kiu | E8: 20850 | F8: Kornhill Aeon | G8: Mar/1-3,5-8,10-13,15-17,20-23,26-29 | H8: 22 | I8: 176 | J8: 55 | K8: =表格1[[#This Row],[Reg.Hrs]]*表格1[[#This Row],[$]] -> 9680 | L8: 455239.6 | N8: =IFERROR((IF(表格1[[#This Row],[Name.]]=工作表1!$E2,工作表1!$K2," ")*表格1[[#This Row],[Sales]])," ") -> 9104.792 | O8: =IFERROR((IF(表格1[[#This Row],[Full Name.]]=工作表1!F2,工作表1!J2," ")*表格1[[#This Row],[Days]])," ") -> 660 | P8: 0 | Q8: 300 | R8: 0 | S8: 0 | T8: 0 | U8: 0 | V8: 0 | W8: 0 | X8: 0 | Y8: 0 | Z8: 0 | AA8: 0 | AB8: 0 | AC8: 0 | AD8: 0 | AE8: 0 | AG8: =SUM(表格1[[#This Row],[Commission (1% OR 2%)]:[Expenses/支出]])+表格1[[#This Row],[Basic]] -> 19744.792 | AH8: =ROUND(AG8,0) -> 19745 | AJ8: 19744.792 | AK8: =表格1[[#This Row],[Input]]-表格1[[#This Row],[Double check]] -> 0.208
A9: 2 | B9: =IF(表格1[[#This Row],[Full Name.]]=工作表1!F3,"OK") -> OK | C9: Ivy Wong_1 | D9: Wong Wai Chu | E9: Autopay | F9: Vcity_1 Fortress | G9: Mar/1,14-15,21-22,25,28 | H9: 7 | I9: 56 | J9: 60 | K9: =表格1[[#This Row],[Reg.Hrs]]*表格1[[#This Row],[$]] -> 3360 | L9: 242326 | N9: =IFERROR((IF(表格1[[#This Row],[Name.]]=工作表1!$E3,工作表1!$K3," ")*表格1[[#This Row],[Sales]])," ") -> 4846.52 | O9: =IFERROR((IF(表格1[[#This Row],[Full Name.]]=工作表1!F3,工作表1!J3," ")*表格1[[#This Row],[Days]])," ") -> 0 | P9: 0 | Q9: 0 | R9: 0 | S9: 0 | T9: 0 | U9: 0 | V9: 0 | W9: 0 | X9: 0 | Y9: 200 | Z9: 0 | AA9: 200 | AB9: 0 | AC9: 0 | AD9: 0 | AE9: 0 | AG9: =SUM(表格1[[#This Row],[Commission (1% OR 2%)]:[Expenses/支出]])+表格1[[#This Row],[Basic]] -> 8606.52 | AH9: =ROUND(AG9,0) -> 8607 | AJ9: 8606.52 | AK9: =表格1[[#This Row],[Input]]-表格1[[#This Row],[Double check]] -> 0.48
A10: 3 | B10: =IF(表格1[[#This Row],[Full Name.]]=工作表1!F4,"OK") -> OK | C10: Kit_3 | D10: Li Wenjie | E10: Autopay | F10: Vcity_2 Fortress | G10: Mar/7-8 | H10: 2 | I10: 16 | J10: 60 | K10: =表格1[[#This Row],[Reg.Hrs]]*表格1[[#This Row],[$]] -> 960 | L10: 7911 | N10: =IFERROR((IF(表格1[[#This Row],[Name.]]=工作表1!$E4,工作表1!$K4," ")*表格1[[#This Row],[Sales]])," ") -> 158.22 | O10: =IFERROR((IF(表格1[[#This Row],[Full Name.]]=工作表1!F4,工作表1!J4," ")*表格1[[#This Row],[Days]])," ") -> 0 | AG10: =SUM(表格1[[#This Row],[Commission (1% OR 2%)]:[Expenses/支出]])+表格1[[#This Row],[Basic]] -> 1118.22 | AH10: =ROUND(AG10,0) -> 1118 | AJ10: 1118.22 | AK10: =表格1[[#This Row],[Input]]-表格1[[#This Row],[Double check]] -> -0.22
A11: 4 | B11: =IF(表格1[[#This Row],[Full Name.]]=工作表1!F5,"OK") -> OK | C11: Vicky L | D11: Leung Ching | E11: 20851 | F11: Diamond Hill Fortress | G11: Mar/1-2,4,6-8,13-19,21-31 | H11: 24 | I11: 192 | J11: 60 | K11: =表格1[[#This Row],[Reg.Hrs]]*表格1[[#This Row],[$]] -> 11520 | L11: 503165 | N11: =IFERROR((IF(表格1[[#This Row],[Name.]]=工作表1!$E5,工作表1!$K5," ")*表格1[[#This Row],[Sales]])," ") -> 10063.3 | O11: =IFERROR((IF(表格1[[#This Row],[Full Name.]]=工作表1!F5,工作表1!J5," ")*表格1[[#This Row],[Days]])," ") -> 0 | P11: 0 | Q11: 0 | R11: 0 | S11: 0 | T11: 880 | U11: 0 | V11: 0 | W11: 0 | X11: 0 | Y11: 0 | Z11: 0 | AA11: 0 | AB11: 0 | AC11: 0 | AD11: 500 | AE11: 1000 | AG11: =SUM(表格1[[#This Row],[Commission (1% OR 2%)]:[Expenses/支出]])+表格1[[#This Row],[Basic]] -> 23963.3 | AH11: =ROUND(AG11,0) -> 23963 | AJ11: 23963.3 | AK11: =表格1[[#This Row],[Input]]-表格1[[#This Row],[Double check]] -> -0.3
A12: 5 | B12: =IF(表格1[[#This Row],[Full Name.]]=工作表1!F6,"OK") -> OK | C12: Michelle | D12: Lo Muk Chun | E12: Autopay | F12: Good Hope Fortress | G12: Mar/1,5-8,11-15,17-22,25-29,31 | H12: 22 | I12: 176 | J12: 60 | K12: =表格1[[#This Row],[Reg.Hrs]]*表格1[[#This Row],[$]] -> 10560 | L12: 442858 | N12: =IFERROR((IF(表格1[[#This Row],[Name.]]=工作表1!$E6,工作表1!$K6," ")*表格1[[#This Row],[Sales]])," ") -> 8857.16 | O12: =IFERROR((IF(表格1[[#This Row],[Full Name.]]=工作表1!F6,工作表1!J6," ")*表格1[[#This Row],[Days]])," ") -> 0 | P12: 0 | Q12: 0 | R12: 0 | S12: 0 | T12: 480 | U12: 0 | V12: 0 | W12: 0 | X12: 500 | Y12: 0 | Z12: 0 | AA12: 0 | AB12: 0 | AC12: 0 | AD12: 0 | AE12: 0 | AG12: =SUM(表格1[[#This Row],[Commission (1% OR 2%)]:[Expenses/支出]])+表格1[[#This Row],[Basic]] -> 20397.16 | AH12: =ROUND(AG12,0) -> 20397 | AJ12: 20397.16 | AK12: =表格1[[#This Row],[Input]]-表格1[[#This Row],[Double check]] -> -0.16
A13: 6 | B13: =IF(表格1[[#This Row],[Full Name.]]=工作表1!F7,"OK") -> OK | C13: Jessica | D13: Chiu Kan | E13: 20852 | F13: Whampoa Aeon | G13: Mar/1-3,6-9,12-15,19-24,27-28,31 | H13: 20 | I13: 160 | J13: 55 | K13: =表格1[[#This Row],[Reg.Hrs]]*表格1[[#This Row],[$]] -> 8800 | L13: 419085.2 | N13: =IFERROR((IF(表格1[[#This Row],[Name.]]=工作表1!$E7,工作表1!$K7," ")*表格1[[#This Row],[Sales]])," ") -> 8381.704 | O13: =IFERROR((IF(表格1[[#This Row],[Full Name.]]=工作表1!F7,工作表1!J7," ")*表格1[[#This Row],[Days]])," ") -> 1600 | P13: 0 | Q13: 0 | R13: 0 | S13: 0 | T13: 0 | U13: 0 | V13: 0 | W13: 0 | X13: 0 | Y13: 0 | Z13: 0 | AA13: 200 | AB13: 0 | AC13: 0 | AD13: 0 | AE13: 0 | AG13: =SUM(表格1[[#This Row],[Commission (1% OR 2%)]:[Expenses/支出]])+表格1[[#This Row],[Basic]] -> 18981.704 | AH13: =ROUND(AG13,0) -> 18982 | AJ13: 18981.704 | AK13: =表格1[[#This Row],[Input]]-表格1[[#This Row],[Double check]] -> 0.296
A14: 7 | B14: =IF(表格1[[#This Row],[Full Name.]]=工作表1!F8,"OK") -> OK | C14: Kitty Yeung | D14: Yeung Lai Shan | E14: 20853 | F14: TKW Suning | G14: Mar/1-4,7-11,14-17,21-25,28-31 | H14: 22 | I14: 176 | J14: 60 | K14: =表格1[[#This Row],[Reg.Hrs]]*表格1[[#This Row],[$]] -> 10560 | L14: 234404 | N14: =IFERROR((IF(表格1[[#This Row],[Name.]]=工作表1!$E8,工作表1!$K8," ")*表格1[[#This Row],[Sales]])," ") -> 4688.08 | O14: =IFERROR((IF(表格1[[#This Row],[Full Name.]]=工作表1!F8,工作表1!J8," ")*表格1[[#This Row],[Days]])," ") -> 0 | P14: 0 | Q14: 0 | R14: 0 | S14: 0 | T14: 0 | U14: 0 | V14: 250 | W14: 0 | X14: 0 | Y14: 0 | Z14: 0 | AA14: 0 | AB14: 0 | AC14: 0 | AD14: 500 | AE14: 0 | AG14: =SUM(表格1[[#This Row],[Commission (1% OR 2%)]:[Expenses/支出]])+表格1[[#This Row],[Basic]] -> 15998.08 | AH14: =ROUND(AG14,0) -> 15998 | AJ14: 15998.08 | AK14: =表格1[[#This Row],[Input]]-表格1[[#This Row],[Double check]] -> -0.08
A15: 8 | B15: =IF(表格1[[#This Row],[Full Name.]]=工作表1!F9,"OK") -> OK | C15: Amy Or_1 | D15: Or Sim Kiu | E15: 20854 | F15: Tai koo Broadway | G15: Mar/1,7,28-29 | H15: 4 | I15: 32 | J15: 55 | K15: =表格1[[#This Row],[Reg.Hrs]]*表格1[[#This Row],[$]] -> 1760 | L15: 82154 | N15: =IFERROR((IF(表格1[[#This Row],[Name.]]=工作表1!$E9,工作表1!$K9," ")*表格1[[#This Row],[Sales]])," ") -> 1643.08 | O15: =IFERROR((IF(表格1[[#This Row],[Full Name.]]=工作表1!F9,工作表1!J9," ")*表格1[[#This Row],[Days]])," ")+180+60 -> 360 | P15: 0 | Q15: 0 | R15: 0 | S15: 0 | T15: 0 | U15: 0 | V15: 0 | W15: 0 | X15: 0 | Y15: 0 | Z15: 0 | AA15: 0 | AB15: 0 | AC15: 0 | AD15: 0 | AE15: 0 | AG15: =SUM(表格1[[#This Row],[Commission (1% OR 2%)]:[Expenses/支出]])+表格1[[#This Row],[Basic]] -> 3763.08 | AH15: =ROUND(AG15,0) -> 3763 | AJ15: 3523.08 | AK15: =表格1[[#This Row],[Input]]-表格1[[#This Row],[Double check]] -> 239.92
A16: 9 | B16: =IF(表格1[[#This Row],[Full Name.]]=工作表1!F10,"OK") -> OK | C16: Fong_1 | D16: Ng Nga Fong | E16: Autopay | F16: Diamond Hill_1 Broadway | G16: Mar/1,7-8,14-15,28-29 | H16: 7 | I16: 56 | J16: 60 | K16: =表格1[[#This Row],[Reg.Hrs]]*表格1[[#This Row],[$]] -> 3360 | L16: 67587 | N16: =IFERROR((IF(表格1[[#This Row],[Name.]]=工作表1!$E10,工作表1!$K10," ")*表格1[[#This Row],[Sales]])," ") -> 1351.74 | O16: =IFERROR((IF(表格1[[#This Row],[Full Name.]]=工作表1!F10,工作表1!J10," ")*表格1[[#This Row],[Days]])," ") -> 0 | AG16: =SUM(表格1[[#This Row],[Commission (1% OR 2%)]:[Expenses/支出]])+表格1[[#This Row],[Basic]] -> 4711.74 | AH16: =ROUND(AG16,0) -> 4712 | AJ16: 4711.74 | AK16: =表格1[[#This Row],[Input]]-表格1[[#This Row],[Double check]] -> 0.26
A17: 10 | B17: =IF(表格1[[#This Row],[Full Name.]]=工作表1!F11,"OK") -> OK | C17: Mui Chan_2 | D17: Chan So Mui | E17: Autopay | F17: Diamond Hill_2 Broadway | G17: Mar/21-22 | H17: 2 | I17: 16 | J17: 60 | K17: =表格1[[#This Row],[Reg.Hrs]]*表格1[[#This Row],[$]] -> 960 | L17: 17304 | N17: =IFERROR((IF(表格1[[#This Row],[Name.]]=工作表1!$E11,工作表1!$K11," ")*表格1[[#This Row],[Sales]])," ") -> 346.08 | O17: =IFERROR((IF(表格1[[#This Row],[Full Name.]]=工作表1!F11,工作表1!J11," ")*表格1[[#This Row],[Days]])," ") -> 0 | AF17: 30 | AG17: =SUM(表格1[[#This Row],[Commission (1% OR 2%)]:[Expenses/支出]])+表格1[[#This Row],[Basic]] -> 1336.08 | AH17: =ROUND(AG17,0) -> 1336 | AJ17: 1306.08 | AK17: =表格1[[#This Row],[Input]]-表格1[[#This Row],[Double check]] -> 29.92
A18: 11 | B18: =IF(表格1[[#This Row],[Full Name.]]=工作表1!F12,"OK") -> OK | C18: Shan_1 | D18: Chiu Fung Shan | E18: 20855 | F18: TW_1 Citistore | G18: Mar/1-2,5-10,14-17,20-23 | H18: 16 | I18: 144 | J18: 60 | K18: =表格1[[#This Row],[Reg.Hrs]]*表格1[[#This Row],[$]] -> 8640 | L18: 134544 | N18: =IFERROR((IF(表格1[[#This Row],[Name.]]=工作表1!$E12,工作表1!$K12," ")*表格1[[#This Row],[Sales]])," ") -> 2690.88 | O18: =IFERROR((IF(表格1[[#This Row],[Full Name.]]=工作表1!F12,工作表1!J12," ")*表格1[[#This Row],[Days]])," ") -> 0 | P18: 0 | Q18: 0 | R18: 0 | S18: 0 | T18: 0 | U18: 0 | V18: 0 | W18: 0 | X18: 0 | Y18: 0 | Z18: 0 | AA18: 0 | AB18: 0 | AC18: 0 | AD18: 0 | AE18: 0 | AG18: =SUM(表格1[[#This Row],[Commission (1% OR 2%)]:[Expenses/支出]])+表格1[[#This Row],[Basic]] -> 11330.88 | AH18: =ROUND(AG18,0) -> 11331 | AJ18: 11330.88 | AK18: =表格1[[#This Row],[Input]]-表格1[[#This Row],[Double check]] -> 0.12
A19: 12 | B19: =IF(表格1[[#This Row],[Full Name.]]=工作表1!F13,"OK") -> OK | C19: Wendy Wong_1 | D19: Wong Lai Ying | E19: Autopay | F19: TW_2 Citistore | G19: Mar/3-4,11,13,18-19,24 | H19: 7 | I19: 63 | J19: 60 | K19: =表格1[[#This Row],[Reg.Hrs]]*表格1[[#This Row],[$]] -> 3780 | L19: 28203 | N19: =IFERROR((IF(表格1[[#This Row],[Name.]]=工作表1!$E13,工作表1!$K13," ")*表格1[[#This Row],[Sales]])," ") -> 564.06 | O19: =IFERROR((IF(表格1[[#This Row],[Full Name.]]=工作表1!F13,工作表1!J13," ")*表格1[[#This Row],[Days]])," ") -> 0 | AG19: =SUM(表格1[[#This Row],[Commission (1% OR 2%)]:[Expenses/支出]])+表格1[[#This Row],[Basic]] -> 4344.06 | AH19: =ROUND(AG19,0) -> 4344 | AJ19: 4344.06 | AK19: =表格1[[#This Row],[Input]]-表格1[[#This Row],[Double check]] -> -0.06
A20: 13 | B20: =IF(表格1[[#This Row],[Full Name.]]=工作表1!F14,"OK") -> OK | C20: Mandy | D20: Ho Lai Sim | E20: Autopay | F20: TW_3 Citistore | G20: Mar/12 | H20: 1 | I20: 9 | J20: 60 | K20: =表格1[[#This Row],[Reg.Hrs]]*表格1[[#This Row],[$]] -> 540 | L20: 4664 | N20: =IFERROR((IF(表格1[[#This Row],[Name.]]=工作表1!$E14,工作表1!$K14," ")*表格1[[#This Row],[Sales]])," ") -> 93.28 | O20: =IFERROR((IF(表格1[[#This Row],[Full Name.]]=工作表1!F14,工作表1!J14," ")*表格1[[#This Row],[Days]])," ") -> 0 | AG20: =SUM(表格1[[#This Row],[Commission (1% OR 2%)]:[Expenses/支出]])+表格1[[#This Row],[Basic]] -> 633.28 | AH20: =ROUND(AG20,0) -> 633 | AJ20: 633.28 | AK20: =表格1[[#This Row],[Input]]-表格1[[#This Row],[Double check]] -> -0.28
A21: 14 | B21: =IF(表格1[[#This Row],[Full Name.]]=工作表1!F15,"OK") -> OK | C21: Shan_2 | D21: Chiu Fung Shan | E21: 20856 | F21: TW RS_1 Citistore | G21: Mar/25-31 | H21: 7 | I21: 56 | J21: 60 | K21: =表格1[[#This Row],[Reg.Hrs]]*表格1[[#This Row],[$]] -> 3360 | L21: 151474.6 | N21: =IFERROR((IF(表格1[[#This Row],[Name.]]=工作表1!$E15,工作表1!$K15," ")*表格1[[#This Row],[Sales]])," ") -> 3029.492 | O21: =IFERROR((IF(表格1[[#This Row],[Full Name.]]=工作表1!F15,工作表1!J15," ")*表格1[[#This Row],[Days]])," ") -> 0 | AG21: =SUM(表格1[[#This Row],[Commission (1% OR 2%)]:[Expenses/支出]])+表格1[[#This Row],[Basic]] -> 6389.492 | AH21: =ROUND(AG21,0) -> 6389 | AJ21: 6389.492 | AK21: =表格1[[#This Row],[Input]]-表格1[[#This Row],[Double check]] -> -0.492
A22: 15 | B22: =IF(表格1[[#This Row],[Full Name.]]=工作表1!F16,"OK") -> OK | C22: Wendy Wong_2 | D22: Wong Lai Ying | E22: Autopay | F22: TW RS_2 Citistore | G22: Mar/27-29 | H22: 3 | I22: 24 | J22: 60 | K22: =表格1[[#This Row],[Reg.Hrs]]*表格1[[#This Row],[$]] -> 1440 | L22: 79845 | N22: =IFERROR((IF(表格1[[#This Row],[Name.]]=工作表1!$E16,工作表1!$K16," ")*表格1[[#This Row],[Sales]])," ") -> 798.45 | O22: =IFERROR((IF(表格1[[#This Row],[Full Name.]]=工作表1!F16,工作表1!J16," ")*表格1[[#This Row],[Days]])," ") -> 0 | AG22: =SUM(表格1[[#This Row],[Commission (1% OR 2%)]:[Expenses/支出]])+表格1[[#This Row],[Basic]] -> 2238.45 | AH22: =ROUND(AG22,0) -> 2238 | AJ22: 2238.45 | AK22: =表格1[[#This Row],[Input]]-表格1[[#This Row],[Double check]] -> -0.45
A23: 16 | B23: =IF(表格1[[#This Row],[Full Name.]]=工作表1!F17,"OK") -> OK | C23: Kiko | D23: Chan Mei Sim | E23: Autopay | F23: Tai Koo Fortress | G23: Mar/1-3,7-11,14-18,21-25,28-31 | H23: 22 | I23: 176 | J23: 60 | K23: =表格1[[#This Row],[Reg.Hrs]]*表格1[[#This Row],[$]] -> 10560 | L23: 487590 | N23: =IFERROR((IF(表格1[[#This Row],[Name.]]=工作表1!$E17,工作表1!$K17," ")*表格1[[#This Row],[Sales]])," ") -> 9751.8 | O23: =IFERROR((IF(表格1[[#This Row],[Full Name.]]=工作表1!F17,工作表1!J17," ")*表格1[[#This Row],[Days]])," ") -> 0 | P23: 0 | Q23: 0 | R23: 0 | S23: 0 | T23: 320 | U23: 0 | V23: 0 | W23: 0 | X23: 0 | Y23: 0 | Z23: 0 | AA23: 0 | AB23: 0 | AC23: 0 | AD23: 500 | AE23: 1000 | AG23: =SUM(表格1[[#This Row],[Commission (1% OR 2%)]:[Expenses/支出]])+表格1[[#This Row],[Basic]] -> 22131.8 | AH23: =ROUND(AG23,0) -> 22132 | AJ23: 22131.8 | AK23: =表格1[[#This Row],[Input]]-表格1[[#This Row],[Double check]] -> 0.2
A24: 17 | B24: =IF(表格1[[#This Row],[Full Name.]]=工作表1!F18,"OK") -> OK | C24: Jaco | D24: Ka Kui,Jaco | E24: 20857 | F24: Tung Chun Fortress | G24: Mar/2-5,7-11,14-17,20-25,29-31 | H24: 22 | I24: 170 | J24: 60 | K24: =表格1[[#This Row],[Reg.Hrs]]*表格1[[#This Row],[$]] -> 10200 | L24: 372105 | N24: =IFERROR((IF(表格1[[#This Row],[Name.]]=工作表1!$E18,工作表1!$K18," ")*表格1[[#This Row],[Sales]])," ") -> 7442.1 | O24: =IFERROR((IF(表格1[[#This Row],[Full Name.]]=工作表1!F18,工作表1!J18," ")*表格1[[#This Row],[Days]])," ") -> 0 | P24: 0 | Q24: 0 | R24: 0 | S24: 0 | T24: 160 | U24: 0 | V24: 0 | W24: 0 | X24: 300 | Y24: 0 | Z24: 0 | AA24: 0 | AB24: 0 | AC24: 0 | AD24: 0 | AE24: 0 | AG24: =SUM(表格1[[#This Row],[Commission (1% OR 2%)]:[Expenses/支出]])+表格1[[#This Row],[Basic]] -> 18102.1 | AH24: =ROUND(AG24,0) -> 18102 | AJ24: 18102.1 | AK24: =表格1[[#This Row],[Input]]-表格1[[#This Row],[Double check]] -> -0.1
A25: 18 | B25: =IF(表格1[[#This Row],[Full Name.]]=工作表1!F19,"OK") -> OK | C25: Daisy | D25: Yeung Kwai Lin | E25: Autopay | F25: TM Suning | G25: Mar/1-4,7-10,14-18,20-25,28-31 | H25: 23 | I25: 184 | J25: 60 | K25: =表格1[[#This Row],[Reg.Hrs]]*表格1[[#This Row],[$]] -> 11040 | L25: 335290 | N25: =IFERROR((IF(表格1[[#This Row],[Name.]]=工作表1!$E19,工作表1!$K19," ")*表格1[[#This Row],[Sales]])," ") -> 6705.8 | O25: =IFERROR((IF(表格1[[#This Row],[Full Name.]]=工作表1!F19,工作表1!J19," ")*表格1[[#This Row],[Days]])," ") -> 0 | P25: 0 | Q25: 200 | R25: 0 | S25: 0 | T25: 0 | U25: 0 | V25: 0 | W25: 0 | X25: 0 | Y25: 0 | Z25: 0 | AA25: 200 | AB25: 0 | AC25: 0 | AD25: 0 | AE25: 0 | AG25: =SUM(表格1[[#This Row],[Commission (1% OR 2%)]:[Expenses/支出]])+表格1[[#This Row],[Basic]] -> 18145.8 | AH25: =ROUND(AG25,0) -> 18146 | AJ25: 18145.8 | AK25: =表格1[[#This Row],[Input]]-表格1[[#This Row],[Double check]] -> 0.2
A26: 19 | B26: =IF(表格1[[#This Row],[Full Name.]]=工作表1!F20,"OK") -> OK | C26: Pam | D26: Tam Wing Lam | E26: Autopay | F26: Mos_1 Citistore | G26: Mar/1,3-5,7-10,12-16,18,24-26,28-31 | H26: 21 | I26: 168 | J26: 55 | K26: =表格1[[#This Row],[Reg.Hrs]]*表格1[[#This Row],[$]] -> 9240 | L26: 119202.6 | N26: =IFERROR((IF(表格1[[#This Row],[Name.]]=工作表1!$E20,工作表1!$K20," ")*表格1[[#This Row],[Sales]])," ") -> 2384.052 | O26: =IFERROR((IF(表格1[[#This Row],[Full Name.]]=工作表1!F20,工作表1!J20," ")*表格1[[#This Row],[Days]])," ") -> 0 | P26: 0 | Q26: 0 | R26: 0 | S26: 0 | T26: 0 | U26: 0 | V26: 0 | W26: 0 | X26: 0 | Y26: 0 | Z26: 0 | AA26: 0 | AB26: 0 | AC26: 0 | AD26: 0 | AE26: 0 | AG26: =SUM(表格1[[#This Row],[Commission (1% OR 2%)]:[Expenses/支出]])+表格1[[#This Row],[Basic]] -> 11624.052 | AH26: =ROUND(AG26,0) -> 11624 | AJ26: 11624.052 | AK26: =表格1[[#This Row],[Input]]-表格1[[#This Row],[Double check]] -> -0.052
A27: 20 | B27: =IF(表格1[[#This Row],[Full Name.]]=工作表1!F21,"OK") -> OK | C27: Tony_4 | D27: Wong Tak Chung | E27: Autopay | F27: Mos_2 Citistore | G27: Mar/21-22 | H27: 2 | I27: 16 | J27: 60 | K27: =表格1[[#This Row],[Reg.Hrs]]*表格1[[#This Row],[$]] -> 960 | L27: 17628 | N27: =IFERROR((IF(表格1[[#This Row],[Name.]]=工作表1!$E21,工作表1!$K21," ")*表格1[[#This Row],[Sales]])," ") -> 352.56 | O27: =IFERROR((IF(表格1[[#This Row],[Full Name.]]=工作表1!F21,工作表1!J21," ")*表格1[[#This Row],[Days]])," ") -> 0 | AG27: =SUM(表格1[[#This Row],[Commission (1% OR 2%)]:[Expenses/支出]])+表格1[[#This Row],[Basic]] -> 1312.56 | AH27: =ROUND(AG27,0) -> 1313 | AJ27: 1312.56 | AK27: =表格1[[#This Row],[Input]]-表格1[[#This Row],[Double check]] -> 0.44
A28: 21 | B28: =IF(表格1[[#This Row],[Full Name.]]=工作表1!F22,"OK") -> OK | C28: Lily Hon | D28: Hon Lily | E28: 20858 | F28: TM_1 Aeon | G28: Mar/1-2,4,6,8-9,11,13,22-25,27-29,31 | H28: 16 | I28: 128 | J28: 55 | K28: =表格1[[#This Row],[Reg.Hrs]]*表格1[[#This Row],[$]] -> 7040 | L28: 228635.5 | N28: =IFERROR((IF(表格1[[#This Row],[Name.]]=工作表1!$E22,工作表1!$K22," ")*表格1[[#This Row],[Sales]])," ") -> 4572.71 | O28: =IFERROR((IF(表格1[[#This Row],[Full Name.]]=工作表1!F22,工作表1!J22," ")*表格1[[#This Row],[Days]])," ") -> 480 | P28: 0 | Q28: 0 | R28: 0 | S28: 0 | T28: 0 | U28: 0 | V28: 0 | W28: 0 | X28: 0 | Y28: 0 | Z28: 0 | AA28: 0 | AB28: 0 | AC28: 0 | AD28: 0 | AE28: 0 | AG28: =SUM(表格1[[#This Row],[Commission (1% OR 2%)]:[Expenses/支出]])+表格1[[#This Row],[Basic]] -> 12092.71 | AH28: =ROUND(AG28,0) -> 12093 | AJ28: 12092.71 | AK28: =表格1[[#This Row],[Input]]-表格1[[#This Row],[Double check]] -> 0.29
A29: 22 | B29: =IF(表格1[[#This Row],[Full Name.]]=工作表1!F23,"OK") -> OK | C29: Ho_3 | D29: Kwan Tit Ho | E29: 20859 | F29: TM_2 Aeon | G29: Mar/17-18,26,30 | H29: 4 | I29: 32 | J29: 55 | K29: =表格1[[#This Row],[Reg.Hrs]]*表格1[[#This Row],[$]] -> 1760 | L29: 31095 | N29: =IFERROR((IF(表格1[[#This Row],[Name.]]=工作表1!$E23,工作表1!$K23," ")*表格1[[#This Row],[Sales]])," ") -> 621.9 | O29: =IFERROR((IF(表格1[[#This Row],[Full Name.]]=工作表1!F23,工作表1!J23," ")*表格1[[#This Row],[Days]])," ") -> 0 | AG29: =SUM(表格1[[#This Row],[Commission (1% OR 2%)]:[Expenses/支出]])+表格1[[#This Row],[Basic]] -> 2381.9 | AH29: =ROUND(AG29,0) -> 2382 | AJ29: 2381.9 | AK29: =表格1[[#This Row],[Input]]-表格1[[#This Row],[Double check]] -> 0.1
A30: 23 | B30: =IF(表格1[[#This Row],[Full Name.]]=工作表1!F24,"OK") -> OK | C30: Kandy | D30: Sin Hoi Yam | E30: 20860 | F30: TW Fortress | G30: Mar/1,7-8,21-22,28-29 | H30: 7 | I30: 56 | J30: 55 | K30: =表格1[[#This Row],[Reg.Hrs]]*表格1[[#This Row],[$]] -> 3080 | L30: 165639 | N30: =IFERROR((IF(表格1[[#This Row],[Name.]]=工作表1!$E24,工作表1!$K24," ")*表格1[[#This Row],[Sales]])," ") -> 3312.78 | O30: =IFERROR((IF(表格1[[#This Row],[Full Name.]]=工作表1!F24,工作表1!J24," ")*表格1[[#This Row],[Days]])," ") -> 0 | P30: 0 | Q30: 0 | R30: 0 | S30: 0 | T30: 0 | U30: 0 | V30: 0 | W30: 0 | X30: 0 | Y30: 0 | Z30: 0 | AA30: 0 | AB30: 0 | AC30: 0 | AD30: 0 | AE30: 0 | AG30: =SUM(表格1[[#This Row],[Commission (1% OR 2%)]:[Expenses/支出]])+表格1[[#This Row],[Basic]] -> 6392.78 | AH30: =ROUND(AG30,0) -> 6393 | AJ30: 6392.78 | AK30: =表格1[[#This Row],[Input]]-表格1[[#This Row],[Double check]] -> 0.22
A31: 24 | B31: =IF(表格1[[#This Row],[Full Name.]]=工作表1!F25,"OK") -> OK | C31: Hung | D31: Hui Man Hung | E31: 20861 | F31: TW Suning | G31: Mar/1-4,6-12,14-18,20-25 | H31: 22 | I31: 176 | J31: 60 | K31: =表格1[[#This Row],[Reg.Hrs]]*表格1[[#This Row],[$]] -> 10560 | L31: 0 | N31: =IFERROR((IF(表格1[[#This Row],[Name.]]=工作表1!$E25,工作表1!$K25," ")*表格1[[#This Row],[Sales]])," ") -> 0 | O31: =IFERROR((IF(表格1[[#This Row],[Full Name.]]=工作表1!F25,工作表1!J25," ")*表格1[[#This Row],[Days]])," ") -> 0 | P31: 0 | Q31: 0 | R31: 0 | S31: 0 | T31: 0 | U31: 0 | V31: 0 | W31: 0 | X31: 0 | Y31: 0 | Z31: 0 | AA31: 0 | AB31: 0 | AC31: 0 | AD31: 0 | AE31: 0 | AG31: =SUM(表格1[[#This Row],[Commission (1% OR 2%)]:[Expenses/支出]])+表格1[[#This Row],[Basic]] -> 10560 | AH31: =ROUND(AG31,0) -> 10560 | AJ31: 10560 | AK31: =表格1[[#This Row],[Input]]-表格1[[#This Row],[Double check]] -> 0
A32: 25 | B32: =IF(表格1[[#This Row],[Full Name.]]=工作表1!F26,"OK") -> OK | C32: Leo | D32: Lam King Chung | E32: Autopay | F32: Yoho Suning | G32: Mar/2-3,5,7-10,12-17,19-24,26,29-31 | H32: 23 | I32: 184 | J32: 55 | K32: =表格1[[#This Row],[Reg.Hrs]]*表格1[[#This Row],[$]] -> 10120 | L32: 294578 | N32: =IFERROR((IF(表格1[[#This Row],[Name.]]=工作表1!$E26,工作表1!$K26," ")*表格1[[#This Row],[Sales]])," ") -> 5891.56 | O32: =IFERROR((IF(表格1[[#This Row],[Full Name.]]=工作表1!F26,工作表1!J26," ")*表格1[[#This Row],[Days]])," ") -> 0 | P32: 0 | Q32: 0 | R32: 0 | S32: 0 | T32: 0 | U32: 0 | V32: 0 | W32: 0 | X32: 300 | Y32: 0 | Z32: 0 | AA32: 0 | AB32: 0 | AC32: 0 | AD32: 500 | AE32: 1000 | AG32: =SUM(表格1[[#This Row],[Commission (1% OR 2%)]:[Expenses/支出]])+表格1[[#This Row],[Basic]] -> 17811.56 | AH32: =ROUND(AG32,0) -> 17812 | AJ32: 17811.56 | AK32: =表格1[[#This Row],[Input]]-表格1[[#This Row],[Double check]] -> 0.44
A33: 26 | B33: =IF(表格1[[#This Row],[Full Name.]]=工作表1!F27,"OK") -> OK | C33: Yee | D33: Cheung Yu Wing Yee | E33: 20862 | F33: YL Citistore | G33: Mar/1,5-9,12-16,19-22,26-30 | H33: 20 | I33: 160 | J33: 60 | K33: =表格1[[#This Row],[Reg.Hrs]]*表格1[[#This Row],[$]] -> 9600 | L33: 125760 | N33: =IFERROR((IF(表格1[[#This Row],[Name.]]=工作表1!$E27,工作表1!$K27," ")*表格1[[#This Row],[Sales]])," ") -> 2515.2 | O33: =IFERROR((IF(表格1[[#This Row],[Full Name.]]=工作表1!F27,工作表1!J27," ")*表格1[[#This Row],[Days]])," ") -> 0 | P33: 0 | Q33: 0 | R33: 0 | S33: 0 | T33: 0 | U33: 0 | V33: 0 | W33: 0 | X33: 0 | Y33: 0 | Z33: 0 | AA33: 0 | AB33: 0 | AC33: 0 | AD33: 0 | AE33: 0 | AG33: =SUM(表格1[[#This Row],[Commission (1% OR 2%)]:[Expenses/支出]])+表格1[[#This Row],[Basic]] -> 12115.2 | AH33: =ROUND(AG33,0) -> 12115 | AJ33: 12115.2 | AK33: =表格1[[#This Row],[Input]]-表格1[[#This Row],[Double check]] -> -0.2
A34: 27 | B34: =IF(表格1[[#This Row],[Full Name.]]=工作表1!F28,"OK") -> OK | C34: Ling Ho | D34: Ho Wai Ling | E34: Autopay | F34: TM Citistore | G34: Mar/1,3-4,6-9,11-12,14-17,20-24,26-31 | H34: 24 | I34: 192 | J34: 60 | K34: =表格1[[#This Row],[Reg.Hrs]]*表格1[[#This Row],[$]] -> 11520 | L34: 153807.4 | N34: =IFERROR((IF(表格1[[#This Row],[Name.]]=工作表1!$E28,工作表1!$K28," ")*表格1[[#This Row],[Sales]])," ") -> 3076.148 | O34: =IFERROR((IF(表格1[[#This Row],[Full Name.]]=工作表1!F28,工作表1!J28," ")*表格1[[#This Row],[Days]])," ") -> 0 | P34: 0 | Q34: 0 | R34: 0 | S34: 0 | T34: 0 | U34: 0 | V34: 0 | W34: 0 | X34: 0 | Y34: 0 | Z34: 0 | AA34: 0 | AB34: 0 | AC34: 0 | AD34: 0 | AE34: 0 | AG34: =SUM(表格1[[#This Row],[Commission (1% OR 2%)]:[Expenses/支出]])+表格1[[#This Row],[Basic]] -> 14596.148 | AH34: =ROUND(AG34,0) -> 14596 | AJ34: 14596.148 | AK34: =表格1[[#This Row],[Input]]-表格1[[#This Row],[Double check]] -> -0.148
A35: 28 | B35: =IF(表格1[[#This Row],[Full Name.]]=工作表1!F29,"OK") -> OK | C35: Happy | D35: Chun Yin Ling | E35: 20863 | F35: APM Broadway | G35: Mar/1,3-5,7-9,11-12,15-16,19-22,25-31 | H35: 22 | I35: 176 | J35: 60 | K35: =表格1[[#This Row],[Reg.Hrs]]*表格1[[#This Row],[$]] -> 10560 | L35: 470313 | N35: =IFERROR((IF(表格1[[#This Row],[Name.]]=工作表1!$E29,工作表1!$K29," ")*表格1[[#This Row],[Sales]])," ") -> 9406.26 | O35: =IFERROR((IF(表格1[[#This Row],[Full Name.]]=工作表1!F29,工作表1!J29," ")*表格1[[#This Row],[Days]])," ") -> 0 | P35: 0 | Q35: 0 | R35: 0 | S35: 0 | T35: 160 | U35: 0 | V35: 400 | W35: 0 | X35: 0 | Y35: 200 | Z35: 0 | AA35: 0 | AB35: 2450 | AC35: 0 | AD35: 500 | AE35: 1000 | AG35: =SUM(表格1[[#This Row],[Commission (1% OR 2%)]:[Expenses/支出]])+表格1[[#This Row],[Basic]] -> 24676.26 | AH35: =ROUND(AG35,0) -> 24676 | AJ35: 24676.26 | AK35: =表格1[[#This Row],[Input]]-表格1[[#This Row],[Double check]] -> -0.26
A36: 29 | B36: =IF(表格1[[#This Row],[Full Name.]]=工作表1!F30,"OK") -> OK | C36: Tiffany | D36: Man Wai Han | E36: Autopay | F36: APM Fortress | G36: Mar/1,5-6,8-9,11-12,14,16,19-22,24-26,29,31 | H36: 18 | I36: 144 | J36: 60 | K36: =表格1[[#This Row],[Reg.Hrs]]*表格1[[#This Row],[$]] -> 8640 | L36: 376482 | N36: =IFERROR((IF(表格1[[#This Row],[Name.]]=工作表1!$E30,工作表1!$K30," ")*表格1[[#This Row],[Sales]])," ") -> 7529.64 | O36: 6653.48 | P36: 0 | Q36: 0 | R36: 0 | S36: 0 | T36: 160 | U36: 0 | V36: 0 | W36: 0 | X36: 0 | Y36: 0 | Z36: 0 | AA36: 0 | AB36: 0 | AC36: 0 | AD36: 0 | AE36: 0 | AG36: =SUM(表格1[[#This Row],[Commission (1% OR 2%)]:[Expenses/支出]])+表格1[[#This Row],[Basic]] -> 22983.12 | AH36: =ROUND(AG36,0) -> 22983 | AJ36: 16329.64 | AK36: =表格1[[#This Row],[Input]]-表格1[[#This Row],[Double check]] -> 6653.36
A37: 30 | B37: =IF(表格1[[#This Row],[Full Name.]]=工作表1!F31,"OK") -> OK | C37: Coco | D37: Yuen Lai Ying | E37: 20864 | F37: TKO Suning | G37: Mar/1,3-5,7-8,11-12,14-15,17-19,24-26,28-31 | H37: 20 | I37: 160 | J37: 60 | K37: =表格1[[#This Row],[Reg.Hrs]]*表格1[[#This Row],[$]] -> 9600 | L37: 229262 | N37: =IFERROR((IF(表格1[[#This Row],[Name.]]=工作表1!$E31,工作表1!$K31," ")*表格1[[#This Row],[Sales]])," ") -> 4585.24 | O37: =IFERROR((IF(表格1[[#This Row],[Full Name.]]=工作表1!F31,工作表1!J31," ")*表格1[[#This Row],[Days]])," ") -> 0 | P37: 0 | Q37: 0 | R37: 0 | S37: 0 | T37: 0 | U37: 0 | V37: 0 | W37: 0 | X37: 0 | Y37: 0 | Z37: 0 | AA37: 0 | AB37: 0 | AC37: 0 | AD37: 0 | AE37: 0 | AG37: =SUM(表格1[[#This Row],[Commission (1% OR 2%)]:[Expenses/支出]])+表格1[[#This Row],[Basic]] -> 14185.24 | AH37: =ROUND(AG37,0) -> 14185 | AJ37: 14185.24 | AK37: =表格1[[#This Row],[Input]]-表格1[[#This Row],[Double check]] -> -0.24
A38: 31 | B38: =IF(表格1[[#This Row],[Full Name.]]=工作表1!F32,"OK") -> OK | C38: Raymond | D38: Kwok Chun Wah | E38: 20865 | F38: Times Fortress | G38: Mar/1-5,7,9-12,15-18,21-26,28-31 | H38: 24 | I38: 192 | J38: 60 | K38: =表格1[[#This Row],[Reg.Hrs]]*表格1[[#This Row],[$]] -> 11520 | L38: 360494 | N38: =IFERROR((IF(表格1[[#This Row],[Name.]]=工作表1!$E32,工作表1!$K32," ")*表格1[[#This Row],[Sales]])," ") -> 7209.88 | O38: =IFERROR((IF(表格1[[#This Row],[Full Name.]]=工作表1!F32,工作表1!J32," ")*表格1[[#This Row],[Days]])," ") -> 0 | P38: 0 | Q38: 0 | R38: 0 | S38: 0 | T38: 0 | U38: 0 | V38: 0 | W38: 0 | X38: 0 | Y38: 0 | Z38: 0 | AA38: 0 | AB38: 0 | AC38: 0 | AD38: 0 | AE38: 0 | AG38: =SUM(表格1[[#This Row],[Commission (1% OR 2%)]:[Expenses/支出]])+表格1[[#This Row],[Basic]] -> 18729.88 | AH38: =ROUND(AG38,0) -> 18730 | AJ38: 18729.88 | AK38: =表格1[[#This Row],[Input]]-表格1[[#This Row],[Double check]] -> 0.12
A39: 32 | B39: =IF(表格1[[#This Row],[Full Name.]]=工作表1!F33,"OK") -> OK | C39: Maggie Yip | D39: Yip Mei King | E39: 20866 | F39: Shatin_1 Yata | G39: Mar/1-2,5-10,14-17,20-24,27-31 | H39: 22 | I39: 176 | J39: 60 | K39: =表格1[[#This Row],[Reg.Hrs]]*表格1[[#This Row],[$]] -> 10560 | L39: 123292 | N39: =IFERROR((IF(表格1[[#This Row],[Name.]]=工作表1!$E33,工作表1!$K33," ")*表格1[[#This Row],[Sales]])," ") -> 2465.84 | O39: =IFERROR((IF(表格1[[#This Row],[Full Name.]]=工作表1!F33,工作表1!J33," ")*表格1[[#This Row],[Days]])," ") -> 0 | P39: 0 | Q39: 0 | R39: 0 | S39: 0 | T39: 0 | U39: 0 | V39: 0 | W39: 0 | X39: 0 | Y39: 0 | Z39: 0 | AA39: 0 | AB39: 0 | AC39: 0 | AD39: 0 | AE39: 0 | AG39: =SUM(表格1[[#This Row],[Commission (1% OR 2%)]:[Expenses/支出]])+表格1[[#This Row],[Basic]] -> 13025.84 | AH39: =ROUND(AG39,0) -> 13026 | AJ39: 13025.84 | AK39: =表格1[[#This Row],[Input]]-表格1[[#This Row],[Double check]] -> 0.16
A40: 33 | B40: =IF(表格1[[#This Row],[Full Name.]]=工作表1!F34,"OK") -> OK | C40: Emma | D40: Ng Yuk Ying | E40: Autopay | F40: Shatin_2 Yata | G40: Mar/3-4,18-19 | H40: 4 | I40: 32 | J40: 60 | K40: =表格1[[#This Row],[Reg.Hrs]]*表格1[[#This Row],[$]] -> 1920 | L40: 15785 | N40: =IFERROR((IF(表格1[[#This Row],[Name.]]=工作表1!$E34,工作表1!$K34," ")*表格1[[#This Row],[Sales]])," ") -> 315.7 | O40: =IFERROR((IF(表格1[[#This Row],[Full Name.]]=工作表1!F34,工作表1!J34," ")*表格1[[#This Row],[Days]])," ") -> 0 | AF40: 45 | AG40: =SUM(表格1[[#This Row],[Commission (1% OR 2%)]:[Expenses/支出]])+表格1[[#This Row],[Basic]] -> 2280.7 | AH40: =ROUND(AG40,0) -> 2281 | AJ40: 2235.7 | AK40: =表格1[[#This Row],[Input]]-表格1[[#This Row],[Double check]] -> 45.3
...

Sheet 工作表1
A1: Name | B1: Full Name | E1: Name1 | F1: Full Name1 | G1: Shop | H1: No | I1: $$$ | J1: Allowance | K1: % | L1: "Total" No. | M1: 欄2 | N1: 欄3
A2: Amy Or | B2: Or Sim Kiu | E2: May C | F2: Cheng Muk Kiu | G2: Kornhill Aeon | H2: 1 | I2: 55 | J2: 30 | K2: 0.02 | L2: {=_xlfn._xlws.FILTER(表格1[No.],(表格1[Name.]=表格4[[#This Row],[Name1]])+(表格1[Name.]&"_1"=表格4[[#This Row],[Name1]])+(表格1[Name.]&"_2"=表格4[[#This Row],[Name1]])+(表格1[Name.]&"_3"=表格4[[#This Row],[Name1]])+(表格1[Name.]&"_4"=表格4[[#This Row],[Name1]])+(表格1[Name.]&"_5"=表格4[[#This Row],[Name1]]))} -> 1 | M2: =IF(表格4[[#This Row],["Total" No.]]=表格4[[#This Row],[No]],表格4[[#This Row],[No]],"F") -> 1 | N2: =COUNTIF(表格1[No.],表格4[[#This Row],["Total" No.]]) -> 1
A3: Anita | B3: Chan Siu Kuen | E3: Ivy Wong_1 | F3: Wong Wai Chu | G3: Vcity_1 Fortress | H3: 2 | I3: 60 | J3: 0 | K3: 0.02 | L3: {=_xlfn._xlws.FILTER(表格1[No.],(表格1[Name.]=表格4[[#This Row],[Name1]])+(表格1[Name.]&"_1"=表格4[[#This Row],[Name1]])+(表格1[Name.]&"_2"=表格4[[#This Row],[Name1]])+(表格1[Name.]&"_3"=表格4[[#This Row],[Name1]])+(表格1[Name.]&"_4"=表格4[[#This Row],[Name1]])+(表格1[Name.]&"_5"=表格4[[#This Row],[Name1]]))} -> 2 | M3: =IF(表格4[[#This Row],["Total" No.]]=表格4[[#This Row],[No]],表格4[[#This Row],[No]],"F") -> 2 | N3: =COUNTIF(表格1[No.],表格4[[#This Row],["Total" No.]]) -> 1
A4: Cindy | B4: Ng Mei Han | E4: Kit_3 | F4: Li Wenjie | G4: Vcity_2 Fortress | H4: 3 | I4: 60 | K4: 0.02 | L4: {=_xlfn._xlws.FILTER(表格1[No.],(表格1[Name.]=表格4[[#This Row],[Name1]])+(表格1[Name.]&"_1"=表格4[[#This Row],[Name1]])+(表格1[Name.]&"_2"=表格4[[#This Row],[Name1]])+(表格1[Name.]&"_3"=表格4[[#This Row],[Name1]])+(表格1[Name.]&"_4"=表格4[[#This Row],[Name1]])+(表格1[Name.]&"_5"=表格4[[#This Row],[Name1]]))} -> 3 | M4: =IF(表格4[[#This Row],["Total" No.]]=表格4[[#This Row],[No]],表格4[[#This Row],[No]],"F") -> 3 | N4: =COUNTIF(表格1[No.],表格4[[#This Row],["Total" No.]]) -> 1
A5: Coco | B5: Yuen Lai Ying | E5: Vicky L | F5: Leung Ching | G5: Diamond Hill Fortress | H5: 4 | I5: 60 | J5: 0 | K5: 0.02 | L5: {=_xlfn._xlws.FILTER(表格1[No.],(表格1[Name.]=表格4[[#This Row],[Name1]])+(表格1[Name.]&"_1"=表格4[[#This Row],[Name1]])+(表格1[Name.]&"_2"=表格4[[#This Row],[Name1]])+(表格1[Name.]&"_3"=表格4[[#This Row],[Name1]])+(表格1[Name.]&"_4"=表格4[[#This Row],[Name1]])+(表格1[Name.]&"_5"=表格4[[#This Row],[Name1]]))} -> 4 | M5: =IF(表格4[[#This Row],["Total" No.]]=表格4[[#This Row],[No]],表格4[[#This Row],[No]],"F") -> 4 | N5: =COUNTIF(表格1[No.],表格4[[#This Row],["Total" No.]]) -> 1
A6: Connie | B6: Chan Siu Mui | E6: Michelle | F6: Lo Muk Chun | G6: Good Hope Fortress | H6: 5 | I6: 60 | J6: 0 | K6: 0.02 | L6: {=_xlfn._xlws.FILTER(表格1[No.],(表格1[Name.]=表格4[[#This Row],[Name1]])+(表格1[Name.]&"_1"=表格4[[#This Row],[Name1]])+(表格1[Name.]&"_2"=表格4[[#This Row],[Name1]])+(表格1[Name.]&"_3"=表格4[[#This Row],[Name1]])+(表格1[Name.]&"_4"=表格4[[#This Row],[Name1]])+(表格1[Name.]&"_5"=表格4[[#This Row],[Name1]]))} -> 5 | M6: =IF(表格4[[#This Row],["Total" No.]]=表格4[[#This Row],[No]],表格4[[#This Row],[No]],"F") -> 5 | N6: =COUNTIF(表格1[No.],表格4[[#This Row],["Total" No.]]) -> 1
A7: Daisy | B7: Yeung Kwai Lin | E7: Jessica | F7: Chiu Kan | G7: Whampoa Aeon | H7: 6 | I7: 55 | J7: 80 | K7: 0.02 | L7: {=_xlfn._xlws.FILTER(表格1[No.],(表格1[Name.]=表格4[[#This Row],[Name1]])+(表格1[Name.]&"_1"=表格4[[#This Row],[Name1]])+(表格1[Name.]&"_2"=表格4[[#This Row],[Name1]])+(表格1[Name.]&"_3"=表格4[[#This Row],[Name1]])+(表格1[Name.]&"_4"=表格4[[#This Row],[Name1]])+(表格1[Name.]&"_5"=表格4[[#This Row],[Name1]]))} -> 6 | M7: =IF(表格4[[#This Row],["Total" No.]]=表格4[[#This Row],[No]],表格4[[#This Row],[No]],"F") -> 6 | N7: =COUNTIF(表格1[No.],表格4[[#This Row],["Total" No.]]) -> 1
A8: Donnie | B8: Chau Chi Wah | E8: Kitty Yeung | F8: Yeung Lai Shan | G8: TKW Suning | H8: 7 | I8: 60 | J8: 0 | K8: 0.02 | L8: {=_xlfn._xlws.FILTER(表格1[No.],(表格1[Name.]=表格4[[#This Row],[Name1]])+(表格1[Name.]&"_1"=表格4[[#This Row],[Name1]])+(表格1[Name.]&"_2"=表格4[[#This Row],[Name1]])+(表格1[Name.]&"_3"=表格4[[#This Row],[Name1]])+(表格1[Name.]&"_4"=表格4[[#This Row],[Name1]])+(表格1[Name.]&"_5"=表格4[[#This Row],[Name1]]))} -> 7 | M8: =IF(表格4[[#This Row],["Total" No.]]=表格4[[#This Row],[No]],表格4[[#This Row],[No]],"F") -> 7 | N8: =COUNTIF(表格1[No.],表格4[[#This Row],["Total" No.]]) -> 1
A9: Emma | B9: Ng Yuk Ying | E9: Amy Or_1 | F9: Or Sim Kiu | G9: Tai koo Broadway | H9: 8 | I9: 55 | J9: 30 | K9: 0.02 | L9: {=_xlfn._xlws.FILTER(表格1[No.],(表格1[Name.]=表格4[[#This Row],[Name1]])+(表格1[Name.]&"_1"=表格4[[#This Row],[Name1]])+(表格1[Name.]&"_2"=表格4[[#This Row],[Name1]])+(表格1[Name.]&"_3"=表格4[[#This Row],[Name1]])+(表格1[Name.]&"_4"=表格4[[#This Row],[Name1]])+(表格1[Name.]&"_5"=表格4[[#This Row],[Name1]]))} -> 8 | M9: =IF(表格4[[#This Row],["Total" No.]]=表格4[[#This Row],[No]],表格4[[#This Row],[No]],"F") -> 8 | N9: =COUNTIF(表格1[No.],表格4[[#This Row],["Total" No.]]) -> 1
A10: Fong | B10: Ng Nga Fong | E10: Fong_1 | F10: Ng Nga Fong | G10: Diamond Hill_1 Broadway | H10: 9 | I10: 60 | J10: 0 | K10: 0.02 | L10: {=_xlfn._xlws.FILTER(表格1[No.],(表格1[Name.]=表格4[[#This Row],[Name1]])+(表格1[Name.]&"_1"=表格4[[#This Row],[Name1]])+(表格1[Name.]&"_2"=表格4[[#This Row],[Name1]])+(表格1[Name.]&"_3"=表格4[[#This Row],[Name1]])+(表格1[Name.]&"_4"=表格4[[#This Row],[Name1]])+(表格1[Name.]&"_5"=表格4[[#This Row],[Name1]]))} -> 9 | M10: =IF(表格4[[#This Row],["Total" No.]]=表格4[[#This Row],[No]],表格4[[#This Row],[No]],"F") -> 9 | N10: =COUNTIF(表格1[No.],表格4[[#This Row],["Total" No.]]) -> 1
A11: Gloria | B11: Yeung Chor Mui | E11: Mui Chan_2 | F11: Chan So Mui | G11: Diamond Hill_2 Broadway | H11: 10 | I11: 60 | J11: 0 | K11: 0.02 | L11: {=_xlfn._xlws.FILTER(表格1[No.],(表格1[Name.]=表格4[[#This Row],[Name1]])+(表格1[Name.]&"_1"=表格4[[#This Row],[Name1]])+(表格1[Name.]&"_2"=表格4[[#This Row],[Name1]])+(表格1[Name.]&"_3"=表格4[[#This Row],[Name1]])+(表格1[Name.]&"_4"=表格4[[#This Row],[Name1]])+(表格1[Name.]&"_5"=表格4[[#This Row],[Name1]]))} -> 10 | M11: =IF(表格4[[#This Row],["Total" No.]]=表格4[[#This Row],[No]],表格4[[#This Row],[No]],"F") -> 10 | N11: =COUNTIF(表格1[No.],表格4[[#This Row],["Total" No.]]) -> 1
A12: Grace | B12: Mok Choi Lin | E12: Shan_1 | F12: Chiu Fung Shan | G12: TW_1 Citistore | H12: 11 | I12: 60 | J12: 0 | K12: 0.02 | L12: {=_xlfn._xlws.FILTER(表格1[No.],(表格1[Name.]=表格4[[#This Row],[Name1]])+(表格1[Name.]&"_1"=表格4[[#This Row],[Name1]])+(表格1[Name.]&"_2"=表格4[[#This Row],[Name1]])+(表格1[Name.]&"_3"=表格4[[#This Row],[Name1]])+(表格1[Name.]&"_4"=表格4[[#This Row],[Name1]])+(表格1[Name.]&"_5"=表格4[[#This Row],[Name1]]))} -> 11 | M12: =IF(表格4[[#This Row],["Total" No.]]=表格4[[#This Row],[No]],表格4[[#This Row],[No]],"F") -> 11 | N12: =COUNTIF(表格1[No.],表格4[[#This Row],["Total" No.]]) -> 1
A13: Happy | B13: Chun Yin Ling | E13: Wendy Wong_1 | F13: Wong Lai Ying | G13: TW_2 Citistore | H13: 12 | I13: 60 | J13: 0 | K13: 0.02 | L13: {=_xlfn._xlws.FILTER(表格1[No.],(表格1[Name.]=表格4[[#This Row],[Name1]])+(表格1[Name.]&"_1"=表格4[[#This Row],[Name1]])+(表格1[Name.]&"_2"=表格4[[#This Row],[Name1]])+(表格1[Name.]&"_3"=表格4[[#This Row],[Name1]])+(表格1[Name.]&"_4"=表格4[[#This Row],[Name1]])+(表格1[Name.]&"_5"=表格4[[#This Row],[Name1]]))} -> 12 | M13: =IF(表格4[[#This Row],["Total" No.]]=表格4[[#This Row],[No]],表格4[[#This Row],[No]],"F") -> 12 | N13: =COUNTIF(表格1[No.],表格4[[#This Row],["Total" No.]]) -> 1
A14: Ho | B14: Kwan Tit Ho | E14: Mandy | F14: Ho Lai Sim | G14: TW_3 Citistore | H14: 13 | I14: 60 | J14: 0 | K14: 0.02 | L14: {=_xlfn._xlws.FILTER(表格1[No.],(表格1[Name.]=表格4[[#This Row],[Name1]])+(表格1[Name.]&"_1"=表格4[[#This Row],[Name1]])+(表格1[Name.]&"_2"=表格4[[#This Row],[Name1]])+(表格1[Name.]&"_3"=表格4[[#This Row],[Name1]])+(表格1[Name.]&"_4"=表格4[[#This Row],[Name1]])+(表格1[Name.]&"_5"=表格4[[#This Row],[Name1]]))} -> 13 | M14: =IF(表格4[[#This Row],["Total" No.]]=表格4[[#This Row],[No]],表格4[[#This Row],[No]],"F") -> 13 | N14: =COUNTIF(表格1[No.],表格4[[#This Row],["Total" No.]]) -> 1
A15: Hung | B15: Hui Man Hung | E15: Shan_2 | F15: Chiu Fung Shan | G15: TW RS_1 Citistore | H15: 14 | I15: 60 | J15: 0 | K15: 0.02 | L15: {=_xlfn._xlws.FILTER(表格1[No.],(表格1[Name.]=表格4[[#This Row],[Name1]])+(表格1[Name.]&"_1"=表格4[[#This Row],[Name1]])+(表格1[Name.]&"_2"=表格4[[#This Row],[Name1]])+(表格1[Name.]&"_3"=表格4[[#This Row],[Name1]])+(表格1[Name.]&"_4"=表格4[[#This Row],[Name1]])+(表格1[Name.]&"_5"=表格4[[#This Row],[Name1]]))} -> 14 | M15: =IF(表格4[[#This Row],["Total" No.]]=表格4[[#This Row],[No]],表格4[[#This Row],[No]],"F") -> 14 | N15: =COUNTIF(表格1[No.],表格4[[#This Row],["Total" No.]]) -> 1
A16: Iris | B16: Li Hang Yi | E16: Wendy Wong_2 | F16: Wong Lai Ying | G16: TW RS_2 Citistore | H16: 15 | I16: 60 | J16: 0 | K16: 0.01 | L16: {=_xlfn._xlws.FILTER(表格1[No.],(表格1[Name.]=表格4[[#This Row],[Name1]])+(表格1[Name.]&"_1"=表格4[[#This Row],[Name1]])+(表格1[Name.]&"_2"=表格4[[#This Row],[Name1]])+(表格1[Name.]&"_3"=表格4[[#This Row],[Name1]])+(表格1[Name.]&"_4"=表格4[[#This Row],[Name1]])+(表格1[Name.]&"_5"=表格4[[#This Row],[Name1]]))} -> 15 | M16: =IF(表格4[[#This Row],["Total" No.]]=表格4[[#This Row],[No]],表格4[[#This Row],[No]],"F") -> 15 | N16: =COUNTIF(表格1[No.],表格4[[#This Row],["Total" No.]]) -> 1
... A55: Pinky | B55: Cheung Yin Ping | E55: Ho_2 | F55: Kwan Tit Ho | G55: TC RS Tung Yuen | H55: 54 | I55: 60 | J55: 0 | K55: 0.02 | L55: {=_xlfn._xlws.FILTER(表格1[No.],(表格1[Name.]=表格4[[#This Row],[Name1]])+(表格1[Name.]&"_1"=表格4[[#This Row],[Name1]])+(表格1[Name.]&"_2"=表格4[[#This Row],[Name1]])+(表格1[Name.]&"_3"=表格4[[#This Row],[Name1]])+(表格1[Name.]&"_4"=表格4[[#This Row],[Name1]])+(表格1[Name.]&"_5"=表格4[[#This Row],[Name1]]))} -> 54 | M55: =IF(表格4[[#This Row],["Total" No.]]=表格4[[#This Row],[No]],表格4[[#This Row],[No]],"F") -> 54 | N55: =COUNTIF(表格1[No.],表格4[[#This Row],["Total" No.]]) -> 1
E56: Terence_2 | F56: Tsang Tak Kin | G56: TM RS Fortress | H56: 55 | I56: 60 | J56: 0 | K56: 0.01 | L56: {=_xlfn._xlws.FILTER(表格1[No.],(表格1[Name.]=表格4[[#This Row],[Name1]])+(表格1[Name.]&"_1"=表格4[[#This Row],[Name1]])+(表格1[Name.]&"_2"=表格4[[#This Row],[Name1]])+(表格1[Name.]&"_3"=表格4[[#This Row],[Name1]])+(表格1[Name.]&"_4"=表格4[[#This Row],[Name1]])+(表格1[Name.]&"_5"=表格4[[#This Row],[Name1]]))} -> 55 | M56: =IF(表格4[[#This Row],["Total" No.]]=表格4[[#This Row],[No]],表格4[[#This Row],[No]],"F") -> 55 | N56: =COUNTIF(表格1[No.],表格4[[#This Row],["Total" No.]]) -> 1
E57: Ho_1 | F57: Kwan Tit Ho | G57: Tsuen Wan Aeon | H57: 56 | I57: 60 | J57: 0 | K57: 0.02 | L57: {=_xlfn._xlws.FILTER(表格1[No.],(表格1[Name.]=表格4[[#This Row],[Name1]])+(表格1[Name.]&"_1"=表格4[[#This Row],[Name1]])+(表格1[Name.]&"_2"=表格4[[#This Row],[Name1]])+(表格1[Name.]&"_3"=表格4[[#This Row],[Name1]])+(表格1[Name.]&"_4"=表格4[[#This Row],[Name1]])+(表格1[Name.]&"_5"=表格4[[#This Row],[Name1]]))} -> 56 | M57: =IF(表格4[[#This Row],["Total" No.]]=表格4[[#This Row],[No]],表格4[[#This Row],[No]],"F") -> 56 | N57: =COUNTIF(表格1[No.],表格4[[#This Row],["Total" No.]]) -> 1
E58: Winnie | F58: Lee Yee Wan | G58: Panda Aeon | H58: 57 | I58: 60 | J58: 0 | K58: 0.02 | L58: {=_xlfn._xlws.FILTER(表格1[No.],(表格1[Name.]=表格4[[#This Row],[Name1]])+(表格1[Name.]&"_1"=表格4[[#This Row],[Name1]])+(表格1[Name.]&"_2"=表格4[[#This Row],[Name1]])+(表格1[Name.]&"_3"=表格4[[#This Row],[Name1]])+(表格1[Name.]&"_4"=表格4[[#This Row],[Name1]])+(表格1[Name.]&"_5"=表格4[[#This Row],[Name1]]))} -> 57 | M58: =IF(表格4[[#This Row],["Total" No.]]=表格4[[#This Row],[No]],表格4[[#This Row],[No]],"F") -> 57 | N58: =COUNTIF(表格1[No.],表格4[[#This Row],["Total" No.]]) -> 1
E59: Wendy Lau | F59: Lau Kwan Wai | G59: LCK Aeon | H59: 58 | I59: 60 | J59: 0 | K59: 0.02 | L59: {=_xlfn._xlws.FILTER(表格1[No.],(表格1[Name.]=表格4[[#This Row],[Name1]])+(表格1[Name.]&"_1"=表格4[[#This Row],[Name1]])+(表格1[Name.]&"_2"=表格4[[#This Row],[Name1]])+(表格1[Name.]&"_3"=表格4[[#This Row],[Name1]])+(表格1[Name.]&"_4"=表格4[[#This Row],[Name1]])+(表格1[Name.]&"_5"=表格4[[#This Row],[Name1]]))} -> 58 | M59: =IF(表格4[[#This Row],["Total" No.]]=表格4[[#This Row],[No]],表格4[[#This Row],[No]],"F") -> 58 | N59: =COUNTIF(表格1[No.],表格4[[#This Row],["Total" No.]]) -> 1
E60: Me | F60: Ngai Kong Ying | G60: Megabox Aeon | H60: 59 | I60: 60 | J60: 0 | K60: 0.02 | L60: {=_xlfn._xlws.FILTER(表格1[No.],(表格1[Name.]=表格4[[#This Row],[Name1]])+(表格1[Name.]&"_1"=表格4[[#This Row],[Name1]])+(表格1[Name.]&"_2"=表格4[[#This Row],[Name1]])+(表格1[Name.]&"_3"=表格4[[#This Row],[Name1]])+(表格1[Name.]&"_4"=表格4[[#This Row],[Name1]])+(表格1[Name.]&"_5"=表格4[[#This Row],[Name1]]))} -> 59 | M60: =IF(表格4[[#This Row],["Total" No.]]=表格4[[#This Row],[No]],表格4[[#This Row],[No]],"F") -> 59 | N60: =COUNTIF(表格1[No.],表格4[[#This Row],["Total" No.]]) -> 1
E61: Pinky | F61: Cheung Yin Ping | G61: Yau Tong Aeon | H61: 60 | I61: 60 | J61: 0 | K61: 0.02 | L61: {=_xlfn._xlws.FILTER(表格1[No.],(表格1[Name.]=表格4[[#This Row],[Name1]])+(表格1[Name.]&"_1"=表格4[[#This Row],[Name1]])+(表格1[Name.]&"_2"=表格4[[#This Row],[Name1]])+(表格1[Name.]&"_3"=表格4[[#This Row],[Name1]])+(表格1[Name.]&"_4"=表格4[[#This Row],[Name1]])+(表格1[Name.]&"_5"=表格4[[#This Row],[Name1]]))} -> 60 | M61: =IF(表格4[[#This Row],["Total" No.]]=表格4[[#This Row],[No]],表格4[[#This Row],[No]],"F") -> 60 | N61: =COUNTIF(表格1[No.],表格4[[#This Row],["Total" No.]]) -> 1
E62: Maggie Ho_1 | F62: Ho Lai Kuen | G62: TKO Aeon | H62: 61 | I62: 65 | J62: 0 | K62: 0.02 | L62: {=_xlfn._xlws.FILTER(表格1[No.],(表格1[Name.]=表格4[[#This Row],[Name1]])+(表格1[Name.]&"_1"=表格4[[#This Row],[Name1]])+(表格1[Name.]&"_2"=表格4[[#This Row],[Name1]])+(表格1[Name.]&"_3"=表格4[[#This Row],[Name1]])+(表格1[Name.]&"_4"=表格4[[#This Row],[Name1]])+(表格1[Name.]&"_5"=表格4[[#This Row],[Name1]]))} -> 61 | M62: =IF(表格4[[#This Row],["Total" No.]]=表格4[[#This Row],[No]],表格4[[#This Row],[No]],"F") -> 61 | N62: =COUNTIF(表格1[No.],表格4[[#This Row],["Total" No.]]) -> 1
E63: Eddy | F63: Chan Chi Tim | G63: Training_1 | H63: 62 | I63: 50 | J63: 0 | L63: {=_xlfn._xlws.FILTER(表格1[No.],(表格1[Name.]=表格4[[#This Row],[Name1]])+(表格1[Name.]&"_1"=表格4[[#This Row],[Name1]])+(表格1[Name.]&"_2"=表格4[[#This Row],[Name1]])+(表格1[Name.]&"_3"=表格4[[#This Row],[Name1]])+(表格1[Name.]&"_4"=表格4[[#This Row],[Name1]])+(表格1[Name.]&"_5"=表格4[[#This Row],[Name1]]))} -> 62 | M63: =IF(表格4[[#This Row],["Total" No.]]=表格4[[#This Row],[No]],表格4[[#This Row],[No]],"F") -> 62 | N63: =COUNTIF(表格1[No.],表格4[[#This Row],["Total" No.]]) -> 1
E64: Jenny | F64: Pang Kam Chun | G64: Training_2 | H64: 63 | I64: 50 | J64: 0 | L64: {=_xlfn._xlws.FILTER(表格1[No.],(表格1[Name.]=表格4[[#This Row],[Name1]])+(表格1[Name.]&"_1"=表格4[[#This Row],[Name1]])+(表格1[Name.]&"_2"=表格4[[#This Row],[Name1]])+(表格1[Name.]&"_3"=表格4[[#This Row],[Name1]])+(表格1[Name.]&"_4"=表格4[[#This Row],[Name1]])+(表格1[Name.]&"_5"=表格4[[#This Row],[Name1]]))} -> 63 | M64: =IF(表格4[[#This Row],["Total" No.]]=表格4[[#This Row],[No]],表格4[[#This Row],[No]],"F") -> 63 | N64: =COUNTIF(表格1[No.],表格4[[#This Row],["Total" No.]]) -> 1
E65: WanWah | F65: Chan Wan Wah | G65: Training_3 | H65: 64 | I65: 50 | J65: 0 | L65: {=_xlfn._xlws.FILTER(表格1[No.],(表格1[Name.]=表格4[[#This Row],[Name1]])+(表格1[Name.]&"_1"=表格4[[#This Row],[Name1]])+(表格1[Name.]&"_2"=表格4[[#This Row],[Name1]])+(表格1[Name.]&"_3"=表格4[[#This Row],[Name1]])+(表格1[Name.]&"_4"=表格4[[#This Row],[Name1]])+(表格1[Name.]&"_5"=表格4[[#This Row],[Name1]]))} -> 64 | M65: =IF(表格4[[#This Row],["Total" No.]]=表格4[[#This Row],[No]],表格4[[#This Row],[No]],"F") -> 64 | N65: =COUNTIF(表格1[No.],表格4[[#This Row],["Total" No.]]) -> 1
L66: {=_xlfn._xlws.FILTER(表格1[No.],(表格1[Name.]=表格4[[#This Row],[Name1]])+(表格1[Name.]&"_1"=表格4[[#This Row],[Name1]])+(表格1[Name.]&"_2"=表格4[[#This Row],[Name1]])+(表格1[Name.]&"_3"=表格4[[#This Row],[Name1]])+(表格1[Name.]&"_4"=表格4[[#This Row],[Name1]])+(表格1[Name.]&"_5"=表格4[[#This Row],[Name1]]))} -> #VALUE! | M66: =IF(表格4[[#This Row],["Total" No.]]=表格4[[#This Row],[No]],表格4[[#This Row],[No]],"F") -> #VALUE! | N66: =COUNTIF(表格1[No.],表格4[[#This Row],["Total" No.]]) -> 0
L67: {=_xlfn._xlws.FILTER(表格1[No.],(表格1[Name.]=表格4[[#This Row],[Name1]])+(表格1[Name.]&"_1"=表格4[[#This Row],[Name1]])+(表格1[Name.]&"_2"=表格4[[#This Row],[Name1]])+(表格1[Name.]&"_3"=表格4[[#This Row],[Name1]])+(表格1[Name.]&"_4"=表格4[[#This Row],[Name1]])+(表格1[Name.]&"_5"=表格4[[#This Row],[Name1]]))} -> #VALUE! | M67: =IF(表格4[[#This Row],["Total" No.]]=表格4[[#This Row],[No]],表格4[[#This Row],[No]],"F") -> #VALUE! | N67: =COUNTIF(表格1[No.],表格4[[#This Row],["Total" No.]]) -> 0
L68: {=_xlfn._xlws.FILTER(表格1[No.],(表格1[Name.]=表格4[[#This Row],[Name1]])+(表格1[Name.]&"_1"=表格4[[#This Row],[Name1]])+(表格1[Name.]&"_2"=表格4[[#This Row],[Name1]])+(表格1[Name.]&"_3"=表格4[[#This Row],[Name1]])+(表格1[Name.]&"_4"=表格4[[#This Row],[Name1]])+(表格1[Name.]&"_5"=表格4[[#This Row],[Name1]]))} -> #VALUE! | M68: =IF(表格4[[#This Row],["Total" No.]]=表格4[[#This Row],[No]],表格4[[#This Row],[No]],"F") -> #VALUE! | N68: =COUNTIF(表格1[No.],表格4[[#This Row],["Total" No.]]) -> 0
L69: {=_xlfn._xlws.FILTER(表格1[No.],(表格1[Name.]=表格4[[#This Row],[Name1]])+(表格1[Name.]&"_1"=表格4[[#This Row],[Name1]])+(表格1[Name.]&"_2"=表格4[[#This Row],[Name1]])+(表格1[Name.]&"_3"=表格4[[#This Row],[Name1]])+(表格1[Name.]&"_4"=表格4[[#This Row],[Name1]])+(表格1[Name.]&"_5"=表格4[[#This Row],[Name1]]))} -> #VALUE! | M69: =IF(表格4[[#This Row],["Total" No.]]=表格4[[#This Row],[No]],表格4[[#This Row],[No]],"F") -> #VALUE! | N69: =COUNTIF(表格1[No.],表格4[[#This Row],["Total" No.]]) -> 0
L70: {=_xlfn._xlws.FILTER(表格1[No.],(表格1[Name.]=表格4[[#This Row],[Name1]])+(表格1[Name.]&"_1"=表格4[[#This Row],[Name1]])+(表格1[Name.]&"_2"=表格4[[#This Row],[Name1]])+(表格1[Name.]&"_3"=表格4[[#This Row],[Name1]])+(表格1[Name.]&"_4"=表格4[[#This Row],[Name1]])+(表格1[Name.]&"_5"=表格4[[#This Row],[Name1]]))} -> #VALUE! | M70: =IF(表格4[[#This Row],["Total" No.]]=表格4[[#This Row],[No]],表格4[[#This Row],[No]],"F") -> #VALUE! | N70: =COUNTIF(表格1[No.],表格4[[#This Row],["Total" No.]]) -> 0
N71: =COUNTIF(表格1[No.],表格4[[#This Row],["Total" No.]]) -> 0
L72: {=_xlfn._xlws.FILTER(表格1[No.],(表格1[Name.]=表格4[[#This Row],[Name1]])+(表格1[Name.]&"_1"=表格4[[#This Row],[Name1]])+(表格1[Name.]&"_2"=表格4[[#This Row],[Name1]])+(表格1[Name.]&"_3"=表格4[[#This Row],[Name1]])+(表格1[Name.]&"_4"=表格4[[#This Row],[Name1]])+(表格1[Name.]&"_5"=表格4[[#This Row],[Name1]]))} -> #VALUE! | M72: =IF(表格4[[#This Row],["Total" No.]]=表格4[[#This Row],[No]],表格4[[#This Row],[No]],"F") -> #VALUE! | N72: =COUNTIF(表格1[No.],表格4[[#This Row],["Total" No.]]) -> 0
L73: {=_xlfn._xlws.FILTER(表格1[No.],(表格1[Name.]=表格4[[#This Row],[Name1]])+(表格1[Name.]&"_1"=表格4[[#This Row],[Name1]])+(表格1[Name.]&"_2"=表格4[[#This Row],[Name1]])+(表格1[Name.]&"_3"=表格4[[#This Row],[Name1]])+(表格1[Name.]&"_4"=表格4[[#This Row],[Name1]])+(表格1[Name.]&"_5"=表格4[[#This Row],[Name1]]))} -> #VALUE! | M73: =IF(表格4[[#This Row],["Total" No.]]=表格4[[#This Row],[No]],表格4[[#This Row],[No]],"F") -> #VALUE! | N73: =COUNTIF(表格1[No.],表格4[[#This Row],["Total" No.]]) -> 0
L74: {=_xlfn._xlws.FILTER(表格1[No.],(表格1[Name.]=表格4[[#This Row],[Name1]])+(表格1[Name.]&"_1"=表格4[[#This Row],[Name1]])+(表格1[Name.]&"_2"=表格4[[#This Row],[Name1]])+(表格1[Name.]&"_3"=表格4[[#This Row],[Name1]])+(表格1[Name.]&"_4"=表格4[[#This Row],[Name1]])+(表格1[Name.]&"_5"=表格4[[#This Row],[Name1]]))} -> #VALUE! | M74: =IF(表格4[[#This Row],["Total" No.]]=表格4[[#This Row],[No]],表格4[[#This Row],[No]],"F") -> #VALUE! | N74: =COUNTIF(表格1[No.],表格4[[#This Row],["Total" No.]]) -> 0
L75: {=_xlfn._xlws.FILTER(表格1[No.],(表格1[Name.]=表格4[[#This Row],[Name1]])+(表格1[Name.]&"_1"=表格4[[#This Row],[Name1]])+(表格1[Name.]&"_2"=表格4[[#This Row],[Name1]])+(表格1[Name.]&"_3"=表格4[[#This Row],[Name1]])+(表格1[Name.]&"_4"=表格4[[#This Row],[Name1]])+(表格1[Name.]&"_5"=表格4[[#This Row],[Name1]]))} -> #VALUE! | M75: =IF(表格4[[#This Row],["Total" No.]]=表格4[[#This Row],[No]],表格4[[#This Row],[No]],"F") -> #VALUE! | N75: =COUNTIF(表格1[No.],表格4[[#This Row],["Total" No.]]) -> 0
L76: {=_xlfn._xlws.FILTER(表格1[No.],(表格1[Name.]=表格4[[#This Row],[Name1]])+(表格1[Name.]&"_1"=表格4[[#This Row],[Name1]])+(表格1[Name.]&"_2"=表格4[[#This Row],[Name1]])+(表格1[Name.]&"_3"=表格4[[#This Row],[Name1]])+(表格1[Name.]&"_4"=表格4[[#This Row],[Name1]])+(表格1[Name.]&"_5"=表格4[[#This Row],[Name1]]))} -> #VALUE! | M76: =IF(表格4[[#This Row],["Total" No.]]=表格4[[#This Row],[No]],表格4[[#This Row],[No]],"F") -> #VALUE! | N76: =COUNTIF(表格1[No.],表格4[[#This Row],["Total" No.]]) -> 0
L77: {=_xlfn._xlws.FILTER(表格1[No.],(表格1[Name.]=表格4[[#This Row],[Name1]])+(表格1[Name.]&"_1"=表格4[[#This Row],[Name1]])+(表格1[Name.]&"_2"=表格4[[#This Row],[Name1]])+(表格1[Name.]&"_3"=表格4[[#This Row],[Name1]])+(表格1[Name.]&"_4"=表格4[[#This Row],[Name1]])+(表格1[Name.]&"_5"=表格4[[#This Row],[Name1]]))} -> #VALUE! | M77: =IF(表格4[[#This Row],["Total" No.]]=表格4[[#This Row],[No]],表格4[[#This Row],[No]],"F") -> #VALUE! | N77: =COUNTIF(表格1[No.],表格4[[#This Row],["Total" No.]]) -> 0
L78: {=_xlfn._xlws.FILTER(表格1[No.],(表格1[Name.]=表格4[[#This Row],[Name1]])+(表格1[Name.]&"_1"=表格4[[#This Row],[Name1]])+(表格1[Name.]&"_2"=表格4[[#This Row],[Name1]])+(表格1[Name.]&"_3"=表格4[[#This Row],[Name1]])+(表格1[Name.]&"_4"=表格4[[#This Row],[Name1]])+(表格1[Name.]&"_5"=表格4[[#This Row],[Name1]]))} -> #VALUE! | M78: =IF(表格4[[#This Row],["Total" No.]]=表格4[[#This Row],[No]],表格4[[#This Row],[No]],"F") -> #VALUE! | N78: =COUNTIF(表格1[No.],表格4[[#This Row],["Total" No.]]) -> 0
...

Sheet 工作表3
A1: No. | B1: 欄1 | C1: =Total!C7 -> Name. | D1: =Total!D7 -> Full Name. | E1: =Total!E7 -> CQ No. | F1: =Total!F7 -> Shop | G1: =Total!G7 -> Period | H1: =Total!H7 -> Days | I1: =Total!I7 -> Reg.Hrs | J1: =Total!J7 -> $ | ... O1: =Total!O7 -> Allowance | P1: A1 | Q1: A2 | R1: A3 | S1: A4 | T1: A5 | U1: A6 | V1: A7 | W1: A8 | X1: A9 | Y1: A10 | Z1: A11 | AA1: A12 | AB1: A13 | AC1: A14 | AD1: A15 | AE1: A16 | AF1: A17 | AG1: =Total!AG7 -> Total | AO1: B1 | AP1: B2 | AQ1: B3 | AR1: B4 | AS1: B5 | AT1: B6 | AU1: B7 | AV1: B8 | AW1: B9 | AX1: B10 | AY1: B11 | AZ1: B12 | BA1: B13 | BB1: B14 | BC1: B15 | BD1: B16 | BE1: B17
A2: 1 | B2: 2026-03 Toshiba | C2: =Total!C8 -> May C | D2: =Total!D8 -> Cheng Muk Kiu | E2: =Total!E8 -> 20850 | F2: =Total!F8 -> Kornhill Aeon | G2: =Total!G8 -> Mar/1-3,5-8,10-13,15-17,20-23,26-29 | H2: =Total!H8 -> 22 | I2: =Total!I8 -> 176 | J2: =Total!J8 -> 55 | ... AF2: =Total!AF8 -> 0 | AG2: =Total!AH8 -> 19745 | AO2: =表格1[[#Headers],[日本飯煲 RC-DS10K/18K]] -> 日本飯煲 RC-DS10K/18K | AP2: =表格1[[#Headers],[酵活炊電飯煲特佣 RC-18AMXH(W)]] -> 酵活炊電飯煲特佣 RC-18AMXH(W) | AQ2: =表格1[[#Headers],[嵌入式微波氣炸蒸焗爐特佣 EB-T500APW]] -> 嵌入式微波氣炸蒸焗爐特佣 EB-T500APW | AR2: =表格1[[#Headers],[蒸氣烤焗水波爐特佣 ER-VD7000HK(XK)]] -> 蒸氣烤焗水波爐特佣 ER-VD7000HK(XK) | AS2: =表格1[[#Headers],[TWDT21BU95 ]] -> TWDT21BU95 | AT2: =表格1[[#Headers],[日式洗衣機一特佣 AW-Q800APH(WW)]] -> 日式洗衣機一特佣 AW-Q800APH(WW) | AU2: =表格1[[#Headers],[日式洗衣機二特佣 AW-Q801APH(WW)]] -> 日式洗衣機二特佣 AW-Q801APH(WW) | AV2: =表格1[[#Headers],[三門雪櫃特佣 GR-RM469WE-PGA(B3)]] -> 三門雪櫃特佣 GR-RM469WE-PGA(B3) | AW2: =表格1[[#Headers],[雙門雪櫃一特佣 GR-RB449WE-PMA(57)]] -> 雙門雪櫃一特佣 GR-RB449WE-PMA(57) | AX2: =表格1[[#Headers],[雙門雪櫃一特佣 GR-RB410WE-PMA(06)]] -> 雙門雪櫃一特佣 GR-RB410WE-PMA(06) | AY2: =表格1[[#Headers],[十字門雪櫃 GR-RF698WI]] -> 十字門雪櫃 GR-RF698WI | AZ2: =表格1[[#Headers],[水機 TWP-W2265THK(W)]] -> 水機 TWP-W2265THK(W) | BA2: =表格1[[#Headers],[抽濕機特佣]] -> 抽濕機特佣 | BB2: =表格1[[#Headers],[(Fortress ONLY)TW-T25BZU115MWH(MG) ]] -> (Fortress ONLY)TW-T25BZU115MWH(MG) | BC2: =表格1[[#Headers],[開門紅(三月)]] -> 開門紅(三月) | BD2: =表格1[[#Headers],[開門紅(第一季)]] -> 開門紅(第一季) | BE2: =表格1[[#Headers],[酵活炊電飯煲特佣 RC-18AMXH(W)]] -> 酵活炊電飯煲特佣 RC-18AMXH(W)
